Workbook

Sheet 613 Agronomy All VIs + Thresh +
A1: fid | B1: Date | C1: Time | D1: Version | E1: Id | F1: Name | G1: UniqueID | H1: Plot Numbe | I1: BLOC | J1: SPACING | K1: DENSITY | L1: VARIETY | M1: Yield | N1: 618ExG_mean | O1: 618ExG_variance | P1: 618ExR_mean | Q1: 618ExR_variance | R1: 618gNDVI_mean | S1: 618gNDVI_variance | T1: 618NVI_mean | U1: 618NVI_variance | V1: 618HA_mean | W1: 618HA_variance | X1: 618THRESH_mean | Y1: 618THRESH_variance | Z1: 618NDRE_mean | AA1: 618NDRE_variance | AB1: PLTCOUNT
A2: 1123 | B2: 45448 | C2: 01:08:31pm | D2: 4.71 | E2: 905 | F2: D25 | G2: 5009399f124b0578 | H2: 14004 | I2: =VLOOKUP(H2,Sheet1!H:AE,2) -> 3 | J2: =VLOOKUP(H2,Sheet1!H:T,3,FALSE) -> 22" | K2: =VLOOKUP($H2,Sheet1!H:$AE,4,FALSE) -> 150000 | L2: =VLOOKUP($H2,Sheet1!$H:$AE,5,FALSE) -> Zorro | M2: =VLOOKUP($H2,Sheet1!$H:$AE,13,FALSE) -> 1985 | N2: 2648.5104 | O2: 1746098.5 | P2: 15820.179 | Q2: 20481070 | R2: 0.37416141 | S2: 0.0034667381 | T2: 0.24928036 | U2: 0.0049886167 | V2: 1 | W2: 0 | X2: 0.63461432 | Y2: 0.23187898 | Z2: 0.10079552 | AA2: 0.0011483677 | AB2: 95
A3: 1124 | B3: 45448 | C3: 01:09:45pm | D3: 4.71 | E3: 905 | F3: D23 | G3: 500939e974326067 | H3: 13004 | I3: =VLOOKUP(H3,Sheet1!H:AE,2) -> 3 | J3: =VLOOKUP(H3,Sheet1!H:T,3,FALSE) -> 22" | K3: =VLOOKUP($H3,Sheet1!H:$AE,4,FALSE) -> 150000 | L3: =VLOOKUP($H3,Sheet1!$H:$AE,5,FALSE) -> Redhawk | M3: =VLOOKUP($H3,Sheet1!$H:$AE,13,FALSE) -> 821 | N3: 2650.0769 | O3: 1204924.9 | P3: 16666.338 | Q3: 15995491 | R3: 0.35800444 | S3: 0.0024858345 | T3: 0.22809271 | U3: 0.0026127804 | V3: 0.98711135 | W3: 0.012722533 | X3: 0.56377741 | Y3: 0.24593244 | Z3: 0.10154143 | AA3: 0.00081137284 | AB3: 53
A4: 1125 | B4: 45448 | C4: 01:10:13pm | D4: 4.71 | E4: 905 | F4: D21 | G4: 50093a0530f42610 | H4: 12004 | I4: =VLOOKUP(H4,Sheet1!H:AE,2) -> 3 | J4: =VLOOKUP(H4,Sheet1!H:T,3,FALSE) -> 22" | K4: =VLOOKUP($H4,Sheet1!H:$AE,4,FALSE) -> 150000 | L4: =VLOOKUP($H4,Sheet1!$H:$AE,5,FALSE) -> Cayenne | M4: =VLOOKUP($H4,Sheet1!$H:$AE,13,FALSE) -> 1897 | N4: 2768.7995 | O4: 1359173.4 | P4: 16644.478 | Q4: 16886150 | R4: 0.35982636 | S4: 0.0030575287 | T4: 0.23004306 | U4: 0.0040955777 | V4: 0.85078054 | W4: 0.12695301 | X4: 0.36875719 | Y4: 0.23277532 | Z4: 0.11647585 | AA4: 0.00088454665 | AB4: 57
A5: 1126 | B5: 45448 | C5: 01:10:34pm | D5: 4.71 | E5: 905 | F5: D19 | G5: 50093a1a08b553e0 | H5: 11004 | I5: =VLOOKUP(H5,Sheet1!H:AE,2) -> 3 | J5: =VLOOKUP(H5,Sheet1!H:T,3,FALSE) -> 22" | K5: =VLOOKUP($H5,Sheet1!H:$AE,4,FALSE) -> 150000 | L5: =VLOOKUP($H5,Sheet1!$H:$AE,5,FALSE) -> Windbreaker | M5: =VLOOKUP($H5,Sheet1!$H:$AE,13,FALSE) -> 1964 | N5: 2623.8886 | O5: 2033207.2 | P5: 16174.961 | Q5: 19747834 | R5: 0.37351339 | S5: 0.0027929083 | T5: 0.23476086 | U5: 0.0044131266 | V5: 0.99985185 | W5: 0.00014812346 | X5: 0.67725905 | Y5: 0.21857923 | Z5: 0.13521569 | AA5: 0.00090151646 | AB5: 71
A6: 1127 | B6: 45448 | C6: 01:10:55pm | D6: 4.71 | E6: 905 | F6: D17 | G6: 50093a2f7621b22f | H6: 10004 | I6: =VLOOKUP(H6,Sheet1!H:AE,2) -> 3 | J6: =VLOOKUP(H6,Sheet1!H:T,3,FALSE) -> 22" | K6: =VLOOKUP($H6,Sheet1!H:$AE,4,FALSE) -> 150000 | L6: =VLOOKUP($H6,Sheet1!$H:$AE,5,FALSE) -> Eclipse | M6: =VLOOKUP($H6,Sheet1!$H:$AE,13,FALSE) -> 1693 | N6: 2341.0078 | O6: 1269082.1 | P6: 15830.24 | Q6: 17925003 | R6: 0.39021857 | S6: 0.0028976654 | T6: 0.23160747 | U6: 0.0037761625 | V6: 0.81030779 | W6: 0.15370908 | X6: 0.17085224 | Y6: 0.14166175 | Z6: 0.077678777 | AA6: 0.001123971 | AB6: 65
A7: 1128 | B7: 45448 | C7: 01:11:16pm | D7: 4.71 | E7: 905 | F7: D15 | G7: 50093a442aae9133 | H7: 9004 | I7: =VLOOKUP(H7,Sheet1!H:AE,2) -> 2 | J7: =VLOOKUP(H7,Sheet1!H:T,3,FALSE) -> 22" | K7: =VLOOKUP($H7,Sheet1!H:$AE,4,FALSE) -> 150000 | L7: =VLOOKUP($H7,Sheet1!$H:$AE,5,FALSE) -> CLERK | M7: =VLOOKUP($H7,Sheet1!$H:$AE,13,FALSE) -> 839 | N7: 2883.1388 | O7: 2522768.4 | P7: 16075.221 | Q7: 19682200 | R7: 0.37081627 | S7: 0.002956207 | T7: 0.23934029 | U7: 0.004982097 | V7: 1 | W7: 0 | X7: 0.90202177 | Y7: 0.088378494 | Z7: 0.10209412 | AA7: 0.00085563714 | AB7: 84
A8: 1129 | B8: 45448 | C8: 01:11:37pm | D8: 4.71 | E8: 905 | F8: D13 | G8: 50093a597a18dd17 | H8: 8004 | I8: =VLOOKUP(H8,Sheet1!H:AE,2) -> 2 | J8: =VLOOKUP(H8,Sheet1!H:T,3,FALSE) -> 22" | K8: =VLOOKUP($H8,Sheet1!H:$AE,4,FALSE) -> 150000 | L8: =VLOOKUP($H8,Sheet1!$H:$AE,5,FALSE) -> Red Rover | M8: =VLOOKUP($H8,Sheet1!$H:$AE,13,FALSE) -> 994 | N8: 2734.644 | O8: 2977435.5 | P8: 16039.588 | Q8: 24524407 | R8: 0.3734447 | S8: 0.0039762759 | T8: 0.24327959 | U8: 0.0065227014 | V8: 0.99994445 | W8: 5.555144e-05 | X8: 0.90578296 | Y8: 0.085340186 | Z8: 0.096373351 | AA8: 0.00091612187 | AB8: 84
A9: 1130 | B9: 45448 | C9: 01:11:58pm | D9: 4.71 | E9: 905 | F9: D11 | G9: 50093a6e39d14fbd | H9: 7004 | I9: =VLOOKUP(H9,Sheet1!H:AE,2) -> 2 | J9: =VLOOKUP(H9,Sheet1!H:T,3,FALSE) -> 22" | K9: =VLOOKUP($H9,Sheet1!H:$AE,4,FALSE) -> 150000 | L9: =VLOOKUP($H9,Sheet1!$H:$AE,5,FALSE) -> Red Dawn | M9: =VLOOKUP($H9,Sheet1!$H:$AE,13,FALSE) -> 700 | N9: 2865.1414 | O9: 2889644 | P9: 16264.204 | Q9: 18243755 | R9: 0.35610063 | S9: 0.0031595107 | T9: 0.23424732 | U9: 0.0056627159 | V9: 0.96777837 | W9: 0.031183392 | X9: 0.60827313 | Y9: 0.23827693 | Z9: 0.093056266 | AA9: 0.00093336124 | AB9: 63
A10: 1131 | B10: 45448 | C10: 01:12:19pm | D10: 4.71 | E10: 905 | F10: D9 | G10: 50093a832c9493fd | H10: 6004 | I10: =VLOOKUP(H10,Sheet1!H:AE,2) -> 2 | J10: =VLOOKUP(H10,Sheet1!H:T,3,FALSE) -> 22" | K10: =VLOOKUP($H10,Sheet1!H:$AE,4,FALSE) -> 150000 | L10: =VLOOKUP($H10,Sheet1!$H:$AE,5,FALSE) -> T9905 | M10: =VLOOKUP($H10,Sheet1!$H:$AE,13,FALSE) -> 2396 | N10: 2608.4308 | O10: 1315844.3 | P10: 16185.342 | Q10: 15835866 | R10: 0.35720251 | S10: 0.0025329642 | T10: 0.22171643 | U10: 0.003112249 | V10: 0.99727783 | W10: 0.0027147616 | X10: 0.5721306 | Y10: 0.24479718 | Z10: 0.08587291 | AA10: 0.00087433742 | AB10: 61
A11: 1132 | B11: 45448 | C11: 01:12:40pm | D11: 4.71 | E11: 905 | F11: D7 | G11: 50093a987f396412 | H11: 5004 | I11: =VLOOKUP(H11,Sheet1!H:AE,2) -> 1 | J11: =VLOOKUP(H11,Sheet1!H:T,3,FALSE) -> 22" | K11: =VLOOKUP($H11,Sheet1!H:$AE,4,FALSE) -> 150000 | L11: =VLOOKUP($H11,Sheet1!$H:$AE,5,FALSE) -> Ronnies red | M11: =VLOOKUP($H11,Sheet1!$H:$AE,13,FALSE) -> 988 | N11: 2967.8138 | O11: 3274480.3 | P11: 16174.791 | Q11: 18347066 | R11: 0.35419235 | S11: 0.0030469032 | T11: 0.23395861 | U11: 0.0055424892 | V11: 0.99990741 | W11: 9.2580591e-05 | X11: 0.70771255 | Y11: 0.2068555 | Z11: 0.090307155 | AA11: 0.00095910824 | AB11: 73
A12: 1133 | B12: 45448 | C12: 01:13:01pm | D12: 4.71 | E12: 905 | F12: D5 | G12: 50093aad1f4f98d9 | H12: 4004 | I12: =VLOOKUP(H12,Sheet1!H:AE,2) -> 1 | J12: =VLOOKUP(H12,Sheet1!H:T,3,FALSE) -> 22" | K12: =VLOOKUP($H12,Sheet1!H:$AE,4,FALSE) -> 150000 | L12: =VLOOKUP($H12,Sheet1!$H:$AE,5,FALSE) -> Merlot | M12: =VLOOKUP($H12,Sheet1!$H:$AE,13,FALSE) -> 2033 | N12: 2580.4687 | O12: 1069805.3 | P12: 16611.261 | Q12: 14939708 | R12: 0.35062413 | S12: 0.0025761499 | T12: 0.22588639 | U12: 0.003099408 | V12: 0.99931481 | W12: 0.00068471571 | X12: 0.57510836 | Y12: 0.24435873 | Z12: 0.094957034 | AA12: 0.00084252625 | AB12: 55
A13: 1134 | B13: 45448 | C13: 01:13:21pm | D13: 4.71 | E13: 905 | F13: D3 | G13: 50093ac156fbaaaa | H13: 3004 | I13: =VLOOKUP(H13,Sheet1!H:AE,2) -> 1 | J13: =VLOOKUP(H13,Sheet1!H:T,3,FALSE) -> 22" | K13: =VLOOKUP($H13,Sheet1!H:$AE,4,FALSE) -> 150000 | L13: =VLOOKUP($H13,Sheet1!$H:$AE,5,FALSE) -> Apex | M13: =VLOOKUP($H13,Sheet1!$H:$AE,13,FALSE) -> 2070 | N13: 2911.366 | O13: 2691615 | P13: 15834.873 | Q13: 18238243 | R13: 0.36419508 | S13: 0.0034112521 | T13: 0.24368605 | U13: 0.0066725625 | V13: 1 | W13: 0 | X13: 0.62852226 | Y13: 0.23348203 | Z13: 0.10455132 | AA13: 0.00099505154 | AB13: 84
... A58: 1181 | B58: 45448 | C58: 01:38:48pm | D58: 4.71 | E58: 905 | F58: U27 | G58: 500930b8015b0226 | H58: 15007 | I58: =VLOOKUP(H58,Sheet1!H:AE,2) -> 3 | J58: =VLOOKUP(H58,Sheet1!H:T,3,FALSE) -> 22" | K58: =VLOOKUP($H58,Sheet1!H:$AE,4,FALSE) -> 75000 | L58: =VLOOKUP($H58,Sheet1!$H:$AE,5,FALSE) -> Cayenne | M58: =VLOOKUP($H58,Sheet1!$H:$AE,13,FALSE) -> 2032 | N58: 2301.3513 | O58: 984438.27 | P58: 15773.065 | Q58: 16690309 | R58: 0.36603813 | S58: 0.0024000532 | T58: 0.23411301 | U58: 0.0024913176 | V58: 0.99896296 | W58: 0.0010359616 | X58: 0.50020245 | Y58: 0.24999996 | Z58: 0.084192932 | AA58: 0.0029695729 | AB58: 47
A59: 1182 | B59: 45448 | C59: 01:41:13pm | D59: 4.71 | E59: 905 | F59: D27 | G59: 5.009315e+15 | H59: 15008 | I59: =VLOOKUP(H59,Sheet1!H:AE,2) -> 3 | J59: =VLOOKUP(H59,Sheet1!H:T,3,FALSE) -> 22" | K59: =VLOOKUP($H59,Sheet1!H:$AE,4,FALSE) -> 150000 | L59: =VLOOKUP($H59,Sheet1!$H:$AE,5,FALSE) -> Windbreaker | M59: =VLOOKUP($H59,Sheet1!$H:$AE,13,FALSE) -> 1502 | N59: 2500.2492 | O59: 2216482.7 | P59: 16005.321 | Q59: 21312647 | R59: 0.38268686 | S59: 0.0027186556 | T59: 0.25268512 | U59: 0.003844162 | V59: 0.99992593 | W59: 7.4065844e-05 | X59: 0.60215895 | Y59: 0.23956355 | Z59: 0.084192932 | AA59: 0.0029695729 | AB59: 71
A60: 1184 | B60: 45448 | C60: 01:41:47pm | D60: 4.71 | E60: 905 | F60: D23 | G60: 5009316b170729f3 | H60: 13008 | I60: =VLOOKUP(H60,Sheet1!H:AE,2) -> 3 | J60: =VLOOKUP(H60,Sheet1!H:T,3,FALSE) -> 22" | K60: =VLOOKUP($H60,Sheet1!H:$AE,4,FALSE) -> 150000 | L60: =VLOOKUP($H60,Sheet1!$H:$AE,5,FALSE) -> Cayenne | M60: =VLOOKUP($H60,Sheet1!$H:$AE,13,FALSE) -> 2029 | N60: 2590.6995 | O60: 1216633 | P60: 16280.355 | Q60: 17463173 | R60: 0.36160577 | S60: 0.0031768468 | T60: 0.23414287 | U60: 0.0042061687 | V60: 1 | W60: 0 | X60: 0.45128101 | Y60: 0.24762646 | Z60: 0.10154143 | AA60: 0.00081137284 | AB60: 92
A61: 1185 | B61: 45448 | C61: 01:43:10pm | D61: 4.71 | E61: 905 | F61: D21 | G61: 500931be718e62fc | H61: 12008 | I61: =VLOOKUP(H61,Sheet1!H:AE,2) -> 3 | J61: =VLOOKUP(H61,Sheet1!H:T,3,FALSE) -> 22" | K61: =VLOOKUP($H61,Sheet1!H:$AE,4,FALSE) -> 150000 | L61: =VLOOKUP($H61,Sheet1!$H:$AE,5,FALSE) -> ETNA | M61: =VLOOKUP($H61,Sheet1!$H:$AE,13,FALSE) -> 218 | N61: 2627.6234 | O61: 1846395.2 | P61: 16646.071 | Q61: 16918247 | R61: 0.34245004 | S61: 0.0034181251 | T61: 0.21999205 | U61: 0.0046435246 | V61: 0.71509787 | W61: 0.20373291 | X61: 0.21651344 | Y61: 0.16963537 | Z61: 0.11647585 | AA61: 0.00088454665 | AB61: 34
A62: 1186 | B62: 45448 | C62: 01:43:27pm | D62: 4.71 | E62: 905 | F62: D19 | G62: 500931cf441ba1bb | H62: 11008 | I62: =VLOOKUP(H62,Sheet1!H:AE,2) -> 3 | J62: =VLOOKUP(H62,Sheet1!H:T,3,FALSE) -> 22" | K62: =VLOOKUP($H62,Sheet1!H:$AE,4,FALSE) -> 150000 | L62: =VLOOKUP($H62,Sheet1!$H:$AE,5,FALSE) -> Apex | M62: =VLOOKUP($H62,Sheet1!$H:$AE,13,FALSE) -> 1864 | N62: 2814.8537 | O62: 3529001.7 | P62: 16620.725 | Q62: 21238804 | R62: 0.35379896 | S62: 0.0047574319 | T62: 0.23627894 | U62: 0.00537333 | V62: 0.99896296 | W62: 0.0010359616 | X62: 0.43331738 | Y62: 0.24555343 | Z62: 0.13521569 | AA62: 0.00090151646 | AB62: 74
A63: 1187 | B63: 45448 | C63: 01:43:44pm | D63: 4.71 | E63: 905 | F63: D17 | G63: 500931e05692012d | H63: 10008 | I63: =VLOOKUP(H63,Sheet1!H:AE,2) -> 3 | J63: =VLOOKUP(H63,Sheet1!H:T,3,FALSE) -> 22" | K63: =VLOOKUP($H63,Sheet1!H:$AE,4,FALSE) -> 150000 | L63: =VLOOKUP($H63,Sheet1!$H:$AE,5,FALSE) -> Red Rover | M63: =VLOOKUP($H63,Sheet1!$H:$AE,13,FALSE) -> 1045 | N63: 2852.7317 | O63: 2730640.9 | P63: 15404.725 | Q63: 23674913 | R63: 0.40429088 | S63: 0.0037530744 | T63: 0.26479804 | U63: 0.0077084595 | V63: 1 | W63: 0 | X63: 0.61953491 | Y63: 0.23571141 | Z63: 0.077678777 | AA63: 0.001123971 | AB63: 87
A64: 1188 | B64: 45448 | C64: 01:44:01pm | D64: 4.71 | E64: 905 | F64: D15 | G64: 500931f15831b7e0 | H64: 9008 | I64: =VLOOKUP(H64,Sheet1!H:AE,2) -> 2 | J64: =VLOOKUP(H64,Sheet1!H:T,3,FALSE) -> 22" | K64: =VLOOKUP($H64,Sheet1!H:$AE,4,FALSE) -> 150000 | L64: =VLOOKUP($H64,Sheet1!$H:$AE,5,FALSE) -> Zorro | M64: =VLOOKUP($H64,Sheet1!$H:$AE,13,FALSE) -> 1911 | N64: 2933.2706 | O64: 2953666.4 | P64: 15980.673 | Q64: 20740896 | R64: 0.3665152 | S64: 0.0040269258 | T64: 0.24221883 | U64: 0.0071156065 | V64: 1 | W64: 0 | X64: 0.50837896 | Y64: 0.24992979 | Z64: 0.10209412 | AA64: 0.00085563714 | AB64: 96
A65: 1189 | B65: 45448 | C65: 01:44:18pm | D65: 4.71 | E65: 905 | F65: D13 | G65: 500932020f58c618 | H65: 8008 | I65: =VLOOKUP(H65,Sheet1!H:AE,2) -> 2 | J65: =VLOOKUP(H65,Sheet1!H:T,3,FALSE) -> 22" | K65: =VLOOKUP($H65,Sheet1!H:$AE,4,FALSE) -> 150000 | L65: =VLOOKUP($H65,Sheet1!$H:$AE,5,FALSE) -> black bear | M65: =VLOOKUP($H65,Sheet1!$H:$AE,13,FALSE) -> 2266 | N65: 2687.6418 | O65: 1766277.9 | P65: 16526.164 | Q65: 20729808 | R65: 0.32278798 | S65: 0.0039985792 | T65: 0.23495791 | U65: 0.0046124173 | V65: 1 | W65: 0 | X65: 0.60037178 | Y65: 0.23992551 | Z65: 0.096373351 | AA65: 0.00091612187 | AB65: 89
A66: 1190 | B66: 45448 | C66: 01:44:35pm | D66: 4.71 | E66: 905 | F66: D11 | G66: 5009321313b82097 | H66: 7008 | I66: =VLOOKUP(H66,Sheet1!H:AE,2) -> 2 | J66: =VLOOKUP(H66,Sheet1!H:T,3,FALSE) -> 22" | K66: =VLOOKUP($H66,Sheet1!H:$AE,4,FALSE) -> 150000 | L66: =VLOOKUP($H66,Sheet1!$H:$AE,5,FALSE) -> Eclipse | M66: =VLOOKUP($H66,Sheet1!$H:$AE,13,FALSE) -> 2113 | N66: 2859.044 | O66: 1293345.3 | P66: 16168.846 | Q66: 15768861 | R66: 0.3430859 | S66: 0.0035191541 | T66: 0.2291819 | U66: 0.0053039168 | V66: 1 | W66: 0 | X66: 0.4982193 | Y66: 0.24999683 | Z66: 0.093056266 | AA66: 0.00093336124 | AB66: 111
A67: 1191 | B67: 45448 | C67: 01:44:52pm | D67: 4.71 | E67: 905 | F67: D9 | G67: 50093224293f387a | H67: 6008 | I67: =VLOOKUP(H67,Sheet1!H:AE,2) -> 2 | J67: =VLOOKUP(H67,Sheet1!H:T,3,FALSE) -> 22" | K67: =VLOOKUP($H67,Sheet1!H:$AE,4,FALSE) -> 150000 | L67: =VLOOKUP($H67,Sheet1!$H:$AE,5,FALSE) -> T9905 | M67: =VLOOKUP($H67,Sheet1!$H:$AE,13,FALSE) -> 2690 | N67: 2726.6898 | O67: 1346077.6 | P67: 16560.935 | Q67: 15842426 | R67: 0.35069968 | S67: 0.0023645621 | T67: 0.21770672 | U67: 0.0027461691 | V67: 0.99875928 | W67: 0.0012391784 | X67: 0.48859359 | Y67: 0.24986989 | Z67: 0.090332478 | AA67: 0.001026119 | AB67: 72
A68: 1192 | B68: 45448 | C68: 01:45:08pm | D68: 4.71 | E68: 905 | F68: D7 | G68: 500932344a5c82a7 | H68: 5008 | I68: =VLOOKUP(H68,Sheet1!H:AE,2) -> 2 | J68: =VLOOKUP(H68,Sheet1!H:T,3,FALSE) -> 22" | K68: =VLOOKUP($H68,Sheet1!H:$AE,4,FALSE) -> 150000 | L68: =VLOOKUP($H68,Sheet1!$H:$AE,5,FALSE) -> CLERK | M68: =VLOOKUP($H68,Sheet1!$H:$AE,13,FALSE) -> 1081 | N68: 3047.6716 | O68: 2984034.3 | P68: 16102.052 | Q68: 18924779 | R68: 0.36579328 | S68: 0.0031060726 | T68: 0.24173183 | U68: 0.0066712011 | V68: 1 | W68: 0 | X68: 0.56504854 | Y68: 0.24576869 | Z68: 0.08587291 | AA68: 0.00087433742 | AB68: 84
A69: 1193 | B69: 45448 | C69: 01:47:21pm | D69: 4.71 | E69: 905 | F69: D5 | G69: 500932b92c1203b8 | H69: 4008 | I69: =VLOOKUP(H69,Sheet1!H:AE,2) -> 1 | J69: =VLOOKUP(H69,Sheet1!H:T,3,FALSE) -> 22" | K69: =VLOOKUP($H69,Sheet1!H:$AE,4,FALSE) -> 150000 | L69: =VLOOKUP($H69,Sheet1!$H:$AE,5,FALSE) -> Red Dawn | M69: =VLOOKUP($H69,Sheet1!$H:$AE,13,FALSE) -> 741 | N69: 3024.3901 | O69: 3588103.5 | P69: 16093.277 | Q69: 19682720 | R69: 0.36672129 | S69: 0.0031924875 | T69: 0.24353069 | U69: 0.0066593746 | V69: 1 | W69: 0 | X69: 0.4632041 | Y69: 0.24864606 | Z69: 0.090307155 | AA69: 0.00095910824 | AB69: 65
A70: 1194 | B70: 45448 | C70: 01:47:38pm | D70: 4.71 | E70: 905 | F70: D3 | G70: 500932ca52befd13 | H70: 3008 | I70: =VLOOKUP(H70,Sheet1!H:AE,2) -> 1 | J70: =VLOOKUP(H70,Sheet1!H:T,3,FALSE) -> 22" | K70: =VLOOKUP($H70,Sheet1!H:$AE,4,FALSE) -> 150000 | L70: =VLOOKUP($H70,Sheet1!$H:$AE,5,FALSE) -> Ronnies red | M70: =VLOOKUP($H70,Sheet1!$H:$AE,13,FALSE) -> 991 | N70: 2745.2425 | O70: 3042196.3 | P70: 15475.814 | Q70: 19155214 | R70: 0.36397781 | S70: 0.0032474304 | T70: 0.2441702 | U70: 0.0063944059 | V70: 1 | W70: 0 | X70: 0.61993503 | Y70: 0.23561559 | Z70: 0.094957034 | AA70: 0.00084252625 | AB70: 68
A71: 1195 | B71: 45448 | C71: 01:47:55pm | D71: 4.71 | E71: 905 | F71: D1 | G71: 500932db3f68c504 | H71: 2008 | I71: =VLOOKUP(H71,Sheet1!H:AE,2) -> 1 | J71: =VLOOKUP(H71,Sheet1!H:T,3,FALSE) -> 22" | K71: =VLOOKUP($H71,Sheet1!H:$AE,4,FALSE) -> 150000 | L71: =VLOOKUP($H71,Sheet1!$H:$AE,5,FALSE) -> Merlot | M71: =VLOOKUP($H71,Sheet1!$H:$AE,13,FALSE) -> 1672 | N71: 2134.8715 | O71: 948777.01 | P71: 15745.689 | Q71: 16564865 | R71: 0.36279978 | S71: 0.0022943075 | T71: 0.22663083 | U71: 0.0022590396 | V71: 0.90253704 | W71: 0.087963934 | X71: 0.49819169 | Y71: 0.24999673 | Z71: 0.10455132 | AA71: 0.00099505154 | AB71: 37
... A80: 1204 | B80: 45448 | C80: 01:57:11pm | D80: 4.71 | E80: 905 | F80: U13 | G80: 500935070683b2d8 | H80: 8009 | I80: =VLOOKUP(H80,Sheet1!H:AE,2) -> 2 | J80: =VLOOKUP(H80,Sheet1!H:T,3,FALSE) -> 22" | K80: =VLOOKUP($H80,Sheet1!H:$AE,4,FALSE) -> 100000 | L80: =VLOOKUP($H80,Sheet1!$H:$AE,5,FALSE) -> Red Rover | M80: =VLOOKUP($H80,Sheet1!$H:$AE,13,FALSE) -> 1163 | N80: 2697.6135 | O80: 2252523.6 | P80: 16804.376 | Q80: 19652212 | R80: 0.32144867 | S80: 0.0036530339 | T80: 0.22917213 | U80: 0.0042064861 | V80: 1 | W80: 0 | X80: 0.73881435 | Y80: 0.19296771 | Z80: 0.096373351 | AA80: 0.00091612187 | AB80: 65
A81: 1205 | B81: 45448 | C81: 01:57:28pm | D81: 4.71 | E81: 905 | F81: U15 | G81: 5.0093518e+15 | H81: 9009 | I81: =VLOOKUP(H81,Sheet1!H:AE,2) -> 2 | J81: =VLOOKUP(H81,Sheet1!H:T,3,FALSE) -> 22" | K81: =VLOOKUP($H81,Sheet1!H:$AE,4,FALSE) -> 100000 | L81: =VLOOKUP($H81,Sheet1!$H:$AE,5,FALSE) -> Apex | M81: =VLOOKUP($H81,Sheet1!$H:$AE,13,FALSE) -> 1876 | N81: 2824.1872 | O81: 1962483.3 | P81: 16152.804 | Q81: 17095845 | R81: 0.35609429 | S81: 0.0024898857 | T81: 0.22878283 | U81: 0.0035898802 | V81: 0.99972222 | W81: 0.00027770062 | X81: 0.6494667 | Y81: 0.22765971 | Z81: 0.10209412 | AA81: 0.00085563714 | AB81: 78
A82: 1206 | B82: 45448 | C82: 01:57:45pm | D82: 4.71 | E82: 905 | F82: U17 | G82: 500935296ee2769c | H82: 10009 | I82: =VLOOKUP(H82,Sheet1!H:AE,2) -> 3 | J82: =VLOOKUP(H82,Sheet1!H:T,3,FALSE) -> 22" | K82: =VLOOKUP($H82,Sheet1!H:$AE,4,FALSE) -> 100000 | L82: =VLOOKUP($H82,Sheet1!$H:$AE,5,FALSE) -> Windbreaker | M82: =VLOOKUP($H82,Sheet1!$H:$AE,13,FALSE) -> 1965 | N82: 2722.5146 | O82: 1910094.8 | P82: 16304.445 | Q82: 19094756 | R82: 0.39470779 | S82: 0.0029269569 | T82: 0.24547568 | U82: 0.0040228767 | V82: 1 | W82: 0 | X82: 0.59452072 | Y82: 0.24106583 | Z82: 0.077678777 | AA82: 0.001123971 | AB82: 71
A83: 1207 | B83: 45448 | C83: 01:59:14pm | D83: 4.71 | E83: 905 | F83: U19 | G83: 500935820e50ca1d | H83: 11009 | I83: =VLOOKUP(H83,Sheet1!H:AE,2) -> 3 | J83: =VLOOKUP(H83,Sheet1!H:T,3,FALSE) -> 22" | K83: =VLOOKUP($H83,Sheet1!H:$AE,4,FALSE) -> 100000 | L83: =VLOOKUP($H83,Sheet1!$H:$AE,5,FALSE) -> T9905 | M83: =VLOOKUP($H83,Sheet1!$H:$AE,13,FALSE) -> 1558 | N83: 2579.9998 | O83: 1147924.4 | P83: 16647.3 | Q83: 14402247 | R83: 0.34870272 | S83: 0.0021971136 | T83: 0.217909 | U83: 0.0021655164 | V83: 0.92440741 | W83: 0.069878353 | X83: 0.50121934 | Y83: 0.24999851 | Z83: 0.13521569 | AA83: 0.00090151646 | AB83: 41
A84: 1208 | B84: 45448 | C84: 01:59:30pm | D84: 4.71 | E84: 905 | F84: U21 | G84: 500935926109b79f | H84: 12009 | I84: =VLOOKUP(H84,Sheet1!H:AE,2) -> 3 | J84: =VLOOKUP(H84,Sheet1!H:T,3,FALSE) -> 22" | K84: =VLOOKUP($H84,Sheet1!H:$AE,4,FALSE) -> 100000 | L84: =VLOOKUP($H84,Sheet1!$H:$AE,5,FALSE) -> Nautica | M84: =VLOOKUP($H84,Sheet1!$H:$AE,13,FALSE) -> 1797 | N84: 2699.5853 | O84: 1495953.3 | P84: 16672.322 | Q84: 13747705 | R84: 0.34590273 | S84: 0.0023232196 | T84: 0.21385445 | U84: 0.0029101426 | V84: 0.99942594 | W84: 0.00057373389 | X84: 0.43499227 | Y84: 0.245774 | Z84: 0.11647585 | AA84: 0.00088454665 | AB84: 63
A85: 1209 | B85: 45448 | C85: 01:59:47pm | D85: 4.71 | E85: 905 | F85: U23 | G85: 500935a376bc7075 | H85: 13009 | I85: =VLOOKUP(H85,Sheet1!H:AE,2) -> 3 | J85: =VLOOKUP(H85,Sheet1!H:T,3,FALSE) -> 22" | K85: =VLOOKUP($H85,Sheet1!H:$AE,4,FALSE) -> 100000 | L85: =VLOOKUP($H85,Sheet1!$H:$AE,5,FALSE) -> Zorro | M85: =VLOOKUP($H85,Sheet1!$H:$AE,13,FALSE) -> 1891 | N85: 2507.2926 | O85: 1331818.3 | P85: 16499.335 | Q85: 15968130 | R85: 0.35759408 | S85: 0.0026581701 | T85: 0.22721252 | U85: 0.0026885739 | V85: 0.87313433 | W85: 0.11077077 | X85: 0.42179707 | Y85: 0.2438843 | Z85: 0.10154143 | AA85: 0.00081137284 | AB85: 48
A86: 1210 | B86: 45448 | C86: 02:00:04pm | D86: 4.71 | E86: 905 | F86: U25 | G86: 500935b4198bcba9 | H86: 14009 | I86: =VLOOKUP(H86,Sheet1!H:AE,2) -> 3 | J86: =VLOOKUP(H86,Sheet1!H:T,3,FALSE) -> 22" | K86: =VLOOKUP($H86,Sheet1!H:$AE,4,FALSE) -> 100000 | L86: =VLOOKUP($H86,Sheet1!$H:$AE,5,FALSE) -> Eclipse | M86: =VLOOKUP($H86,Sheet1!$H:$AE,13,FALSE) -> 2304 | N86: 2439.3217 | O86: 1171532.4 | P86: 15852.924 | Q86: 16657961 | R86: 0.38582737 | S86: 0.0027849387 | T86: 0.26033984 | U86: 0.0031138986 | V86: 1 | W86: 0 | X86: 0.4911932 | Y86: 0.24992244 | Z86: 0.10079552 | AA86: 0.0011483677 | AB86: 88
A87: 1211 | B87: 45448 | C87: 02:00:20pm | D87: 4.71 | E87: 905 | F87: U27 | G87: 500935c4304d8100 | H87: 15009 | I87: =VLOOKUP(H87,Sheet1!H:AE,2) -> 3 | J87: =VLOOKUP(H87,Sheet1!H:T,3,FALSE) -> 22" | K87: =VLOOKUP($H87,Sheet1!H:$AE,4,FALSE) -> 100000 | L87: =VLOOKUP($H87,Sheet1!$H:$AE,5,FALSE) -> Red Dawn | M87: =VLOOKUP($H87,Sheet1!$H:$AE,13,FALSE) -> 724 | N87: 2365.9884 | O87: 1715004 | P87: 15601.513 | Q87: 17937418 | R87: 0.37941679 | S87: 0.0025761733 | T87: 0.25065241 | U87: 0.0034124674 | V87: 1 | W87: 0 | X87: 0.58772535 | Y87: 0.24230426 | Z87: 0.084192932 | AA87: 0.0029695729 | AB87: 59
A88: 1212 | B88: 45448 | C88: 02:32:21pm | D88: 4.71 | E88: 905 | F88: U-1 | G88: 50093d455ba62858 | H88: 1013 | I88: =VLOOKUP(H88,Sheet1!H:AE,2) -> 1 | J88: =VLOOKUP(H88,Sheet1!H:T,3,FALSE) -> 22" | K88: =VLOOKUP($H88,Sheet1!H:$AE,4,FALSE) -> 150000 | L88: =VLOOKUP($H88,Sheet1!$H:$AE,5,FALSE) -> Red Rover | M88: =VLOOKUP($H88,Sheet1!$H:$AE,13,FALSE) -> 581 | N88: 2408.6875 | O88: 2199916.3 | P88: 15835.324 | Q88: 21501595 | R88: 0.38420689 | S88: 0.0038922983 | T88: 0.24483595 | U88: 0.0067094168 | V88: 0.99994444 | W88: 5.5552469e-05 | X88: 0.544715 | Y88: 0.24800057 | Z88: 0 | AA88: 0 | AB88: 77
A89: 1213 | B89: 45448 | C89: 02:32:39pm | D89: 4.71 | E89: 905 | F89: U1 | G89: 50093d571304575a | H89: 2013 | I89: =VLOOKUP(H89,Sheet1!H:AE,2) -> 1 | J89: =VLOOKUP(H89,Sheet1!H:T,3,FALSE) -> 22" | K89: =VLOOKUP($H89,Sheet1!H:$AE,4,FALSE) -> 150000 | L89: =VLOOKUP($H89,Sheet1!$H:$AE,5,FALSE) -> Zorro | M89: =VLOOKUP($H89,Sheet1!$H:$AE,13,FALSE) -> 1967 | N89: 2578.4627 | O89: 2228329.7 | P89: 15908.515 | Q89: 16704658 | R89: 0.35624765 | S89: 0.0029483156 | T89: 0.23091101 | U89: 0.005199661 | V89: 0.99629623 | W89: 0.0036900544 | X89: 0.59284242 | Y89: 0.24138029 | Z89: 0.10455132 | AA89: 0.00099505154 | AB89: 69
A90: 1214 | B90: 45448 | C90: 02:32:58pm | D90: 4.71 | E90: 905 | F90: U3 | G90: 50093d6a24602668 | H90: 3013 | I90: =VLOOKUP(H90,Sheet1!H:AE,2) -> 1 | J90: =VLOOKUP(H90,Sheet1!H:T,3,FALSE) -> 22" | K90: =VLOOKUP($H90,Sheet1!H:$AE,4,FALSE) -> 150000 | L90: =VLOOKUP($H90,Sheet1!$H:$AE,5,FALSE) -> Apex | M90: =VLOOKUP($H90,Sheet1!$H:$AE,13,FALSE) -> 2729 | N90: 2881.9484 | O90: 2677962.7 | P90: 15778.679 | Q90: 15868351 | R90: 0.35236681 | S90: 0.0029668417 | T90: 0.2338497 | U90: 0.0061697759 | V90: 0.9927963 | W90: 0.0071518104 | X90: 0.76076013 | Y90: 0.18200415 | Z90: 0.094957034 | AA90: 0.00084252625 | AB90: 78
A91: 1215 | B91: 45448 | C91: 02:33:16pm | D91: 4.71 | E91: 905 | F91: U5 | G91: 50093d7c32e40d45 | H91: 4013 | I91: =VLOOKUP(H91,Sheet1!H:AE,2) -> 1 | J91: =VLOOKUP(H91,Sheet1!H:T,3,FALSE) -> 22" | K91: =VLOOKUP($H91,Sheet1!H:$AE,4,FALSE) -> 150000 | L91: =VLOOKUP($H91,Sheet1!$H:$AE,5,FALSE) -> Merlot | M91: =VLOOKUP($H91,Sheet1!$H:$AE,13,FALSE) -> 1973 | N91: 2695.2886 | O91: 1010818.6 | P91: 16844.589 | Q91: 14467335 | R91: 0.35517836 | S91: 0.0022290723 | T91: 0.22485858 | U91: 0.0022737087 | V91: 0.91457091 | W91: 0.078130961 | X91: 0.59084175 | Y91: 0.24174778 | Z91: 0.090307155 | AA91: 0.00095910824 | AB91: 44
A92: 1216 | B92: 45448 | C92: 02:33:34pm | D92: 4.71 | E92: 905 | F92: U7 | G92: 50093d8e01acb101 | H92: 5013 | I92: =VLOOKUP(H92,Sheet1!H:AE,2) -> 2 | J92: =VLOOKUP(H92,Sheet1!H:T,3,FALSE) -> 22" | K92: =VLOOKUP($H92,Sheet1!H:$AE,4,FALSE) -> 150000 | L92: =VLOOKUP($H92,Sheet1!$H:$AE,5,FALSE) -> Red Dawn | M92: =VLOOKUP($H92,Sheet1!$H:$AE,13,FALSE) -> 580 | N92: 2917.3852 | O92: 3029015.9 | P92: 16225.683 | Q92: 20018446 | R92: 0.3716683 | S92: 0.0033586344 | T92: 0.24740705 | U92: 0.0064326428 | V92: 0.99727788 | W92: 0.0027147115 | X92: 0.63379776 | Y92: 0.23209816 | Z92: 0.08587291 | AA92: 0.00087433742 | AB92: 74
...

Sheet Sheet1
A1: Experiment Name | B1: BARCODE_128 | C1: Org Name | D1: Locn | E1: Plot | F1: Identity1 | G1: Description1 | H1: qGIS plot number | I1: BLOC | J1: SPACING | K1: DENSITY | L1: VARIETY | M1: Treatment | N1: Mason Plot # | O1: Plot Range | P1: Plot Column | Q1: 100 Seed weight | R1: Moisture | S1: Plot Weight | T1: Yield | U1: Flowering Date | V1: Maturity Date | W1: HAsum | X1: HAmean | Y1: AdjustedYield | Z1: Weighted Adjustment(0.5) | AA1: WeightedYield | AB1: AlgoYield | AC1: WeightedAdjustment(0.35) | AD1: WeightedYield(0.35) | AE1: AlgoYield2 | AF1: Comments | AG1: Check | AH1: Planter
A2: 24101-n | B2: 17A4AB3390 | D2: LODS | E2: 1 | H2: 1001 | I2: 1 | J2: 30" | K2: 100000 | L2: Nautica | M2: 68 | N2: 101 | O2: 1 | P2: 1 | Q2: 39 | R2: 19.8 | S2: 1772 | T2: 2280 | U2: 45497 | V2: 45536 | W2: 131707 | X2: 0.86650482 | Y2: 2631.2606 | Z2: =1-((0.95-X2)*0.5) -> 0.95825241 | AA2: =T2/Z2 -> 2379.3313 | AB2: {=_xlfn.IFS(X2<0.6,T2,0.9<X2,T2,X2,AA2)} -> 2379.3313 | AC2: 0.95327669 | AD2: 2562.812 | AE2: 2562.812 | AG2: 0 | AH2: 1
A3: 24101-n | B3: 17DD20C9A0 | D3: LODS | E3: 2 | H3: 2001 | I3: 1 | J3: 30" | K3: 100000 | L3: CLERK | M3: 64 | N3: 201 | O3: 2 | P3: 1 | Q3: 67 | R3: 23.8 | S3: 635 | T3: 776 | U3: 45496 | V3: 45536 | W3: 151510 | X3: 0.99678287 | Y3: 778.50455 | Z3: =1-((0.95-X3)*0.5) -> 1.0233914 | AA3: =T3/Z3 -> 758.26314 | AB3: {=_xlfn.IFS(X3<0.6,T3,0.9<X3,T3,X3,AA3)} -> 776 | AC3: 0.99887401 | AD3: 778.12642 | AE3: 776 | AG3: 0 | AH3: 2
A4: 24101-n | B4: 1143BB41EA | D4: LODS | E4: 3 | H4: 3001 | I4: 1 | J4: 30" | K4: 100000 | L4: Windbreaker | M4: 74 | N4: 301 | O4: 3 | P4: 1 | Q4: 42 | R4: 21.2 | S4: 1586 | T4: 2005 | U4: 45494 | V4: 45527 | W4: 151855 | X4: 0.99903948 | Y4: 2006.9277 | Z4: =1-((0.95-X4)*0.5) -> 1.0245197 | AA4: =T4/Z4 -> 1957.0145 | AB4: {=_xlfn.IFS(X4<0.6,T4,0.9<X4,T4,X4,AA4)} -> 2005 | AC4: 0.99966382 | AD4: 2006.638 | AE4: 2005 | AG4: 0 | AH4: 3
A5: 24101-n | B5: 197BBB7845 | D5: LODS | E5: 4 | H5: 4001 | I5: 1 | J5: 30" | K5: 100000 | L5: Zorro | M5: 75 | N5: 401 | O5: 4 | P5: 1 | Q5: 27 | R5: 21.5 | S5: 1519 | T5: 1913 | U5: 45494 | V5: 45528 | W5: 144210 | X5: 0.94875624 | Y5: 2016.324 | Z5: =1-((0.95-X5)*0.5) -> 0.99937812 | AA5: =T5/Z5 -> 1914.1904 | AB5: {=_xlfn.IFS(X5<0.6,T5,0.9<X5,T5,X5,AA5)} -> 1913 | AC5: 0.98206468 | AD5: 1999.1591 | AE5: 1913 | AG5: 0 | AH5: 4
A6: 24101-n | B6: 1A09581714 | D6: LODS | E6: 5 | H6: 5001 | I6: 1 | J6: 30" | K6: 100000 | L6: Eclipse | M6: 65 | N6: 501 | O6: 5 | P6: 1 | Q6: 26 | R6: 19.4 | S6: 1534 | T6: 1984 | U6: 45496 | V6: 45530 | W6: 151698 | X6: 0.99801316 | Y6: 1987.9497 | Z6: =1-((0.95-X6)*0.5) -> 1.0240066 | AA6: =T6/Z6 -> 1937.4876 | AB6: {=_xlfn.IFS(X6<0.6,T6,0.9<X6,T6,X6,AA6)} -> 1984 | AC6: 0.9993046 | AD6: 1987.3549 | AE6: 1984 | AG6: 0 | AH6: 5
A7: 24101-n | B7: 178E433348 | D7: LODS | E7: 6 | H7: 6001 | I7: 1 | J7: 30" | K7: 100000 | L7: Apex | M7: 61 | N7: 601 | O7: 6 | P7: 1 | Q7: 52 | R7: 25.6 | S7: 1417 | T7: 1692 | U7: 45493 | V7: 45536 | W7: 129965 | X7: 0.85502164 | Y7: 1978.8973 | Z7: =1-((0.95-X7)*0.5) -> 0.95251082 | AA7: =T7/Z7 -> 1776.3578 | AB7: {=_xlfn.IFS(X7<0.6,T7,0.9<X7,T7,X7,AA7)} -> 1776.3578 | AC7: 0.94925757 | AD7: 1921.7518 | AE7: 1921.7518 | AG7: 0 | AH7: 6
A8: 24101-n | B8: 1647132305 | D8: LODS | E8: 7 | H8: 7001 | I8: 1 | J8: 30" | K8: 100000 | L8: Redhawk | M8: 71 | N8: 701 | O8: 7 | P8: 1 | Q8: -9 | R8: -9 | S8: -9 | U8: 45490 | V8: 45525 | W8: 141596 | X8: 0.93154037 | Z8: =1-((0.95-X8)*0.5) -> 0.99077019 | AG8: 0 | AH8: 7
A9: 24101-n | B9: 1A2F8E059F | D9: LODS | E9: 8 | H9: 8001 | I9: 1 | J9: 30" | K9: 100000 | L9: ETNA | M9: 66 | N9: 801 | O9: 8 | P9: 1 | Q9: 41 | R9: 18.2 | S9: 851 | T9: 1117 | U9: 45489 | V9: 45523 | W9: 146571 | X9: 0.96428289 | Y9: 1158.3738 | Z9: =1-((0.95-X9)*0.5) -> 1.0071414 | AA9: =T9/Z9 -> 1109.0796 | AB9: {=_xlfn.IFS(X9<0.6,T9,0.9<X9,T9,X9,AA9)} -> 1117 | AC9: 0.98749901 | AD9: 1151.7082 | AE9: 1117 | AG9: 0 | AH9: 8
A10: 24101-n | B10: 1047A4D661 | D10: LODS | E10: 9 | H10: 9001 | I10: 1 | J10: 30" | K10: 100000 | L10: black bear | M10: 62 | N10: 901 | O10: 9 | P10: 1 | Q10: 25 | R10: 19.6 | S10: 1633 | T10: 2107 | U10: 45499 | V10: 45534 | W10: 151495 | X10: 0.99667107 | Y10: 2114.0375 | Z10: =1-((0.95-X10)*0.5) -> 1.0233355 | AA10: =T10/Z10 -> 2058.9532 | AB10: {=_xlfn.IFS(X10<0.6,T10,0.9<X10,T10,X10,AA10)} -> 2107 | AC10: 0.99883488 | AD10: 2112.9747 | AE10: 2107 | AG10: 0 | AH10: 9
A11: 24101-n | B11: 161743762B | D11: LODS | E11: 10 | H11: 10001 | I11: 1 | J11: 30" | K11: 100000 | L11: Ronnies red | M11: 72 | N11: 1001 | O11: 10 | P11: 1 | Q11: 72 | R11: 23 | S11: 590 | T11: 729 | U11: 45497 | V11: 45537 | W11: 149980 | X11: 0.98671053 | Y11: 738.81851 | Z11: =1-((0.95-X11)*0.5) -> 1.0183553 | AA11: =T11/Z11 -> 715.8602 | AB11: {=_xlfn.IFS(X11<0.6,T11,0.9<X11,T11,X11,AA11)} -> 729 | AC11: 0.99534868 | AD11: 737.30586 | AE11: 729 | AG11: 0 | AH11: 10
A12: 24101-n | B12: 11FBF792FB | D12: LODS | E12: 11 | H12: 11001 | I12: 1 | J12: 30" | K12: 100000 | L12: T9905 | M12: 73 | N12: 1101 | O12: 11 | P12: 1 | Q12: 26 | R12: 21.3 | S12: 1675 | T12: 2115 | U12: 45499 | V12: 45534 | W12: 149211 | X12: 0.98165132 | Y12: 2154.5328 | Z12: =1-((0.95-X12)*0.5) -> 1.0158257 | AA12: =T12/Z12 -> 2082.0502 | AB12: {=_xlfn.IFS(X12<0.6,T12,0.9<X12,T12,X12,AA12)} -> 2115 | AC12: 0.99357796 | AD12: 2148.3804 | AE12: 2115 | AG12: 0 | AH12: 11
A13: 24101-n | B13: 14D1D74C4F | D13: LODS | E13: 12 | H13: 12001 | I13: 1 | J13: 30" | K13: 100000 | L13: Red Rover | M13: 70 | N13: 1201 | O13: 12 | P13: 1 | Q13: 60 | R13: 20.7 | S13: 642 | T13: 817 | U13: 45491 | V13: 45524 | W13: 151820 | X13: 0.99880922 | Y13: 817.97403 | Z13: =1-((0.95-X13)*0.5) -> 1.0244046 | AA13: =T13/Z13 -> 797.53644 | AB13: {=_xlfn.IFS(X13<0.6,T13,0.9<X13,T13,X13,AA13)} -> 817 | AC13: 0.99958323 | AD13: 817.82757 | AE13: 817 | AG13: 0 | AH13: 12
A14: 24101-n | B14: 1913C5BCE2 | D14: LODS | E14: 13 | H14: 13001 | I14: 1 | J14: 30" | K14: 100000 | L14: Merlot | M14: 67 | N14: 1301 | O14: 13 | P14: 1 | Q14: 40 | R14: 19.5 | S14: 1360 | T14: 1757 | U14: 45498 | V14: 45536 | W14: 129422 | X14: 0.85145492 | Y14: 2063.5267 | Z14: =1-((0.95-X14)*0.5) -> 0.95072746 | AA14: =T14/Z14 -> 1848.0585 | AB14: {=_xlfn.IFS(X14<0.6,T14,0.9<X14,T14,X14,AA14)} -> 1848.0585 | AC14: 0.94800922 | AD14: 2002.0552 | AE14: 2002.0552 | AG14: 0 | AH14: 13
A15: 24101-n | B15: 1F3E3C7202 | D15: LODS | E15: 14 | H15: 14001 | I15: 1 | J15: 30" | K15: 100000 | L15: Red Dawn | M15: 69 | N15: 1401 | O15: 14 | P15: 1 | Q15: 61 | R15: 20.1 | S15: 427 | T15: 547 | U15: 45491 | V15: 45525 | W15: 150318 | X15: 0.98895373 | Y15: 553.1098 | Z15: =1-((0.95-X15)*0.5) -> 1.0194769 | AA15: =T15/Z15 -> 536.54969 | AB15: {=_xlfn.IFS(X15<0.6,T15,0.9<X15,T15,X15,AA15)} -> 547 | AC15: 0.99613381 | AD15: 552.17274 | AE15: 547 | AG15: 0 | AH15: 14
A16: 24101-n | B16: 1ECBE9100C | D16: LODS | E16: 15 | H16: 15001 | I16: 1 | J16: 30" | K16: 100000 | L16: Cayenne | M16: 63 | N16: 1501 | O16: 15 | P16: 1 | Q16: 40 | R16: 20.6 | S16: 1809 | T16: 2305 | U16: 45495 | V16: 45533 | W16: 145383 | X16: 0.95646081 | Y16: 2409.9262 | Z16: =1-((0.95-X16)*0.5) -> 1.0032304 | AA16: =T16/Z16 -> 2297.5779 | AB16: {=_xlfn.IFS(X16<0.6,T16,0.9<X16,T16,X16,AA16)} -> 2305 | AC16: 0.98476129 | AD16: 2392.7582 | AE16: 2305 | AG16: 0 | AH16: 15
A17: 24101-n | B17: 13C7E686AA | D17: LODS | E17: 16 | H17: 15002 | I17: 1 | J17: 30" | K17: 150000 | L17: Ronnies red | M17: 87 | N17: 1502 | O17: 15 | P17: 2 | Q17: 82 | R17: 22 | S17: 664 | T17: 831 | U17: 45494 | W17: 151993 | X17: 0.99997368 | Y17: 831.02187 | Z17: =1-((0.95-X17)*0.5) -> 1.0249868 | AA17: =T17/Z17 -> 810.74211 | AB17: {=_xlfn.IFS(X17<0.6,T17,0.9<X17,T17,X17,AA17)} -> 831 | AC17: 0.99999079 | AD17: 831.01859 | AE17: 831 | AG17: 0 | AH17: 16
A18: 24101-n | B18: 1EE98D13AE | D18: LODS | E18: 17 | H18: 14002 | I18: 1 | J18: 30" | K18: 150000 | L18: Red Dawn | M18: 84 | N18: 1402 | O18: 14 | P18: 2 | Q18: 65 | R18: 20.5 | S18: 595 | T18: 759 | U18: 45492 | V18: 45525 | W18: 149613 | X18: 0.98428958 | Y18: 771.11454 | Z18: =1-((0.95-X18)*0.5) -> 1.0171448 | AA18: =T18/Z18 -> 746.20645 | AB18: {=_xlfn.IFS(X18<0.6,T18,0.9<X18,T18,X18,AA18)} -> 759 | AC18: 0.99450135 | AD18: 769.23908 | AE18: 759 | AG18: 0 | AH18: 17
A19: 24101-n | B19: 17B74EF533 | D19: LODS | E19: 18 | H19: 13002 | I19: 1 | J19: 30" | K19: 150000 | L19: Redhawk | M19: 86 | N19: 1302 | O19: 13 | P19: 2 | Q19: 61 | R19: 21.2 | S19: 763 | T19: 965 | U19: 45493 | V19: 45530 | W19: 149562 | X19: 0.98397347 | Y19: 980.7175 | Z19: =1-((0.95-X19)*0.5) -> 1.0169867 | AA19: =T19/Z19 -> 948.8816 | AB19: {=_xlfn.IFS(X19<0.6,T19,0.9<X19,T19,X19,AA19)} -> 965 | AC19: 0.99439072 | AD19: 978.28273 | AE19: 965 | AG19: 0 | AH19: 18
A20: 24101-n | B20: 11EC8AEE89 | D20: LODS | E20: 19 | H20: 12002 | I20: 1 | J20: 30" | K20: 150000 | L20: Red Rover | M20: 85 | N20: 1202 | O20: 12 | P20: 2 | Q20: 57 | R20: 21.2 | S20: 1338 | T20: 1692 | U20: 45492 | V20: 45526 | W20: 150834 | X20: 0.99234201 | Y20: 1705.0573 | Z20: =1-((0.95-X20)*0.5) -> 1.021171 | AA20: =T20/Z20 -> 1656.9213 | AB20: {=_xlfn.IFS(X20<0.6,T20,0.9<X20,T20,X20,AA20)} -> 1692 | AC20: 0.9973197 | AD20: 1703.0683 | AE20: 1692 | AG20: 0 | AH20: 19
A21: 24101-n | B21: 1B9839AAA6 | D21: LODS | E21: 20 | H21: 11002 | I21: 1 | J21: 30" | K21: 150000 | L21: CLERK | M21: 79 | N21: 1102 | O21: 11 | P21: 2 | Q21: 70 | R21: 23 | S21: 963 | T21: 1190 | U21: 45498 | V21: 45538 | W21: 149803 | X21: 0.98554605 | Y21: 1207.4525 | Z21: =1-((0.95-X21)*0.5) -> 1.017773 | AA21: =T21/Z21 -> 1169.2194 | AB21: {=_xlfn.IFS(X21<0.6,T21,0.9<X21,T21,X21,AA21)} -> 1190 | AC21: 0.99494112 | AD21: 1204.7574 | AE21: 1190 | AG21: 0 | AH21: 20
A22: 24101-n | B22: 128FFC5EE2 | D22: LODS | E22: 21 | H22: 10002 | I22: 1 | J22: 30" | K22: 150000 | L22: Windbreaker | M22: 89 | N22: 1002 | O22: 10 | P22: 2 | Q22: 45 | R22: 20.2 | S22: 1444 | T22: 1849 | U22: 45493 | V22: 45528 | W22: 151879 | X22: 0.99920395 | Y22: 1850.4731 | Z22: =1-((0.95-X22)*0.5) -> 1.024602 | AA22: =T22/Z22 -> 1804.6032 | AB22: {=_xlfn.IFS(X22<0.6,T22,0.9<X22,T22,X22,AA22)} -> 1849 | AC22: 0.99972138 | AD22: 1850.2518 | AE22: 1849 | AG22: 0 | AH22: 21
A23: 24101-n | B23: 17D142D80C | D23: LODS | E23: 22 | H23: 9002 | I23: 1 | J23: 30" | K23: 150000 | L23: Apex | M23: 76 | N23: 902 | O23: 9 | P23: 2 | Q23: 28 | R23: 20.3 | S23: 2220 | T23: 2839 | U23: 45497 | V23: 45535 | W23: 147339 | X23: 0.96932277 | Y23: 2928.849 | Z23: =1-((0.95-X23)*0.5) -> 1.0096614 | AA23: =T23/Z23 -> 2811.8338 | AB23: {=_xlfn.IFS(X23<0.6,T23,0.9<X23,T23,X23,AA23)} -> 2839 | AC23: 0.98926297 | AD23: 2914.5179 | AE23: 2839 | AG23: 0 | AH23: 22
A24: 24101-n | B24: 13D7345BF6 | D24: LODS | E24: 23 | H24: 8002 | I24: 1 | J24: 30" | K24: 150000 | L24: black bear | M24: 77 | N24: 802 | O24: 8 | P24: 2 | Q24: 60 | R24: 19 | S24: 1885 | T24: 2450 | U24: 45496 | V24: 45533 | W24: 151632 | X24: 0.99757895 | Y24: 2455.946 | Z24: =1-((0.95-X24)*0.5) -> 1.0237895 | AA24: =T24/Z24 -> 2393.0701 | AB24: {=_xlfn.IFS(X24<0.6,T24,0.9<X24,T24,X24,AA24)} -> 2450 | AC24: 0.99915263 | AD24: 2455.0497 | AE24: 2450 | AG24: 0 | AH24: 23
A25: 24101-n | B25: 135525D516 | D25: LODS | E25: 24 | H25: 7002 | I25: 1 | J25: 30" | K25: 150000 | L25: T9905 | M25: 88 | N25: 702 | O25: 7 | P25: 2 | Q25: 27 | R25: 20 | S25: 2001 | T25: 2569 | U25: 45497 | V25: 45534 | W25: 123769 | X25: 0.81426974 | Y25: 3154.9742 | Z25: =1-((0.95-X25)*0.5) -> 0.93213487 | AA25: =T25/Z25 -> 2756.0389 | AB25: {=_xlfn.IFS(X25<0.6,T25,0.9<X25,T25,X25,AA25)} -> 2756.0389 | AC25: 0.93499441 | AD25: 3028.8881 | AE25: 3028.8881 | AG25: 0 | AH25: 24
A26: 24101-n | B26: 1ED16701A9 | D26: LODS | E26: 25 | H26: 6002 | I26: 1 | J26: 30" | K26: 150000 | L26: Eclipse | M26: 80 | N26: 602 | O26: 6 | P26: 2 | Q26: 27 | R26: 19.4 | S26: 2351 | T26: 3041 | U26: 45493 | V26: 45531 | W26: 151962 | X26: 0.99976316 | Y26: 3041.7204 | Z26: =1-((0.95-X26)*0.5) -> 1.0248816 | AA26: =T26/Z26 -> 2967.1721 | AB26: {=_xlfn.IFS(X26<0.6,T26,0.9<X26,T26,X26,AA26)} -> 3041 | AC26: 0.9999171 | AD26: 3041.6123 | AE26: 3041 | AG26: 0 | AH26: 25
A27: 24101-n | B27: 1BF894EAAD | D27: LODS | E27: 26 | H27: 5002 | I27: 1 | J27: 30" | K27: 150000 | L27: Nautica | M27: 83 | N27: 502 | O27: 5 | P27: 2 | Q27: 48 | R27: 18.9 | S27: 1705 | T27: 2219 | U27: 45495 | V27: 45532 | W27: 149375 | X27: 0.9827238 | Y27: 2258.0098 | Z27: =1-((0.95-X27)*0.5) -> 1.0163619 | AA27: =T27/Z27 -> 2183.2774 | AB27: {=_xlfn.IFS(X27<0.6,T27,0.9<X27,T27,X27,AA27)} -> 2219 | AC27: 0.99395333 | AD27: 2251.9518 | AE27: 2219 | AG27: 0 | AH27: 26
A28: 24101-n | B28: 1CFB818B13 | D28: LODS | E28: 27 | H28: 4002 | I28: 1 | J28: 30" | K28: 150000 | L28: Merlot | M28: 82 | N28: 402 | O28: 4 | P28: 2 | Q28: 38 | R28: 19.7 | S28: 1394 | T28: 1796 | U28: 45493 | V28: 45530 | W28: 144312 | X28: 0.94941481 | Y28: 1891.6916 | Z28: =1-((0.95-X28)*0.5) -> 0.9997074 | AA28: =T28/Z28 -> 1796.5257 | AB28: {=_xlfn.IFS(X28<0.6,T28,0.9<X28,T28,X28,AA28)} -> 1796 | AC28: 0.98229518 | AD28: 1875.8152 | AE28: 1796 | AG28: 0 | AH28: 27
A29: 24101-n | B29: 1FA7816CE1 | D29: LODS | E29: 28 | H29: 3002 | I29: 1 | J29: 30" | K29: 150000 | L29: Zorro | M29: 90 | N29: 302 | O29: 3 | P29: 2 | Q29: 25 | R29: 19.4 | S29: 2071 | T29: 2678 | U29: 45495 | V29: 45530 | W29: 148840 | X29: 0.97921053 | Y29: 2734.8562 | Z29: =1-((0.95-X29)*0.5) -> 1.0146053 | AA29: =T29/Z29 -> 2639.4501 | AB29: {=_xlfn.IFS(X29<0.6,T29,0.9<X29,T29,X29,AA29)} -> 2678 | AC29: 0.99272368 | AD29: 2725.9645 | AE29: 2678 | AG29: 0 | AH29: 28
A30: 24101-n | B30: 167E0CFA3F | D30: LODS | E30: 29 | H30: 2002 | I30: 1 | J30: 30" | K30: 150000 | L30: Cayenne | M30: 78 | N30: 202 | O30: 2 | P30: 2 | U30: 45493 | V30: 45534 | W30: 149240 | X30: 0.98184211 | AG30: 0 | AH30: 29
A31: 24101-n | B31: 1EB5B01FFF | D31: LODS | E31: 30 | H31: 1002 | I31: 1 | J31: 30" | K31: 150000 | L31: ETNA | M31: 81 | N31: 102 | O31: 1 | P31: 2 | Q31: 47 | R31: 19.2 | S31: 1967 | T31: 2550 | U31: 45490 | V31: 45524 | W31: 143320 | X31: 0.94289474 | Y31: 2704.4376 | Z31: =1-((0.95-X31)*0.5) -> 0.99644737 | AA31: =T31/Z31 -> 2559.0915 | AB31: {=_xlfn.IFS(X31<0.6,T31,0.9<X31,T31,X31,AA31)} -> 2550 | AC31: 0.98001316 | AD31: 2678.4836 | AE31: 2550 | AG31: 0 | AH31: 30
A32: 24101-n | B32: 114965A262 | D32: LODS | E32: 31 | H32: 1003 | I32: 1 | J32: 30" | K32: 75000 | L32: Red Rover | M32: 55 | N32: 103 | O32: 1 | P32: 3 | U32: 45489 | V32: 45525 | W32: 149940 | X32: 0.98644088 | AG32: 0 | AH32: 31
A33: 24101-n | B33: 13EFA08461 | D33: LODS | E33: 32 | H33: 2003 | I33: 1 | J33: 30" | K33: 75000 | L33: T9905 | M33: 58 | N33: 203 | O33: 2 | P33: 3 | Q33: 38 | R33: 21 | S33: 1637 | T33: 2075 | U33: 45497 | V33: 45534 | W33: 147503 | X33: 0.97040809 | Y33: 2138.2757 | Z33: =1-((0.95-X33)*0.5) -> 1.010204 | AA33: =T33/Z33 -> 2054.0405 | AB33: {=_xlfn.IFS(X33<0.6,T33,0.9<X33,T33,X33,AA33)} -> 2075 | AC33: 0.98964283 | AD33: 2128.2049 | AE33: 2075 | AG33: 0 | AH33: 32
A34: 24101-n | B34: 15158A5F69 | D34: LODS | E34: 33 | H34: 3003 | I34: 1 | J34: 30" | K34: 75000 | L34: black bear | M34: 47 | N34: 303 | O34: 3 | P34: 3 | Q34: 26 | R34: 21.7 | S34: 1836 | T34: 2307 | U34: 45496 | V34: 45535 | W34: 134790 | X34: 0.88678215 | Y34: 2601.5409 | Z34: =1-((0.95-X34)*0.5) -> 0.96839107 | AA34: =T34/Z34 -> 2382.302 | AB34: {=_xlfn.IFS(X34<0.6,T34,0.9<X34,T34,X34,AA34)} -> 2382.302 | AC34: 0.96037375 | AD34: 2546.3351 | AE34: 2546.3351 | AG34: 0 | AH34: 33
A35: 24101-n | B35: 1D59F1C964 | D35: LODS | E35: 34 | H35: 4003 | I35: 1 | J35: 30" | K35: 75000 | L35: Zorro | M35: 60 | N35: 403 | O35: 4 | P35: 3 | Q35: 28 | R35: 19.6 | S35: 1320 | T35: 1703 | U35: 45496 | V35: 45530 | W35: 126330 | X35: 0.83111295 | Y35: 2049.0596 | Z35: =1-((0.95-X35)*0.5) -> 0.94055648 | AA35: =T35/Z35 -> 1810.6302 | AB35: {=_xlfn.IFS(X35<0.6,T35,0.9<X35,T35,X35,AA35)} -> 1810.6302 | AC35: 0.94088953 | AD35: 1976.9281 | AE35: 1976.9281 | AG35: 0 | AH35: 34
A36: 24101-n | B36: 142BD536E6 | D36: LODS | E36: 35 | H36: 5003 | I36: 1 | J36: 30" | K36: 75000 | L36: Ronnies red | M36: 57 | N36: 503 | O36: 5 | P36: 3 | Q36: 70 | R36: 22 | S36: 693 | T36: 867 | U36: 45495 | W36: 144507 | X36: 0.95069144 | Y36: 911.96782 | Z36: =1-((0.95-X36)*0.5) -> 1.0003457 | AA36: =T36/Z36 -> 866.70037 | AB36: {=_xlfn.IFS(X36<0.6,T36,0.9<X36,T36,X36,AA36)} -> 867 | AC36: 0.982742 | AD36: 904.52588 | AE36: 867 | AG36: 0 | AH36: 35
A37: 24101-n | B37: 1DBB1A7FEC | D37: LODS | E37: 36 | H37: 6003 | I37: 1 | J37: 30" | K37: 75000 | L37: ETNA | M37: 51 | N37: 603 | O37: 6 | P37: 3 | Q37: 58 | R37: 23 | S37: 828 | T37: 1023 | U37: 45492 | V37: 45525 | W37: 144415 | X37: 0.95009868 | Y37: 1076.7303 | Z37: =1-((0.95-X37)*0.5) -> 1.0000493 | AA37: =T37/Z37 -> 1022.9495 | AB37: {=_xlfn.IFS(X37<0.6,T37,0.9<X37,T37,X37,AA37)} -> 1023 | AC37: 0.98253454 | AD37: 1067.8278 | AE37: 1023 | AG37: 0 | AH37: 36
A38: 24101-n | B38: 1CB9084CD5 | D38: LODS | E38: 37 | H38: 7003 | I38: 1 | J38: 30" | K38: 75000 | L38: Red Dawn | M38: 54 | N38: 703 | O38: 7 | P38: 3 | Q38: 65 | R38: 20.6 | S38: 553 | T38: 705 | U38: 45489 | V38: 45524 | W38: 148085 | X38: 0.97424342 | Y38: 723.63845 | Z38: =1-((0.95-X38)*0.5) -> 1.0121217 | AA38: =T38/Z38 -> 696.55654 | AB38: {=_xlfn.IFS(X38<0.6,T38,0.9<X38,T38,X38,AA38)} -> 705 | AC38: 0.9909852 | AD38: 720.69456 | AE38: 705 | AG38: 0 | AH38: 37
A39: 24101-n | B39: 13519E0F5D | D39: LODS | E39: 38 | H39: 8003 | I39: 1 | J39: 30" | K39: 75000 | L39: CLERK | M39: 49 | N39: 803 | O39: 8 | P39: 3 | Q39: 67 | R39: 23 | S39: 722 | T39: 892 | U39: 45496 | W39: 142067 | X39: 0.93465747 | Y39: 954.36032 | Z39: =1-((0.95-X39)*0.5) -> 0.99232873 | AA39: =T39/Z39 -> 898.89567 | AB39: {=_xlfn.IFS(X39<0.6,T39,0.9<X39,T39,X39,AA39)} -> 892 | AC39: 0.97713011 | AD39: 943.70959 | AE39: 892 | AG39: 0 | AH39: 38
A40: 24101-n | B40: 1BAF74E1C8 | D40: LODS | E40: 39 | H40: 9003 | I40: 1 | J40: 30" | K40: 75000 | L40: Windbreaker | M40: 59 | N40: 903 | O40: 9 | P40: 3 | Q40: 46 | R40: 19.6 | S40: 1482 | T40: 1912 | U40: 45494 | V40: 45530 | W40: 144393 | X40: 0.94997895 | Y40: 2012.6762 | Z40: =1-((0.95-X40)*0.5) -> 0.99998947 | AA40: =T40/Z40 -> 1912.0201 | AB40: {=_xlfn.IFS(X40<0.6,T40,0.9<X40,T40,X40,AA40)} -> 1912 | AC40: 0.98249263 | AD40: 1995.9914 | AE40: 1912 | AG40: 0 | AH40: 39
...
