Workbook

Sheet 613
A1: fid | B1: Date | C1: DAS | D1: Time | E1: Version | F1: Id | G1: Name | H1: Latitude | I1: Longitude | J1: Height | K1: AlarmRad | L1: WarningRad | M1: Visible | N1: UniqueID | O1: joined_row_index | P1: joined_col_index | Q1: joined_PlotID | R1: joined_PlotIDstring | S1: pntcounts | T1: Thresh_sum | U1: Thresh_mean | V1: NDVI_mean | W1: SAVI_mean | X1: HAreamean | Y1: 613GNDVI_mean | Z1: 613GNDVI_variance | AA1: 613NDRE_mean | AB1: 613NDRE_variance | AC1: 613ExG_mean | AD1: 613ExG_variance | AE1: 613ExR_mean | AF1: 613ExR_variance
A2: 1517 | B2: 45447 | C2: 8 | D2: 01:48:44pm | E2: 4.71 | F2: 905 | G2: U-1 | H2: 45.43295 | I2: -73.939211 | J2: 39.021 | K2: 0 | L2: 0 | M2: 1 | N2: 5009318c201f855b | O2: 0 | P2: 0 | Q2: 101 | R2: 101 | S2: 25 | T2: 138 | U2: 0.001167651 | V2: 0.27746898 | W2: 0.55491244 | X2: 0.69304455 | Y2: 0.079031091 | Z2: 0.0042683876 | AA2: -0.017167418 | AB2: 0.0012096195 | AC2: 2137.9751 | AD2: 1517090.9 | AE2: 15061.102 | AF2: 23748993
A3: 1533 | B3: 45447 | C3: 8 | D3: 02:20:00pm | E3: 4.71 | F3: 905 | G3: D-1 | H3: 45.432925 | I3: -73.939194 | J3: 39.021 | K3: 0 | L3: 0 | M3: 1 | N3: 500938e02a9ec38d | O3: 1 | P3: 0 | Q3: 102 | R3: 102 | S3: 37 | T3: 371 | U3: 0.0031391197 | V3: 0.27399433 | W3: 0.5479642 | X3: 0.89947501 | Y3: 0.074093804 | Z3: 0.0045883674 | AA3: -0.019803941 | AB3: 0.0012961527 | AC3: 2304.8042 | AD3: 1711194.1 | AE3: 15679.66 | AF3: 24504353
A4: 1534 | B4: 45447 | C4: 8 | D4: 02:20:58pm | E4: 4.71 | F4: 905 | G4: U-1 | H4: 45.4329 | I4: -73.939178 | J4: 39.021 | K4: 0 | L4: 0 | M4: 1 | N4: 5009391a2cd19750 | O4: 2 | P4: 0 | Q4: 103 | R4: 103 | S4: 23 | T4: 170 | U4: 0.0014383863 | V4: 0.26976504 | W4: 0.53950542 | X4: 0.71355263 | Y4: 0.070448375 | Z4: 0.0037407828 | AA4: -0.020293419 | AB4: 0.0010596723 | AC4: 2192.1049 | AD4: 1370721.6 | AE4: 15364.241 | AF4: 21781355
A5: 1549 | B5: 45447 | C5: 8 | D5: 02:29:12pm | E5: 4.71 | F5: 905 | G5: D-1 | H5: 45.432875 | I5: -73.939161 | J5: 39.021 | K5: 0 | L5: 0 | M5: 1 | N5: 50093b08785a7bd0 | O5: 3 | P5: 0 | Q5: 104 | R5: 104 | S5: 38 | T5: 272 | U5: 0.0023013986 | V5: 0.2691757 | W5: 0.53832671 | X5: 0.89520915 | Y5: 0.075662778 | Z5: 0.0046806748 | AA5: -0.019924761 | AB5: 0.0012663827 | AC5: 2201.2652 | AD5: 1697353.5 | AE5: 15237.149 | AF5: 25619117
A6: 1550 | B6: 45447 | C6: 8 | D6: 02:30:00pm | E6: 4.71 | F6: 905 | G6: U-1 | H6: 45.43285 | I6: -73.939144 | J6: 39.02 | K6: 0 | L6: 0 | M6: 1 | N6: 50093b3805b857f6 | O6: 4 | P6: 0 | Q6: 105 | R6: 105 | S6: 24 | T6: 171 | U6: 0.0014468841 | V6: 0.26260807 | W6: 0.52519307 | X6: 0.72071053 | Y6: 0.072886261 | Z6: 0.0043785827 | AA6: -0.022465287 | AB6: 0.0013458489 | AC6: 2283.7753 | AD6: 1786230.3 | AE6: 15674.425 | AF6: 23714756
A7: 1565 | B7: 45447 | C7: 8 | D7: 02:34:09pm | E7: 4.71 | F7: 905 | G7: D-1 | H7: 45.432826 | I7: -73.939128 | J7: 39.02 | K7: 0 | L7: 0 | M7: 1 | N7: 50093c313a5b4233 | O7: 5 | P7: 0 | Q7: 106 | R7: 106 | S7: 51 | T7: 387 | U7: 0.0032744164 | V7: 0.27157897 | W7: 0.54313382 | X7: 0.92030473 | Y7: 0.081655012 | Z7: 0.0047209705 | AA7: -0.021756627 | AB7: 0.0013493867 | AC7: 2160.2413 | AD7: 1815564.8 | AE7: 15333.241 | AF7: 25561344
A8: 1566 | B8: 45447 | C8: 8 | D8: 02:35:04pm | E8: 4.71 | F8: 905 | G8: U-1 | H8: 45.432801 | I8: -73.939111 | J8: 39.02 | K8: 0 | L8: 0 | M8: 1 | N8: 50093c68674bddc2 | O8: 6 | P8: 0 | Q8: 107 | R8: 107 | S8: 44 | T8: 376 | U8: 0.003181399 | V8: 0.26986302 | W8: 0.53970165 | X8: 0.83332895 | Y8: 0.077081366 | Z8: 0.0044855443 | AA8: -0.024647895 | AB8: 0.0012381597 | AC8: 2165.9179 | AD8: 1805887 | AE8: 15221.37 | AF8: 23915763
A9: 1519 | B9: 45447 | C9: 8 | D9: 02:15:42pm | E9: 4.71 | F9: 905 | G9: U1 | H9: 45.432976 | I9: -73.93913 | J9: 39.021 | K9: 0 | L9: 0 | M9: 1 | N9: 500937de01a1bd1f | O9: 0 | P9: 1 | Q9: 108 | R9: 108 | S9: 20 | T9: 137 | U9: 0.0011591996 | V9: 0.26480924 | W9: 0.52959376 | X9: 0.63843057 | Y9: 0.070771581 | Z9: 0.0041802878 | AA9: -0.021408005 | AB9: 0.0016182787 | AC9: 1856.7576 | AD9: 1520579.5 | AE9: 14837.603 | AF9: 27082338
A10: 1532 | B10: 45447 | C10: 8 | D10: 02:19:47pm | E10: 4.71 | F10: 905 | G10: D1 | H10: 45.432952 | I10: -73.939113 | J10: 39.021 | K10: 0 | L10: 0 | M10: 1 | N10: 500938d31d4cc688 | O10: 1 | P10: 1 | Q10: 109 | R10: 109 | S10: 16 | T10: 290 | U10: 0.0024537386 | V10: 0.26018324 | W10: 0.52034438 | X10: 0.44924409 | Y10: 0.071512613 | Z10: 0.0048754349 | AA10: -0.02109466 | AB10: 0.0019594199 | AC10: 1940.3627 | AD10: 1775084.8 | AE10: 15949.7 | AF10: 28147606
A11: 1535 | B11: 45447 | C11: 8 | D11: 02:21:11pm | E11: 4.71 | F11: 905 | G11: U1 | H11: 45.432926 | I11: -73.939096 | J11: 39.021 | K11: 0 | L11: 0 | M11: 1 | N11: 500939272161cf8e | O11: 2 | P11: 1 | Q11: 110 | R11: 110 | S11: 5 | T11: 25 | U11: 0.0002115274 | V11: 0.25887909 | W11: 0.51773536 | X11: 0.12018421 | Y11: 0.064247564 | Z11: 0.0038435659 | AA11: -0.024110931 | AB11: 0.001627755 | AC11: 1982.1856 | AD11: 1707275 | AE11: 15594.698 | AF11: 25744214
A12: 1548 | B12: 45447 | C12: 8 | D12: 02:28:59pm | E12: 4.71 | F12: 905 | G12: D1 | H12: 45.432902 | I12: -73.93908 | J12: 39.02 | K12: 0 | L12: 0 | M12: 1 | N12: 50093afb12549ffc | O12: 3 | P12: 1 | Q12: 111 | R12: 111 | S12: 27 | T12: 211 | U12: 0.0017852912 | V12: 0.26070016 | W12: 0.52137729 | X12: 0.78234211 | Y12: 0.06862375 | Z12: 0.0043838065 | AA12: -0.023128824 | AB12: 0.0017021533 | AC12: 2067.3461 | AD12: 1661777.2 | AE12: 15646.277 | AF12: 26997978
A13: 1551 | B13: 45447 | C13: 8 | D13: 02:30:13pm | E13: 4.71 | F13: 905 | G13: U1 | H13: 45.432877 | I13: -73.939063 | J13: 39.02 | K13: 0 | L13: 0 | M13: 1 | N13: 50093b45131a1f8a | O13: 4 | P13: 1 | Q13: 112 | R13: 112 | S13: 6 | T13: 40 | U13: 0.00033844097 | V13: 0.25623668 | W13: 0.51245135 | X13: 0.2953119 | Y13: 0.068215957 | Z13: 0.0039021308 | AA13: -0.023961778 | AB13: 0.0015437058 | AC13: 2002.6371 | AD13: 1561245.8 | AE13: 16000.848 | AF13: 24905304
... A36: 1570 | B36: 45447 | C36: 8 | D36: 02:35:55pm | E36: 4.71 | F36: 905 | G36: U7 | H36: 45.432909 | I36: -73.938787 | J36: 39.019 | K36: 0 | L36: 0 | M36: 1 | N36: 50093c9b5b838619 | O36: 6 | P36: 4 | Q36: 307 | R36: 307 | S36: 8 | T36: 224 | U36: 0.0018952855 | V36: 0.25831209 | W36: 0.51660209 | X36: 0.36245576 | Y36: 0.071272939 | Z36: 0.0042213943 | AA36: -0.023257284 | AB36: 0.0017496591 | AC36: 1968.388 | AD36: 2014166.6 | AE36: 15654.679 | AF36: 27592001
A37: 1523 | B37: 45447 | C37: 8 | D37: 02:16:32pm | E37: 4.71 | F37: 905 | G37: U9 | H37: 45.433084 | I37: -73.938806 | J37: 39.021 | K37: 0 | L37: 0 | M37: 1 | N37: 5.009381e+15 | O37: 0 | P37: 5 | Q37: 308 | R37: 308 | S37: 2 | T37: 49 | U37: 0.00041460422 | V37: 0.26357877 | W37: 0.52713456 | X37: 0.11739628 | Y37: 0.077923928 | Z37: 0.0056605808 | AA37: -0.021181049 | AB37: 0.0016733454 | AC37: 1858.7781 | AD37: 2051015.4 | AE37: 15528.777 | AF37: 27021215
A38: 1528 | B38: 45447 | C38: 8 | D38: 02:18:57pm | E38: 4.71 | F38: 905 | G38: D9 | H38: 45.433059 | I38: -73.93879 | J38: 39.021 | K38: 0 | L38: 0 | M38: 1 | N38: 500938a125f6843f | O38: 1 | P38: 5 | Q38: 309 | R38: 309 | S38: 22 | T38: 439 | U38: 0.0037143897 | V38: 0.26471005 | W38: 0.52939777 | X38: 0.73405263 | Y38: 0.077621343 | Z38: 0.005504399 | AA38: -0.021021287 | AB38: 0.0016996974 | AC38: 2102.6818 | AD38: 2959683 | AE38: 15945.778 | AF38: 27506531
A39: 1539 | B39: 45447 | C39: 8 | D39: 02:22:17pm | E39: 4.71 | F39: 905 | G39: U9 | H39: 45.433035 | I39: -73.938773 | J39: 39.02 | K39: 0 | L39: 0 | M39: 1 | N39: 500939696854b105 | O39: 2 | P39: 5 | Q39: 310 | R39: 310 | S39: 16 | T39: 336 | U39: 0.0028430244 | V39: 0.26598404 | W39: 0.53194498 | X39: 0.66841226 | Y39: 0.077602152 | Z39: 0.0049234268 | AA39: -0.021280586 | AB39: 0.0014430201 | AC39: 2018.0009 | AD39: 2647002.2 | AE39: 15590.28 | AF39: 25963520
A40: 1544 | B40: 45447 | C40: 8 | D40: 02:28:09pm | E40: 4.71 | F40: 905 | G40: D9 | H40: 45.43301 | I40: -73.938757 | J40: 39.02 | K40: 0 | L40: 0 | M40: 1 | N40: 50093ac93b20d3c3 | O40: 3 | P40: 5 | Q40: 311 | R40: 311 | S40: 15 | T40: 287 | U40: 0.002428314 | V40: 0.26553877 | W40: 0.53105406 | X40: 0.57443421 | Y40: 0.079204794 | Z40: 0.005917766 | AA40: -0.018997455 | AB40: 0.0017612959 | AC40: 1804.7904 | AD40: 2277763 | AE40: 15306.127 | AF40: 27725393
A41: 1555 | B41: 45447 | C41: 8 | D41: 02:31:03pm | E41: 4.71 | F41: 905 | G41: U9 | H41: 45.432985 | I41: -73.93874 | J41: 39.02 | K41: 0 | L41: 0 | M41: 1 | N41: 50093b771410315b | O41: 4 | P41: 5 | Q41: 312 | R41: 312 | S41: 17 | T41: 517 | U41: 0.0043744236 | V41: 0.26461443 | W41: 0.5292053 | X41: 0.64606579 | Y41: 0.075151959 | Z41: 0.0051519519 | AA41: -0.022141625 | AB41: 0.0015936 | AC41: 2036.3761 | AD41: 2756989.2 | AE41: 15404.121 | AF41: 26586789
A42: 1560 | B42: 45447 | C42: 8 | D42: 02:33:06pm | E42: 4.71 | F42: 905 | G42: D9 | H42: 45.43296 | I42: -73.938723 | J42: 39.02 | K42: 0 | L42: 0 | M42: 1 | N42: 50093bf2355ce56d | O42: 5 | P42: 5 | Q42: 313 | R42: 313 | S42: 15 | T42: 118 | U42: 0.00099840087 | V42: 0.26160815 | W42: 0.52319367 | X42: 0.49907238 | Y42: 0.074497973 | Z42: 0.0059960166 | AA42: -0.020804582 | AB42: 0.0017243538 | AC42: 1881.2389 | AD42: 2276732.2 | AE42: 15781.854 | AF42: 31246166
A43: 1571 | B43: 45447 | C43: 8 | D43: 02:36:07pm | E43: 4.71 | F43: 905 | G43: U9 | H43: 45.432936 | I43: -73.938707 | J43: 39.019 | K43: 0 | L43: 0 | M43: 1 | N43: 50093ca71aaea32f | O43: 6 | P43: 5 | Q43: 314 | R43: 314 | S43: 7 | T43: 84 | U43: 0.00071074408 | V43: 0.26118876 | W43: 0.52235468 | X43: 0.34555718 | Y43: 0.073316738 | Z43: 0.0055900458 | AA43: -0.02214409 | AB43: 0.001683731 | AC43: 1791.2389 | AD43: 1978023.8 | AE43: 15400.83 | AF43: 27704651
A44: 1524 | B44: 45447 | C44: 8 | D44: 02:17:01pm | E44: 4.71 | F44: 905 | G44: U11 | H44: 45.433111 | I44: -73.938725 | J44: 39.021 | K44: 0 | L44: 0 | M44: 1 | N44: 5009382d1f03b98f | O44: 0 | P44: 6 | Q44: 401 | R44: 401 | S44: 5 | T44: 60 | U44: 0.00050766575 | V44: 0.25436867 | W44: 0.50871381 | X44: 0.19938683 | Y44: 0.069753366 | Z44: 0.0042296407 | AA44: -0.029081134 | AB44: 0.001656722 | AC44: 1839.1222 | AD44: 2073585.2 | AE44: 15709.386 | AF44: 25263461
A45: 1527 | B45: 45447 | C45: 8 | D45: 02:18:44pm | E45: 4.71 | F45: 905 | G45: D11 | H45: 45.433086 | I45: -73.938709 | J45: 39.02 | K45: 0 | L45: 0 | M45: 1 | N45: 50093894752ce1b7 | O45: 1 | P45: 6 | Q45: 402 | R45: 402 | S45: 5 | T45: 81 | U45: 0.00068534297 | V45: 0.25316292 | W45: 0.5063036 | X45: 0.27327991 | Y45: 0.070106304 | Z45: 0.0045062831 | AA45: -0.025473943 | AB45: 0.0020368856 | AC45: 1831.432 | AD45: 2397129.4 | AE45: 16115.147 | AF45: 27709811
A46: 1540 | B46: 45447 | C46: 8 | D46: 02:22:29pm | E46: 4.71 | F46: 905 | G46: U11 | H46: 45.433061 | I46: -73.938692 | J46: 39.02 | K46: 0 | L46: 0 | M46: 1 | N46: 5009397538f822dd | O46: 2 | P46: 6 | Q46: 403 | R46: 403 | S46: 10 | T46: 169 | U46: 0.0014299252 | V46: 0.25766373 | W46: 0.51530424 | X46: 0.39980263 | Y46: 0.071224449 | Z46: 0.0043978393 | AA46: -0.024022273 | AB46: 0.0017429466 | AC46: 1948.1365 | AD46: 2568920.4 | AE46: 15733.856 | AF46: 26447197
A47: 1543 | B47: 45447 | C47: 8 | D47: 02:27:50pm | E47: 4.71 | F47: 905 | G47: D11 | H47: 45.433036 | I47: -73.938675 | J47: 39.02 | K47: 0 | L47: 0 | M47: 1 | N47: 50093ab67d023af4 | O47: 3 | P47: 6 | Q47: 404 | R47: 404 | S47: 3 | T47: 23 | U47: 0.00019460356 | V47: 0.25371501 | W47: 0.50740729 | X47: 0.18005737 | Y47: 0.066042383 | Z47: 0.0048350847 | AA47: -0.022600949 | AB47: 0.00181986 | AC47: 1789.5304 | AD47: 2148072.3 | AE47: 15990.403 | AF47: 27003344
A48: 1556 | B48: 45447 | C48: 8 | D48: 02:31:16pm | E48: 4.71 | F48: 905 | G48: U11 | H48: 45.433012 | I48: -73.938659 | J48: 39.02 | K48: 0 | L48: 0 | M48: 1 | N48: 50093b8410c2a505 | O48: 4 | P48: 6 | Q48: 405 | R48: 405 | S48: 6 | T48: 41 | U48: 0.000346902 | V48: 0.25362105 | W48: 0.5072201 | X48: 0.23944737 | Y48: 0.069081046 | Z48: 0.0048915747 | AA48: -0.019902428 | AB48: 0.0021057071 | AC48: 1860.7478 | AD48: 2492550.1 | AE48: 16236.241 | AF48: 28863189
A49: 1559 | B49: 45447 | C49: 8 | D49: 02:32:54pm | E49: 4.71 | F49: 905 | G49: D11 | H49: 45.432987 | I49: -73.938642 | J49: 39.019 | K49: 0 | L49: 0 | M49: 1 | N49: 50093be6278a06c1 | O49: 5 | P49: 6 | Q49: 406 | R49: 406 | S49: 2 | T49: 16 | U49: 0.00013538097 | V49: 0.25095164 | W49: 0.50188126 | X49: 0.12249007 | Y49: 0.064867467 | Z49: 0.0049260313 | AA49: -0.022629293 | AB49: 0.001998596 | AC49: 1792.2414 | AD49: 2336813.9 | AE49: 16146.597 | AF49: 29537347
... A57: 1573 | B57: 45447 | C57: 8 | D57: 02:36:33pm | E57: 4.71 | F57: 905 | G57: U13 | H57: 45.432989 | I57: -73.938545 | J57: 39.019 | K57: 0 | L57: 0 | M57: 1 | N57: 50093cc1072c464e | O57: 6 | P57: 7 | Q57: 414 | R57: 414 | S57: 5 | T57: 34 | U57: 0.00028767969 | V57: 0.24834502 | W57: 0.49666847 | X57: 0.20293688 | Y57: 0.059070783 | Z57: 0.0054584503 | AA57: -0.023862818 | AB57: 0.0022578136 | AC57: 1773.2504 | AD57: 2341844.1 | AE57: 15924.557 | AF57: 28220158

Sheet 618
A1: fid | B1: Date | C1: DAS | D1: Time | E1: Version | F1: Id | G1: Name | H1: Latitude | I1: Longitude | J1: Height | K1: AlarmRad | L1: WarningRad | M1: Status_Txt | N1: Visible | O1: UniqueID | P1: joined_row_index | Q1: joined_col_index | R1: joined_PlotID | S1: joined_PlotIDstring | T1: NDVI_mean | U1: SAVI_mean | V1: Threshold_sum | W1: Threshold_mean | X1: PLANTS_2ROW | Y1: HAreamean | Z1: NDVImean | AA1: NDVIvariance | AB1: 618gNDVI_mean | AC1: 618gNDVI_variance | AD1: 618NDRE_mean | AE1: 618NDRE_variance | AF1: 618ExG_mean | AG1: 618ExG_variance | AH1: 618ExR_mean | AI1: 618ExR_variance
A2: 1517 | B2: 45447 | C2: 13 | D2: 01:48:44pm | E2: 4.71 | F2: 905 | G2: U-1 | H2: 45.43295 | I2: -73.939211 | J2: 39.021 | K2: 0 | L2: 0 | N2: 1 | O2: 5009318c201f855b | P2: 0 | Q2: 0 | R2: 101 | S2: 101 | T2: 0.23532462 | U2: 0.015681717 | V2: 1277 | W2: 0.0089366318 | X2: 69 | Y2: 0.93073866 | Z2: 0.23532462 | AA2: 0.0024592894 | AB2: 0.38610535 | AC2: 0.0021730237 | AD2: 0.12413603 | AE2: 0.0008065091 | AF2: 2673.8035 | AG2: 1075698 | AH2: 16849.914 | AI2: 12563162
A3: 1519 | B3: 45447 | C3: 13 | D3: 02:15:42pm | E3: 4.71 | F3: 905 | G3: U1 | H3: 45.432976 | I3: -73.93913 | J3: 39.021 | K3: 0 | L3: 0 | N3: 1 | O3: 500937de01a1bd1f | P3: 0 | Q3: 1 | R3: 108 | S3: 108 | T3: 0.22549139 | U3: 0.016015569 | V3: 1365 | W3: 0.0095526023 | X3: 78 | Y3: 0.97785526 | Z3: 0.22549139 | AA3: 0.0023883706 | AB3: 0.37751449 | AC3: 0.0018815693 | AD3: 0.11866167 | AE3: 0.00083471364 | AF3: 2718.8148 | AG3: 1198562.9 | AH3: 16987.686 | AI3: 13785583
A4: 1520 | B4: 45447 | C4: 13 | D4: 02:15:55pm | E4: 4.71 | F4: 905 | G4: U3 | H4: 45.433004 | I4: -73.939049 | J4: 39.021 | K4: 0 | L4: 0 | N4: 1 | O4: 500937eb32eb8e40 | P4: 0 | Q4: 2 | R4: 201 | S4: 201 | T4: 0.22858069 | U4: 0.014714106 | V4: 2572 | W4: 0.01799923 | X4: 86 | Y4: 0.98800032 | Z4: 0.22858069 | AA4: 0.0039325426 | AB4: 0.36566202 | AC4: 0.0029000198 | AD4: 0.10101876 | AE4: 0.00087309988 | AF4: 2719.5805 | AG4: 1534110 | AH4: 16508.909 | AI4: 16490425
A5: 1521 | B5: 45447 | C5: 13 | D5: 02:16:07pm | E5: 4.71 | F5: 905 | G5: U5 | H5: 45.43303 | I5: -73.938968 | J5: 39.021 | K5: 0 | L5: 0 | N5: 1 | O5: 500937f72fc8d1c6 | P5: 0 | Q5: 3 | R5: 208 | S5: 208 | T5: 0.23506675 | U5: 0.015226197 | V5: 8087 | W5: 0.056594399 | X5: 59 | Y5: 0.97809211 | Z5: 0.23506675 | AA5: 0.0096413151 | AB5: 0.35658406 | AC5: 0.0037279228 | AD5: 0.087472901 | AE5: 0.0011687368 | AF5: 3023.3712 | AG5: 8308009.1 | AH5: 16465.898 | AI5: 23875792
A6: 1522 | B6: 45447 | C6: 13 | D6: 02:16:20pm | E6: 4.71 | F6: 905 | G6: U7 | H6: 45.433057 | I6: -73.938887 | J6: 39.021 | K6: 0 | L6: 0 | N6: 1 | O6: 5009380464b28f42 | P6: 0 | Q6: 4 | R6: 301 | S6: 301 | T6: 0.21966306 | U6: 0.014594337 | V6: 4290 | W6: 0.030022464 | X6: 46 | Y6: 0.75652632 | Z6: 0.21966306 | AA6: 0.0063673596 | AB6: 0.35473557 | AC6: 0.0031275323 | AD6: 0.088250976 | AE6: 0.0009386293 | AF6: 2931.6704 | AG6: 4684304.1 | AH6: 16337.968 | AI6: 17164686
A7: 1523 | B7: 45447 | C7: 13 | D7: 02:16:32pm | E7: 4.71 | F7: 905 | G7: U9 | H7: 45.433084 | I7: -73.938806 | J7: 39.021 | K7: 0 | L7: 0 | N7: 1 | O7: 5.009381e+15 | P7: 0 | Q7: 5 | R7: 308 | S7: 308 | T7: 0.23125402 | U7: 0.014993184 | V7: 1744 | W7: 0.012205022 | X7: 44 | Y7: 0.73038513 | Z7: 0.23125402 | AA7: 0.0030404829 | AB7: 0.35929521 | AC7: 0.0026981473 | AD7: 0.095652047 | AE7: 0.0010430258 | AF7: 2522.3803 | AG7: 2063328.3 | AH7: 16615.196 | AI7: 18735848
A8: 1524 | B8: 45447 | C8: 13 | D8: 02:17:01pm | E8: 4.71 | F8: 905 | G8: U11 | H8: 45.433111 | I8: -73.938725 | J8: 39.021 | K8: 0 | L8: 0 | N8: 1 | O8: 5009382d1f03b98f | P8: 0 | Q8: 6 | R8: 401 | S8: 401 | T8: 0.23426241 | U8: 0.01645932 | V8: 3654 | W8: 0.025571224 | X8: 43 | Y8: 0.8703175 | Z8: 0.23426241 | AA8: 0.0044820225 | AB8: 0.36286389 | AC8: 0.0027537978 | AD8: 0.099049516 | AE8: 0.00091238826 | AF8: 2889.4985 | AG8: 4159347.7 | AH8: 16605.305 | AI8: 18318567
A9: 1525 | B9: 45447 | C9: 13 | D9: 02:17:13pm | E9: 4.71 | F9: 905 | G9: U13 | H9: 45.433138 | I9: -73.938644 | J9: 39.021 | K9: 0 | L9: 0 | N9: 1 | O9: 500938393916ae56 | P9: 0 | Q9: 6 | R9: 408 | S9: 408 | T9: 0.24352485 | U9: 0.015811624 | V9: 4672 | W9: 0.032695336 | X9: 58 | Y9: 0.95418361 | Z9: 0.24352485 | AA9: 0.0060220968 | AB9: 0.37451818 | AC9: 0.0034908947 | AD9: 0.10465285 | AE9: 0.001106812 | AF9: 2923.0888 | AG9: 5059712.5 | AH9: 17013.376 | AI9: 21808398
A10: 1526 | B10: 45447 | C10: 13 | D10: 02:18:31pm | E10: 4.71 | F10: 905 | G10: D13 | H10: 45.433113 | I10: -73.938628 | J10: 39.02 | K10: 0 | L10: 0 | N10: 1 | O10: 500938877536384a | P10: 1 | Q10: 7 | R10: 409 | S10: 409 | T10: 0.22942995 | U10: 0.01467139 | V10: 1434 | W10: 0.010035341 | X10: 43 | Y10: 0.60805548 | Z10: 0.22942995 | AA10: 0.0029756069 | AB10: 0.37039407 | AC10: 0.0027161844 | AD10: 0.10264666 | AE10: 0.00094696323 | AF10: 2735.4816 | AG10: 2153023 | AH10: 17225.602 | AI10: 16799791
A11: 1527 | B11: 45447 | C11: 13 | D11: 02:18:44pm | E11: 4.71 | F11: 905 | G11: D11 | H11: 45.433086 | I11: -73.938709 | J11: 39.02 | K11: 0 | L11: 0 | N11: 1 | O11: 50093894752ce1b7 | P11: 1 | Q11: 6 | R11: 402 | S11: 402 | T11: 0.23998713 | U11: 0.015651831 | V11: 8241 | W11: 0.057671717 | X11: 64 | Y11: 0.98147393 | Z11: 0.23998713 | AA11: 0.010631145 | AB11: 0.36907049 | AC11: 0.0042138959 | AD11: 0.095940678 | AE11: 0.0012393173 | AF11: 3173.201 | AG11: 8564586.5 | AH11: 16116.053 | AI11: 23794131
A12: 1528 | B12: 45447 | C12: 13 | D12: 02:18:57pm | E12: 4.71 | F12: 905 | G12: D9 | H12: 45.433059 | I12: -73.93879 | J12: 39.021 | K12: 0 | L12: 0 | N12: 1 | O12: 500938a125f6843f | P12: 1 | Q12: 5 | R12: 309 | S12: 309 | T12: 0.24302609 | U12: 0.015174554 | V12: 6918 | W12: 0.048413509 | X12: 60 | Y12: 0.98394758 | Z12: 0.24302609 | AA12: 0.007593612 | AB12: 0.36579023 | AC12: 0.0037408652 | AD12: 0.095106153 | AE12: 0.0012936671 | AF12: 3052.9439 | AG12: 8514688.9 | AH12: 16356.354 | AI12: 23975077
A13: 1529 | B13: 45447 | C13: 13 | D13: 02:19:09pm | E13: 4.71 | F13: 905 | G13: D7 | H13: 45.433032 | I13: -73.938871 | J13: 39.021 | K13: 0 | L13: 0 | N13: 1 | O13: 500938ad2f841179 | P13: 1 | Q13: 4 | R13: 302 | S13: 302 | T13: 0.2194265 | U13: 0.014484674 | V13: 2906 | W13: 0.020336895 | X13: 66 | Y13: 0.97861842 | Z13: 0.2194265 | AA13: 0.0047497892 | AB13: 0.35676923 | AC13: 0.0030203797 | AD13: 0.089993611 | AE13: 0.0009512125 | AF13: 2759.8273 | AG13: 2192135.9 | AH13: 16430.498 | AI13: 17636400
A14: 1530 | B14: 45447 | C14: 13 | D14: 02:19:22pm | E14: 4.71 | F14: 905 | G14: D5 | H14: 45.433006 | I14: -73.938952 | J14: 39.021 | K14: 0 | L14: 0 | N14: 1 | O14: 500938ba669012e1 | P14: 1 | Q14: 3 | R14: 209 | S14: 209 | T14: 0.22690168 | U14: 0.014447963 | V14: 3836 | W14: 0.026845262 | X14: 47 | Y14: 0.95221053 | Z14: 0.22690168 | AA14: 0.0051064219 | AB14: 0.35439109 | AC14: 0.0029786302 | AD14: 0.089167976 | AE14: 0.0011773479 | AF14: 2735.0004 | AG14: 5566581.8 | AH14: 16830.022 | AI14: 20539294
A15: 1531 | B15: 45447 | C15: 13 | D15: 02:19:34pm | E15: 4.71 | F15: 905 | G15: D3 | H15: 45.432979 | I15: -73.939032 | J15: 39.021 | K15: 0 | L15: 0 | N15: 1 | O15: 500938c669fc4194 | P15: 1 | Q15: 2 | R15: 202 | S15: 202 | T15: 0.22104876 | U15: 0.013970478 | V15: 1352 | W15: 0.0094614265 | X15: 83 | Y15: 0.98107895 | Z15: 0.22104876 | AA15: 0.0030821859 | AB15: 0.35459287 | AC15: 0.0027940806 | AD15: 0.091677604 | AE15: 0.00087925126 | AF15: 2648.1037 | AG15: 1527173.1 | AH15: 16931.282 | AI15: 15930185
A16: 1532 | B16: 45447 | C16: 13 | D16: 02:19:47pm | E16: 4.71 | F16: 905 | G16: D1 | H16: 45.432952 | I16: -73.939113 | J16: 39.021 | K16: 0 | L16: 0 | N16: 1 | O16: 500938d31d4cc688 | P16: 1 | Q16: 1 | R16: 109 | S16: 109 | T16: 0.22477342 | U16: 0.014396737 | V16: 2435 | W16: 0.017040604 | X16: 67 | Y16: 0.92168421 | Z16: 0.22477342 | AA16: 0.0035109027 | AB16: 0.37595592 | AC16: 0.0025374914 | AD16: 0.11200381 | AE16: 0.00093005811 | AF16: 2573.1828 | AG16: 2109623.8 | AH16: 16866.204 | AI16: 16068825
A17: 1533 | B17: 45447 | C17: 13 | D17: 02:20:00pm | E17: 4.71 | F17: 905 | G17: D-1 | H17: 45.432925 | I17: -73.939194 | J17: 39.021 | K17: 0 | L17: 0 | N17: 1 | O17: 500938e02a9ec38d | P17: 1 | Q17: 0 | R17: 102 | S17: 102 | T17: 0.23658361 | U17: 0.015577886 | V17: 2680 | W17: 0.018755161 | X17: 85 | Y17: 0.98038158 | Z17: 0.23658361 | AA17: 0.003684161 | AB17: 0.38132024 | AC17: 0.0026796663 | AD17: 0.11797147 | AE17: 0.00074596387 | AF17: 2796.3925 | AG17: 1532110.2 | AH17: 16813.706 | AI17: 13485483
A18: 1534 | B18: 45447 | C18: 13 | D18: 02:20:58pm | E18: 4.71 | F18: 905 | G18: U-1 | H18: 45.4329 | I18: -73.939178 | J18: 39.021 | K18: 0 | L18: 0 | N18: 1 | O18: 5009391a2cd19750 | P18: 2 | Q18: 0 | R18: 103 | S18: 103 | T18: 0.2360351 | U18: 0.015621081 | V18: 2656 | W18: 0.018587725 | X18: 74 | Y18: 0.97440756 | Z18: 0.2360351 | AA18: 0.0033981471 | AB18: 0.37157591 | AC18: 0.0021471657 | AD18: 0.10582747 | AE18: 0.0007023436 | AF18: 2594.6848 | AG18: 1397244.6 | AH18: 16821.681 | AI18: 10851063
A19: 1535 | B19: 45447 | C19: 13 | D19: 02:21:11pm | E19: 4.71 | F19: 905 | G19: U1 | H19: 45.432926 | I19: -73.939096 | J19: 39.021 | K19: 0 | L19: 0 | N19: 1 | O19: 500939272161cf8e | P19: 2 | Q19: 1 | R19: 110 | S19: 110 | T19: 0.21676014 | U19: 0.014236069 | V19: 1104 | W19: 0.0077260067 | X19: 64 | Y19: 0.96492105 | Z19: 0.21676014 | AA19: 0.0022915596 | AB19: 0.35704678 | AC19: 0.0018390272 | AD19: 0.094820522 | AE19: 0.00081621511 | AF19: 2586.8222 | AG19: 1331290.2 | AH19: 17033.325 | AI19: 13636344
... A57: 1573 | B57: 45447 | C57: 13 | D57: 02:36:33pm | E57: 4.71 | F57: 905 | G57: U13 | H57: 45.432989 | I57: -73.938545 | J57: 39.019 | K57: 0 | L57: 0 | N57: 1 | O57: 50093cc1072c464e | P57: 6 | Q57: 7 | R57: 414 | S57: 414 | T57: 0.23396666 | U57: 0.015603621 | V57: 1878 | W57: 0.013142517 | X57: 32 | Y57: 0.70100525 | Z57: 0.23396666 | AA57: 0.0033649651 | AB57: 0.36591198 | AC57: 0.0027435604 | AD57: 0.10595918 | AE57: 0.00097578299 | AF57: 2689.026 | AG57: 2429957.9 | AH57: 17209.18 | AI57: 17950275

Sheet 628
A1: fid | B1: Date | C1: DAS | D1: Time | E1: Version | F1: Id | G1: Name | H1: Latitude | I1: Longitude | J1: Height | K1: AlarmRad | L1: WarningRad | M1: Status_Txt | N1: Visible | O1: UniqueID | P1: joined_row | Q1: joined_col | R1: joined_Plo | S1: joined_P_1 | T1: 628NDVI_me | U1: SAVI_mean | V1: THRESH_mea | W1: HArea_mean | X1: PLTCOUNT | Y1: 6-28SAVI_m | Z1: 628NDVIvariance | AA1: 628gNDVI_mean | AB1: 628gNDVI_variance | AC1: 628gNDRE_mean | AD1: 628gNDRE_variance | AE1: 628gExG_mean | AF1: 628gExG_variance | AG1: 628gExR_mean | AH1: 628gExR_variance
A2: 1517 | B2: 45447 | C2: 23 | D2: 01:48:44pm | E2: 4.71 | F2: 905 | G2: U-1 | H2: 45.43295 | I2: -73.939211 | J2: 39.021 | K2: 0 | L2: 0 | N2: 1 | O2: 5009318c201f855b | P2: 0 | Q2: 0 | R2: 101 | S2: 101 | T2: 0.27767677 | U2: 61465.281 | V2: 0.070022396 | W2: 0.93847287 | X2: 77 | Y2: 0.55591336 | Z2: 0.012511479 | AA2: 0.079653454 | AB2: 0.0076894264 | AC2: -0.025341679 | AD2: 0.0016471715 | AE2: 2688.0758 | AF2: 14647516 | AG2: 15234.614 | AH2: 33086516
A3: 1519 | B3: 45447 | C3: 23 | D3: 02:15:42pm | E3: 4.71 | F3: 905 | G3: U1 | H3: 45.432976 | I3: -73.93913 | J3: 39.021 | K3: 0 | L3: 0 | N3: 1 | O3: 500937de01a1bd1f | P3: 0 | Q3: 1 | R3: 108 | S3: 108 | T3: 0.28681319 | U3: 60446.671 | V3: 0.10021548 | W3: 0.98342105 | X3: 81 | Y3: 0.57341851 | Z3: 0.016485793 | AA3: 0.085484694 | AB3: 0.0089049858 | AC3: -0.023655936 | AD3: 0.0020858363 | AE3: 2820.1391 | AF3: 20113101 | AG3: 14593.863 | AH3: 40661256
A4: 1520 | B4: 45447 | C4: 23 | D4: 02:15:55pm | E4: 4.71 | F4: 905 | G4: U3 | H4: 45.433004 | I4: -73.939049 | J4: 39.021 | K4: 0 | L4: 0 | N4: 1 | O4: 500937eb32eb8e40 | P4: 0 | Q4: 2 | R4: 201 | S4: 201 | T4: 0.30269273 | U4: 63750.25 | V4: 0.14086843 | W4: 0.98652649 | X4: 66 | Y4: 0.60574933 | Z4: 0.025319285 | AA4: 0.098851612 | AB4: 0.013538985 | AC4: -0.020311005 | AD4: 0.0022420005 | AE4: 2892.2609 | AF4: 32539697 | AG4: 14445.806 | AH4: 46557745
A5: 1521 | B5: 45447 | C5: 23 | D5: 02:16:07pm | E5: 4.71 | F5: 905 | G5: U5 | H5: 45.43303 | I5: -73.938968 | J5: 39.021 | K5: 0 | L5: 0 | N5: 1 | O5: 500937f72fc8d1c6 | P5: 0 | Q5: 3 | R5: 208 | S5: 208 | T5: 0.37160737 | U5: 69521.077 | V5: 0.28275448 | W5: 0.77365492 | X5: 29 | Y5: 0.74332409 | Z5: 0.046029579 | AA5: 0.12892114 | AB5: 0.018061369 | AC5: -0.01782728 | AD5: 0.0034393501 | AE5: 6878.8344 | AF5: 1.075359e+08 | AG5: 12363.26 | AH5: 69741837
A6: 1522 | B6: 45447 | C6: 23 | D6: 02:16:20pm | E6: 4.71 | F6: 905 | G6: U7 | H6: 45.433057 | I6: -73.938887 | J6: 39.021 | K6: 0 | L6: 0 | N6: 1 | O6: 5009380464b28f42 | P6: 0 | Q6: 4 | R6: 301 | S6: 301 | T6: 0.30375496 | U6: 64087.916 | V6: 0.16796061 | W6: 0.80024737 | X6: 41 | Y6: 0.60786583 | Z6: 0.033879842 | AA6: 0.099101233 | AB6: 0.014231405 | AC6: -0.022516393 | AD6: 0.0026078644 | AE6: 4278.7636 | AF6: 65644992 | AG6: 13999.969 | AH6: 50818045
A7: 1523 | B7: 45447 | C7: 23 | D7: 02:16:32pm | E7: 4.71 | F7: 905 | G7: U9 | H7: 45.433084 | I7: -73.938806 | J7: 39.021 | K7: 0 | L7: 0 | N7: 1 | O7: 5.009381e+15 | P7: 0 | Q7: 5 | R7: 308 | S7: 308 | T7: 0.25623714 | U7: 64596.332 | V7: 0.10604191 | W7: 0.69283806 | X7: 31 | Y7: 0.51242423 | Z7: 0.022550199 | AA7: 0.071541591 | AB7: 0.0095120665 | AC7: -0.028008252 | AD7: 0.0022684479 | AE7: 3390.2704 | AF7: 53740627 | AG7: 15359.88 | AH7: 42791174
A8: 1524 | B8: 45447 | C8: 23 | D8: 02:17:01pm | E8: 4.71 | F8: 905 | G8: U11 | H8: 45.433111 | I8: -73.938725 | J8: 39.021 | K8: 0 | L8: 0 | N8: 1 | O8: 5009382d1f03b98f | P8: 0 | Q8: 6 | R8: 401 | S8: 401 | T8: 0.3021372 | U8: 63765.395 | V8: 0.16741975 | W8: 0.76528639 | X8: 23 | Y8: 0.60438543 | Z8: 0.032988202 | AA8: 0.098114836 | AB8: 0.013243279 | AC8: -0.027251272 | AD8: 0.0025419247 | AE8: 4583.0437 | AF8: 63871192 | AG8: 13588.011 | AH8: 47286855
A9: 1525 | B9: 45447 | C9: 23 | D9: 02:17:13pm | E9: 4.71 | F9: 905 | G9: U13 | H9: 45.433138 | I9: -73.938644 | J9: 39.021 | K9: 0 | L9: 0 | N9: 1 | O9: 500938393916ae56 | P9: 0 | Q9: 6 | R9: 408 | S9: 408 | T9: 0.32171734 | U9: 67502.191 | V9: 0.18850677 | W9: 0.90936842 | X9: 44 | Y9: 0.64343465 | Z9: 0.030299201 | AA9: 0.10892524 | AB9: 0.013464549 | AC9: -0.019728438 | AD9: 0.0028717174 | AE9: 5105.8409 | AF9: 72373164 | AG9: 14155.66 | AH9: 57221824
A10: 1526 | B10: 45447 | C10: 23 | D10: 02:18:31pm | E10: 4.71 | F10: 905 | G10: D13 | H10: 45.433113 | I10: -73.938628 | J10: 39.02 | K10: 0 | L10: 0 | N10: 1 | O10: 500938877536384a | P10: 1 | Q10: 7 | R10: 409 | S10: 409 | T10: 0.25696014 | U10: 65376.925 | V10: 0.088306736 | W10: 0.52360526 | X10: 18 | Y10: 0.51387674 | Z10: 0.018918884 | AA10: 0.071699561 | AB10: 0.008857866 | AC10: -0.0268659 | AD10: 0.0019332632 | AE10: 3064.186 | AF10: 40611000 | AG10: 15990.105 | AH10: 40180631
A11: 1527 | B11: 45447 | C11: 23 | D11: 02:18:44pm | E11: 4.71 | F11: 905 | G11: D11 | H11: 45.433086 | I11: -73.938709 | J11: 39.02 | K11: 0 | L11: 0 | N11: 1 | O11: 50093894752ce1b7 | P11: 1 | Q11: 6 | R11: 402 | S11: 402 | T11: 0.35522891 | U11: 71277.472 | V11: 0.26191005 | W11: 0.66386411 | X11: 24 | Y11: 0.71068187 | Z11: 0.046217919 | AA11: 0.1242792 | AB11: 0.016272959 | AC11: -0.025273134 | AD11: 0.0030531383 | AE11: 7398.6832 | AF11: 1.2824593e+08 | AG11: 12175.859 | AH11: 60786408
A12: 1528 | B12: 45447 | C12: 23 | D12: 02:18:57pm | E12: 4.71 | F12: 905 | G12: D9 | H12: 45.433059 | I12: -73.93879 | J12: 39.021 | K12: 0 | L12: 0 | N12: 1 | O12: 500938a125f6843f | P12: 1 | Q12: 5 | R12: 309 | S12: 309 | T12: 0.32623227 | U12: 70374.877 | V12: 0.23430583 | W12: 0.89423684 | X12: 41 | Y12: 0.65291678 | Z12: 0.039196226 | AA12: 0.10837839 | AB12: 0.013312839 | AC12: -0.024074756 | AD12: 0.0030713491 | AE12: 6572.2024 | AF12: 1.1807313e+08 | AG12: 13402.35 | AH12: 64462644
A13: 1529 | B13: 45447 | C13: 23 | D13: 02:19:09pm | E13: 4.71 | F13: 905 | G13: D7 | H13: 45.433032 | I13: -73.938871 | J13: 39.021 | K13: 0 | L13: 0 | N13: 1 | O13: 500938ad2f841179 | P13: 1 | Q13: 4 | R13: 302 | S13: 302 | T13: 0.33164583 | U13: 65531.926 | V13: 0.22009794 | W13: 0.92842105 | X13: 45 | Y13: 0.66323341 | Z13: 0.039068971 | AA13: 0.11771615 | AB13: 0.017288321 | AC13: -0.020408278 | AD13: 0.0029417516 | AE13: 5359.1181 | AF13: 78624449 | AG13: 12820.94 | AH13: 57149486
A14: 1530 | B14: 45447 | C14: 23 | D14: 02:19:22pm | E14: 4.71 | F14: 905 | G14: D5 | H14: 45.433006 | I14: -73.938952 | J14: 39.021 | K14: 0 | L14: 0 | N14: 1 | O14: 500938ba669012e1 | P14: 1 | Q14: 3 | R14: 209 | S14: 209 | T14: 0.30386806 | U14: 66464.778 | V14: 0.16649907 | W14: 0.95127696 | X14: 50 | Y14: 0.60781371 | Z14: 0.029043228 | AA14: 0.086938435 | AB14: 0.011676951 | AC14: -0.025258191 | AD14: 0.0027542119 | AE14: 4859.2644 | AF14: 70597453 | AG14: 14232.974 | AH14: 52862495
A15: 1531 | B15: 45447 | C15: 23 | D15: 02:19:34pm | E15: 4.71 | F15: 905 | G15: D3 | H15: 45.432979 | I15: -73.939032 | J15: 39.021 | K15: 0 | L15: 0 | N15: 1 | O15: 500938c669fc4194 | P15: 1 | Q15: 2 | R15: 202 | S15: 202 | T15: 0.26865329 | U15: 61992.421 | V15: 0.075905975 | W15: 0.99564479 | X15: 94 | Y15: 0.53745911 | Z15: 0.014983003 | AA15: 0.077575743 | AB15: 0.0099159532 | AC15: -0.024583073 | AD15: 0.0018966199 | AE15: 2108.8146 | AF15: 15925208 | AG15: 15193.803 | AH15: 37799494
A16: 1532 | B16: 45447 | C16: 23 | D16: 02:19:47pm | E16: 4.71 | F16: 905 | G16: D1 | H16: 45.432952 | I16: -73.939113 | J16: 39.021 | K16: 0 | L16: 0 | N16: 1 | O16: 500938d31d4cc688 | P16: 1 | Q16: 1 | R16: 109 | S16: 109 | T16: 0.29041425 | U16: 67699.045 | V16: 0.12834644 | W16: 0.94582895 | X16: 59 | Y16: 0.58073134 | Z16: 0.022256104 | AA16: 0.079761051 | AB16: 0.0095225432 | AC16: -0.025981056 | AD16: 0.0022085204 | AE16: 3642.1134 | AF16: 49164070 | AG16: 15338.706 | AH16: 44886073
A17: 1533 | B17: 45447 | C17: 23 | D17: 02:20:00pm | E17: 4.71 | F17: 905 | G17: D-1 | H17: 45.432925 | I17: -73.939194 | J17: 39.021 | K17: 0 | L17: 0 | N17: 1 | O17: 500938e02a9ec38d | P17: 1 | Q17: 0 | R17: 102 | S17: 102 | T17: 0.28311011 | U17: 63717.121 | V17: 0.096336296 | W17: 0.98761875 | X17: 109 | Y17: 0.56667427 | Z17: 0.016761562 | AA17: 0.084698576 | AB17: 0.0097318548 | AC17: -0.024400606 | AD17: 0.0018328865 | AE17: 2597.2326 | AF17: 15948423 | AG17: 15484.461 | AH17: 37658266
A18: 1534 | B18: 45447 | C18: 23 | D18: 02:20:58pm | E18: 4.71 | F18: 905 | G18: U-1 | H18: 45.4329 | I18: -73.939178 | J18: 39.021 | K18: 0 | L18: 0 | N18: 1 | O18: 5009391a2cd19750 | P18: 2 | Q18: 0 | R18: 103 | S18: 103 | T18: 0.28477736 | U18: 65577.149 | V18: 0.11715235 | W18: 0.98009237 | X18: 69 | Y18: 0.56951894 | Z18: 0.019743413 | AA18: 0.07605396 | AB18: 0.0092934673 | AC18: -0.028454453 | AD18: 0.0019574744 | AE18: 3433.9801 | AF18: 38503763 | AG18: 15764.918 | AH18: 40640195
A19: 1535 | B19: 45447 | C19: 23 | D19: 02:21:11pm | E19: 4.71 | F19: 905 | G19: U1 | H19: 45.432926 | I19: -73.939096 | J19: 39.021 | K19: 0 | L19: 0 | N19: 1 | O19: 500939272161cf8e | P19: 2 | Q19: 1 | R19: 110 | S19: 110 | T19: 0.24841444 | U19: 63246.42 | V19: 0.060842709 | W19: 0.97988158 | X19: 62 | Y19: 0.49709581 | Z19: 0.012464851 | AA19: 0.053209203 | AB19: 0.0065667849 | AC19: -0.031750058 | AD19: 0.0017438326 | AE19: 2580.3969 | AF19: 16248650 | AG19: 16226.452 | AH19: 35334623
... A57: 1573 | B57: 45447 | C57: 23 | D57: 02:36:33pm | E57: 4.71 | F57: 905 | G57: U13 | H57: 45.432989 | I57: -73.938545 | J57: 39.019 | K57: 0 | L57: 0 | N57: 1 | O57: 50093cc1072c464e | P57: 6 | Q57: 7 | R57: 414 | S57: 414 | T57: 0.25909846 | U57: 64675.351 | V57: 0.10213583 | W57: 0.62003447 | X57: 31 | Y57: 0.51860443 | Z57: 0.022308236 | AA57: 0.0695069 | AB57: 0.010625762 | AC57: -0.030363878 | AD57: 0.0022430496 | AE57: 3125.8109 | AF57: 45222226 | AG57: 15156.7 | AH57: 44192904
A58: 77777 | B58: 45771 | C58: 23 | T58: 0.11650886 | V58: 0 | W58: 0.96498262 | X58: 1 | Y58: 0.2361119 | Z58: 0.020144586 | AA58: -0.12251923 | AB58: 0.036878801 | AC58: -0.061402465 | AD58: 0.0092505489 | AE58: -376.2772 | AF58: 3016697.5 | AG58: 15916.958 | AH58: 56355948

Sheet 702
A1: fid | B1: Date | C1: DAS | D1: Time | E1: Version | F1: Id | G1: Name | H1: Latitude | I1: Longitude | J1: Height | K1: AlarmRad | L1: WarningRad | M1: Status_Txt | N1: Visible | O1: UniqueID | P1: joined_row | Q1: joined_col | R1: joined_Plo | S1: joined_P_1 | T1: 702NDVI_mean | U1: SAVI_mean | V1: 702Thresh_mea | W1: 702HArea_mean | X1: 702pltcountsculled | Y1: 702NDVI_variance | Z1: 702gNDVI_mean | AA1: 702gNDVI_variance | AB1: 702gNDRE_mean | AC1: 702gNDRE_variance | AD1: 702ExG_mean | AE1: 702ExG_variance | AF1: 702ExR_mean | AG1: 702ExR_variance
A2: 1517 | B2: 45447 | C2: 27 | D2: 01:48:44pm | E2: 4.71 | F2: 905 | G2: U-1 | H2: 45.43295 | I2: -73.939211 | J2: 39.021 | K2: 0 | L2: 0 | N2: 1 | O2: 5009318c201f855b | P2: 0 | Q2: 0 | R2: 101 | S2: 101 | T2: 0.26004327 | U2: 0.520064 | V2: 0.05742787 | W2: 0.99113158 | X2: 117 | Y2: 0.011306362 | Z2: 0.07210163 | AA2: 0.006799759 | AB2: -0.027311642 | AC2: 0.0010787513 | AD2: 2983.2447 | AE2: 8511121.3 | AF2: 16226.629 | AG2: 26487623
A3: 1519 | B3: 45447 | C3: 27 | D3: 02:15:42pm | E3: 4.71 | F3: 905 | G3: U1 | H3: 45.432976 | I3: -73.93913 | J3: 39.021 | K3: 0 | L3: 0 | N3: 1 | O3: 500937de01a1bd1f | P3: 0 | Q3: 1 | R3: 108 | S3: 108 | T3: 0.26959666 | U3: 0.5391695 | V3: 0.081159225 | W3: 0.99767111 | X3: 101 | Y3: 0.014269201 | Z3: 0.074885456 | AA3: 0.007484523 | AB3: -0.027996844 | AC3: 0.001287483 | AD3: 3270.6509 | AE3: 11374133 | AF3: 15744.071 | AG3: 32050802
A4: 1520 | B4: 45447 | C4: 27 | D4: 02:15:55pm | E4: 4.71 | F4: 905 | G4: U3 | H4: 45.433004 | I4: -73.939049 | J4: 39.021 | K4: 0 | L4: 0 | N4: 1 | O4: 500937eb32eb8e40 | P4: 0 | Q4: 2 | R4: 201 | S4: 201 | T4: 0.28704148 | U4: 0.57405758 | V4: 0.11143441 | W4: 0.99419744 | X4: 82 | Y4: 0.020401855 | Z4: 0.09510798 | AA4: 0.010857387 | AB4: -0.021382482 | AC4: 0.0013538497 | AD4: 3322.5316 | AE4: 17402777 | AF4: 15255.094 | AG4: 38194496
A5: 1521 | B5: 45447 | C5: 27 | D5: 02:16:07pm | E5: 4.71 | F5: 905 | G5: U5 | H5: 45.43303 | I5: -73.938968 | J5: 39.021 | K5: 0 | L5: 0 | N5: 1 | O5: 500937f72fc8d1c6 | P5: 0 | Q5: 3 | R5: 208 | S5: 208 | T5: 0.38638785 | U5: 0.77274198 | V5: 0.30503855 | W5: 0.93598684 | X5: 50 | Y5: 0.050344822 | Z5: 0.15437408 | AA5: 0.020164188 | AB5: -0.0089347647 | AC5: 0.0030304593 | AD5: 7123.9573 | AE5: 84702066 | AF5: 12318.484 | AG5: 73961071
A6: 1522 | B6: 45447 | C6: 27 | D6: 02:16:20pm | E6: 4.71 | F6: 905 | G6: U7 | H6: 45.433057 | I6: -73.938887 | J6: 39.021 | K6: 0 | L6: 0 | N6: 1 | O6: 5009380464b28f42 | P6: 0 | Q6: 4 | R6: 301 | S6: 301 | T6: 0.3019115 | U6: 0.60379652 | V6: 0.17034168 | W6: 0.77190789 | X6: 40 | Y6: 0.036529244 | Z6: 0.096934757 | AA6: 0.015325765 | AB6: -0.023884263 | AC6: 0.0022772397 | AD6: 4510.0934 | AE6: 50554586 | AF6: 14603.167 | AG6: 52171954
A7: 1523 | B7: 45447 | C7: 27 | D7: 02:16:32pm | E7: 4.71 | F7: 905 | G7: U9 | H7: 45.433084 | I7: -73.938806 | J7: 39.021 | K7: 0 | L7: 0 | N7: 1 | O7: 5.009381e+15 | P7: 0 | Q7: 5 | R7: 308 | S7: 308 | T7: 0.25113887 | U7: 0.50225606 | V7: 0.083191632 | W7: 0.77507303 | X7: 60 | Y7: 0.017444466 | Z7: 0.063592925 | AA7: 0.0081171048 | AB7: -0.025930478 | AC7: 0.0015450028 | AD7: 3346.5363 | AE7: 25446597 | AF7: 16273.441 | AG7: 35309691
A8: 1524 | B8: 45447 | C8: 27 | D8: 02:17:01pm | E8: 4.71 | F8: 905 | G8: U11 | H8: 45.433111 | I8: -73.938725 | J8: 39.021 | K8: 0 | L8: 0 | N8: 1 | O8: 5009382d1f03b98f | P8: 0 | Q8: 6 | R8: 401 | S8: 401 | T8: 0.31409601 | U8: 0.62816441 | V8: 0.18496283 | W8: 0.8910512 | X8: 50 | Y8: 0.032292139 | Z8: 0.094422507 | AA8: 0.01320981 | AB8: -0.024627848 | AC8: 0.0021526063 | AD8: 5863.2515 | AE8: 68231096 | AF8: 14678.161 | AG8: 55706862
A9: 1525 | B9: 45447 | C9: 27 | D9: 02:17:13pm | E9: 4.71 | F9: 905 | G9: U13 | H9: 45.433138 | I9: -73.938644 | J9: 39.021 | K9: 0 | L9: 0 | N9: 1 | O9: 500938393916ae56 | P9: 0 | Q9: 6 | R9: 408 | S9: 408 | T9: 0.32474489 | U9: 0.64946127 | V9: 0.19248264 | W9: 0.95817105 | X9: 69 | Y9: 0.030591038 | Z9: 0.10457815 | AA9: 0.011908595 | AB9: -0.020609205 | AC9: 0.0022164439 | AD9: 5647.5983 | AE9: 67463028 | AF9: 14575.095 | AG9: 55247077
A10: 1526 | B10: 45447 | C10: 27 | D10: 02:18:31pm | E10: 4.71 | F10: 905 | G10: D13 | H10: 45.433113 | I10: -73.938628 | J10: 39.02 | K10: 0 | L10: 0 | N10: 1 | O10: 500938877536384a | P10: 1 | Q10: 7 | R10: 409 | S10: 409 | T10: 0.25144237 | U10: 0.50286327 | V10: 0.070477523 | W10: 0.63076802 | X10: 41 | Y10: 0.014794876 | Z10: 0.064235496 | AA10: 0.0077249531 | AB10: -0.026311728 | AC10: 0.0013218714 | AD10: 2897.2596 | AE10: 18492733 | AF10: 16792.925 | AG10: 33104630
A11: 1527 | B11: 45447 | C11: 27 | D11: 02:18:44pm | E11: 4.71 | F11: 905 | G11: D11 | H11: 45.433086 | I11: -73.938709 | J11: 39.02 | K11: 0 | L11: 0 | N11: 1 | O11: 50093894752ce1b7 | P11: 1 | Q11: 6 | R11: 402 | S11: 402 | T11: 0.37131145 | U11: 0.74259044 | V11: 0.27675705 | W11: 0.71535901 | X11: 27 | Y11: 0.050049487 | Z11: 0.13300031 | AA11: 0.018331277 | AB11: -0.017392429 | AC11: 0.0029069043 | AD11: 7811.0786 | AE11: 1.0605422e+08 | AF11: 12823.916 | AG11: 71946656
A12: 1528 | B12: 45447 | C12: 27 | D12: 02:18:57pm | E12: 4.71 | F12: 905 | G12: D9 | H12: 45.433059 | I12: -73.93879 | J12: 39.021 | K12: 0 | L12: 0 | N12: 1 | O12: 500938a125f6843f | P12: 1 | Q12: 5 | R12: 309 | S12: 309 | T12: 0.34879193 | U12: 0.69755287 | V12: 0.25240323 | W12: 0.94564402 | X12: 59 | Y12: 0.037677602 | Z12: 0.11454045 | AA12: 0.013629669 | AB12: -0.018159694 | AC12: 0.0026813688 | AD12: 7374.9065 | AE12: 98690022 | AF12: 13400.126 | AG12: 66571499
A13: 1529 | B13: 45447 | C13: 27 | D13: 02:19:09pm | E13: 4.71 | F13: 905 | G13: D7 | H13: 45.433032 | I13: -73.938871 | J13: 39.021 | K13: 0 | L13: 0 | N13: 1 | O13: 500938ad2f841179 | P13: 1 | Q13: 4 | R13: 302 | S13: 302 | T13: 0.32763852 | U13: 0.65524771 | V13: 0.20866021 | W13: 0.96967145 | X13: 79 | Y13: 0.038813041 | Z13: 0.11505652 | AA13: 0.016882967 | AB13: -0.021235265 | AC13: 0.0022864088 | AD13: 5156.7633 | AE13: 48169978 | AF13: 13928.015 | AG13: 57205488
A14: 1530 | B14: 45447 | C14: 27 | D14: 02:19:22pm | E14: 4.71 | F14: 905 | G14: D5 | H14: 45.433006 | I14: -73.938952 | J14: 39.021 | K14: 0 | L14: 0 | N14: 1 | O14: 500938ba669012e1 | P14: 1 | Q14: 3 | R14: 209 | S14: 209 | T14: 0.31803937 | U14: 0.63605149 | V14: 0.18876994 | W14: 0.9624347 | X14: 58 | Y14: 0.031769196 | Z14: 0.10703438 | AA14: 0.012113749 | AB14: -0.02098267 | AC14: 0.0021530205 | AD14: 5751.3013 | AE14: 63310334 | AF14: 14341.046 | AG14: 52560667
A15: 1531 | B15: 45447 | C15: 27 | D15: 02:19:34pm | E15: 4.71 | F15: 905 | G15: D3 | H15: 45.432979 | I15: -73.939032 | J15: 39.021 | K15: 0 | L15: 0 | N15: 1 | O15: 500938c669fc4194 | P15: 1 | Q15: 2 | R15: 202 | S15: 202 | T15: 0.26524995 | U15: 0.53047714 | V15: 0.07082786 | W15: 0.99656588 | X15: 110 | Y15: 0.01352002 | Z15: 0.078820706 | AA15: 0.0075375271 | AB15: -0.026051558 | AC15: 0.0010181536 | AD15: 3106.953 | AE15: 11032561 | AF15: 16025.957 | AG15: 32605654
A16: 1532 | B16: 45447 | C16: 27 | D16: 02:19:47pm | E16: 4.71 | F16: 905 | G16: D1 | H16: 45.432952 | I16: -73.939113 | J16: 39.021 | K16: 0 | L16: 0 | N16: 1 | O16: 500938d31d4cc688 | P16: 1 | Q16: 1 | R16: 109 | S16: 109 | T16: 0.27450664 | U16: 0.54898956 | V16: 0.095186647 | W16: 0.98946066 | X16: 79 | Y16: 0.017280502 | Z16: 0.07780011 | AA16: 0.0079194835 | AB16: -0.025290811 | AC16: 0.0014341253 | AD16: 3453.4496 | AE16: 24697168 | AF16: 15812.874 | AG16: 36689970
A17: 1533 | B17: 45447 | C17: 27 | D17: 02:20:00pm | E17: 4.71 | F17: 905 | G17: D-1 | H17: 45.432925 | I17: -73.939194 | J17: 39.021 | K17: 0 | L17: 0 | N17: 1 | O17: 500938e02a9ec38d | P17: 1 | Q17: 0 | R17: 102 | S17: 102 | T17: 0.2776478 | U17: 0.5552714 | V17: 0.098046076 | W17: 0.99028947 | X17: 94 | Y17: 0.017854995 | Z17: 0.081305918 | AA17: 0.010030273 | AB17: -0.023489986 | AC17: 0.0012575184 | AD17: 3113.9884 | AE17: 10855438 | AF17: 16082.814 | AG17: 34030238
A18: 1534 | B18: 45447 | C18: 27 | D18: 02:20:58pm | E18: 4.71 | F18: 905 | G18: U-1 | H18: 45.4329 | I18: -73.939178 | J18: 39.021 | K18: 0 | L18: 0 | N18: 1 | O18: 5009391a2cd19750 | P18: 2 | Q18: 0 | R18: 103 | S18: 103 | T18: 0.26878517 | U18: 0.53754704 | V18: 0.091355539 | W18: 0.99169737 | X18: 84 | Y18: 0.017319913 | Z18: 0.065386978 | AA18: 0.0085695512 | AB18: -0.028301356 | AC18: 0.0010934629 | AD18: 3222.0498 | AE18: 16430691 | AF18: 16406.669 | AG18: 32028014
A19: 1535 | B19: 45447 | C19: 27 | D19: 02:21:11pm | E19: 4.71 | F19: 905 | G19: U1 | H19: 45.432926 | I19: -73.939096 | J19: 39.021 | K19: 0 | L19: 0 | N19: 1 | O19: 500939272161cf8e | P19: 2 | Q19: 1 | R19: 110 | S19: 110 | T19: 0.24668183 | U19: 0.49334227 | V19: 0.058814502 | W19: 0.98784227 | X19: 73 | Y19: 0.011645924 | Z19: 0.052291815 | AA19: 0.0057165548 | AB19: -0.030993819 | AC19: 0.0012111671 | AD19: 3182.941 | AE19: 11530047 | AF19: 16364.239 | AG19: 28969378
... A57: 1573 | B57: 45447 | C57: 27 | D57: 02:36:33pm | E57: 4.71 | F57: 905 | G57: U13 | H57: 45.432989 | I57: -73.938545 | J57: 39.019 | K57: 0 | L57: 0 | N57: 1 | O57: 50093cc1072c464e | P57: 6 | Q57: 7 | R57: 414 | S57: 414 | T57: 0.25888628 | U57: 0.51775051 | V57: 0.091784118 | W57: 0.70513254 | X57: 37 | Y57: 0.020024414 | Z57: 0.064682569 | AA57: 0.009717246 | AB57: -0.02710823 | AC57: 0.0014805295 | AD57: 3285.2919 | AE57: 25261685 | AF57: 15875.747 | AG57: 36968367
A58: 77777 | B58: 45771 | C58: 27 | T58: 0.13001853 | U58: 0.26002023 | V58: 0 | X58: 0 | Y58: 0.019774442 | Z58: -0.098932588 | AA58: 0.03694117 | AB58: -0.049953151 | AC58: 0.011514568 | AD58: -46.778277 | AE58: 2650260.4 | AF58: 15325.932 | AG58: 50849253

Sheet 710
A1: fid | B1: Date | C1: DAS | D1: Time | E1: Version | F1: Id | G1: Name | H1: Latitude | I1: Longitude | J1: Height | K1: AlarmRad | L1: WarningRad | M1: Status_Txt | N1: Visible | O1: UniqueID | P1: joined_row_index | Q1: joined_col_index | R1: joined_PlotID | S1: joined_PlotIDstring | T1: 710NDVI_mean | U1: 710NDVI_variance | V1: 710gNDVI_mean | W1: 710gNDVI_variance | X1: 710NDRE_mean | Y1: 710NDRE_variance | Z1: 710ExG_mean | AA1: 710ExG_variance | AB1: 710ExR_mean | AC1: 710ExR_variance | AD1: 710THRESH_mean | AE1: 710HA_mean | AF1: 710PLTCOUNT_
A2: 1517 | B2: 45447 | C2: 35 | D2: 01:48:44pm | E2: 4.71 | F2: 905 | G2: U-1 | H2: 45.43295 | I2: -73.939211 | J2: 39.021 | K2: 0 | L2: 0 | N2: 1 | O2: 5009318c201f855b | P2: 0 | Q2: 0 | R2: 101 | S2: 101 | T2: 0.30989558 | U2: 0.056533784 | V2: 0.094148944 | W2: 0.019562178 | X2: -0.041060259 | Y2: 0.0011669842 | Z2: 7633.7196 | AA2: 1.1545737e+08 | AB2: 10351.04 | AC2: 58781161 | AD2: 0.26384852 | AE2: 0.89632895 | AF2: 34
A3: 1519 | B3: 45447 | C3: 35 | D3: 02:15:42pm | E3: 4.71 | F3: 905 | G3: U1 | H3: 45.432976 | I3: -73.93913 | J3: 39.021 | K3: 0 | L3: 0 | N3: 1 | O3: 500937de01a1bd1f | P3: 0 | Q3: 1 | R3: 108 | S3: 108 | T3: 0.34445648 | U3: 0.071227552 | V3: 0.11597745 | W3: 0.024221596 | X3: -0.04129244 | Y3: 0.0013867769 | Z3: 9490.9186 | AA3: 1.3039291e+08 | AB3: 8318.0427 | AC3: 65589584 | AD3: 0.34392172 | AE3: 0.76757191 | AF3: 28
A4: 1520 | B4: 45447 | C4: 35 | D4: 02:15:55pm | E4: 4.71 | F4: 905 | G4: U3 | H4: 45.433004 | I4: -73.939049 | J4: 39.021 | K4: 0 | L4: 0 | N4: 1 | O4: 500937eb32eb8e40 | P4: 0 | Q4: 2 | R4: 201 | S4: 201 | T4: 0.33950845 | U4: 0.071654505 | V4: 0.12131275 | W4: 0.02367753 | X4: -0.038963071 | Y4: 0.0012769748 | Z4: 9303.9269 | AA4: 1.4942803e+08 | AB4: 8024.7969 | AC4: 67444604 | AD4: 0.32199889 | AE4: 0.59768421 | AF4: 17
A5: 1521 | B5: 45447 | C5: 35 | D5: 02:16:07pm | E5: 4.71 | F5: 905 | G5: U5 | H5: 45.43303 | I5: -73.938968 | J5: 39.021 | K5: 0 | L5: 0 | N5: 1 | O5: 500937f72fc8d1c6 | P5: 0 | Q5: 3 | R5: 208 | S5: 208 | T5: 0.43473274 | U5: 0.072270064 | V5: 0.16582127 | W5: 0.021423418 | X5: -0.024502704 | Y5: 0.0014047726 | Z5: 14295.349 | AA5: 2.137512e+08 | AB5: 5611.1493 | AC5: 73048313 | AD5: 0.44964381 | AE5: 0.29071818 | AF5: 8
A6: 1522 | B6: 45447 | C6: 35 | D6: 02:16:20pm | E6: 4.71 | F6: 905 | G6: U7 | H6: 45.433057 | I6: -73.938887 | J6: 39.021 | K6: 0 | L6: 0 | N6: 1 | O6: 5009380464b28f42 | P6: 0 | Q6: 4 | R6: 301 | S6: 301 | T6: 0.30762149 | U6: 0.072963482 | V6: 0.094463992 | W6: 0.023450527 | X6: -0.034765882 | Y6: 0.0012798591 | Z6: 9201.6318 | AA6: 1.6920837e+08 | AB6: 9211.9997 | AC6: 72996268 | AD6: 0.28678871 | AE6: 0.36028106 | AF6: 12
A7: 1523 | B7: 45447 | C7: 35 | D7: 02:16:32pm | E7: 4.71 | F7: 905 | G7: U9 | H7: 45.433084 | I7: -73.938806 | J7: 39.021 | K7: 0 | L7: 0 | N7: 1 | O7: 5.009381e+15 | P7: 0 | Q7: 5 | R7: 308 | S7: 308 | T7: 0.24637067 | U7: 0.052424976 | V7: 0.062314966 | W7: 0.014264521 | X7: -0.037879712 | Y7: 0.0012869913 | Z7: 7594.3495 | AA7: 1.543843e+08 | AB7: 10948.746 | AC7: 54500447 | AD7: 0.20029925 | AE7: 0.46047974 | AF7: 11
A8: 1524 | B8: 45447 | C8: 35 | D8: 02:17:01pm | E8: 4.71 | F8: 905 | G8: U11 | H8: 45.433111 | I8: -73.938725 | J8: 39.021 | K8: 0 | L8: 0 | N8: 1 | O8: 5009382d1f03b98f | P8: 0 | Q8: 6 | R8: 401 | S8: 401 | T8: 0.36104368 | U8: 0.064346901 | V8: 0.11574965 | W8: 0.016375599 | X8: -0.041203667 | Y8: 0.0016128396 | Z8: 12677.612 | AA8: 2.2840916e+08 | AB8: 8598.6752 | AC8: 66140991 | AD8: 0.35333179 | AE8: 0.67975473 | AF8: 26
A9: 1525 | B9: 45447 | C9: 35 | D9: 02:17:13pm | E9: 4.71 | F9: 905 | G9: U13 | H9: 45.433138 | I9: -73.938644 | J9: 39.021 | K9: 0 | L9: 0 | N9: 1 | O9: 500938393916ae56 | P9: 0 | Q9: 6 | R9: 408 | S9: 408 | T9: 0.39267317 | U9: 0.057292837 | V9: 0.13209627 | W9: 0.013812359 | X9: -0.04000206 | Y9: 0.0016105689 | Z9: 13137.721 | AA9: 2.3163146e+08 | AB9: 8194.3428 | AC9: 60522853 | AD9: 0.37158047 | AE9: 0.79997632 | AF9: 32
A10: 1526 | B10: 45447 | C10: 35 | D10: 02:18:31pm | E10: 4.71 | F10: 905 | G10: D13 | H10: 45.433113 | I10: -73.938628 | J10: 39.02 | K10: 0 | L10: 0 | N10: 1 | O10: 500938877536384a | P10: 1 | Q10: 7 | R10: 409 | S10: 409 | T10: 0.2453222 | U10: 0.042687681 | V10: 0.065402689 | W10: 0.01292707 | X10: -0.041579541 | Y10: 0.001171923 | Z10: 5598.6673 | AA10: 1.1877098e+08 | AB10: 12641.465 | AC10: 49101285 | AD10: 0.15823866 | AE10: 0.39765789 | AF10: 12
A11: 1527 | B11: 45447 | C11: 35 | D11: 02:18:44pm | E11: 4.71 | F11: 905 | G11: D11 | H11: 45.433086 | I11: -73.938709 | J11: 39.02 | K11: 0 | L11: 0 | N11: 1 | O11: 50093894752ce1b7 | P11: 1 | Q11: 6 | R11: 402 | S11: 402 | T11: 0.3959398 | U11: 0.069148048 | V11: 0.1551711 | W11: 0.018282857 | X11: -0.027366026 | Y11: 0.0014144342 | Z11: 13707.018 | AA11: 2.5872699e+08 | AB11: 7190.0709 | AC11: 74503205 | AD11: 0.37222266 | AE11: 0.26739122 | AF11: 4
A12: 1528 | B12: 45447 | C12: 35 | D12: 02:18:57pm | E12: 4.71 | F12: 905 | G12: D9 | H12: 45.433059 | I12: -73.93879 | J12: 39.021 | K12: 0 | L12: 0 | N12: 1 | O12: 500938a125f6843f | P12: 1 | Q12: 5 | R12: 309 | S12: 309 | T12: 0.37123875 | U12: 0.064515307 | V12: 0.12702665 | W12: 0.015008827 | X12: -0.032375803 | Y12: 0.0016005301 | Z12: 13974.027 | AA12: 2.5323134e+08 | AB12: 7470.1491 | AC12: 65094811 | AD12: 0.36856984 | AE12: 0.67669737 | AF12: 14
A13: 1529 | B13: 45447 | C13: 35 | D13: 02:19:09pm | E13: 4.71 | F13: 905 | G13: D7 | H13: 45.433032 | I13: -73.938871 | J13: 39.021 | K13: 0 | L13: 0 | N13: 1 | O13: 500938ad2f841179 | P13: 1 | Q13: 4 | R13: 302 | S13: 302 | T13: 0.41249349 | U13: 0.075923933 | V13: 0.15199404 | W13: 0.023131853 | X13: -0.030520325 | Y13: 0.0015132122 | Z13: 14217.988 | AA13: 2.1824869e+08 | AB13: 6349.9994 | AC13: 83554519 | AD13: 0.44083259 | AE13: 0.55488744 | AF13: 15
A14: 1530 | B14: 45447 | C14: 35 | D14: 02:19:22pm | E14: 4.71 | F14: 905 | G14: D5 | H14: 45.433006 | I14: -73.938952 | J14: 39.021 | K14: 0 | L14: 0 | N14: 1 | O14: 500938ba669012e1 | P14: 1 | Q14: 3 | R14: 209 | S14: 209 | T14: 0.33838092 | U14: 0.064864228 | V14: 0.097865813 | W14: 0.016876185 | X14: -0.039604872 | Y14: 0.0014145364 | Z14: 11422.978 | AA14: 2.0548829e+08 | AB14: 8576.6189 | AC14: 68318060 | AD14: 0.3316208 | AE14: 0.77599274 | AF14: 26
A15: 1531 | B15: 45447 | C15: 35 | D15: 02:19:34pm | E15: 4.71 | F15: 905 | G15: D3 | H15: 45.432979 | I15: -73.939032 | J15: 39.021 | K15: 0 | L15: 0 | N15: 1 | O15: 500938c669fc4194 | P15: 1 | Q15: 2 | R15: 202 | S15: 202 | T15: 0.30690757 | U15: 0.063850986 | V15: 0.099491892 | W15: 0.021816388 | X15: -0.040848711 | Y15: 0.0012774788 | Z15: 8036.4856 | AA15: 1.155226e+08 | AB15: 9502.5778 | AC15: 56673626 | AD15: 0.28263475 | AE15: 0.87217105 | AF15: 66
A16: 1532 | B16: 45447 | C16: 35 | D16: 02:19:47pm | E16: 4.71 | F16: 905 | G16: D1 | H16: 45.432952 | I16: -73.939113 | J16: 39.021 | K16: 0 | L16: 0 | N16: 1 | O16: 500938d31d4cc688 | P16: 1 | Q16: 1 | R16: 109 | S16: 109 | T16: 0.31839208 | U16: 0.067264975 | V16: 0.091430297 | W16: 0.01884527 | X16: -0.039643231 | Y16: 0.0013692497 | Z16: 9975.0896 | AA16: 1.7483283e+08 | AB16: 8816.9228 | AC16: 69614024 | AD16: 0.3052819 | AE16: 0.54257895 | AF16: 24
A17: 1533 | B17: 45447 | C17: 35 | D17: 02:20:00pm | E17: 4.71 | F17: 905 | G17: D-1 | H17: 45.432925 | I17: -73.939194 | J17: 39.021 | K17: 0 | L17: 0 | N17: 1 | O17: 500938e02a9ec38d | P17: 1 | Q17: 0 | R17: 102 | S17: 102 | T17: 0.35441335 | U17: 0.071654563 | V17: 0.12554717 | W17: 0.026791164 | X17: -0.030819617 | Y17: 0.0012971003 | Z17: 9484.3292 | AA17: 1.3260355e+08 | AB17: 8682.8611 | AC17: 75756712 | AD17: 0.32886226 | AE17: 0.46360526 | AF17: 10
A18: 1534 | B18: 45447 | C18: 35 | D18: 02:20:58pm | E18: 4.71 | F18: 905 | G18: U-1 | H18: 45.4329 | I18: -73.939178 | J18: 39.021 | K18: 0 | L18: 0 | N18: 1 | O18: 5009391a2cd19750 | P18: 2 | Q18: 0 | R18: 103 | S18: 103 | T18: 0.33159283 | U18: 0.068421812 | V18: 0.10184427 | W18: 0.022349491 | X18: -0.036106879 | Y18: 0.0011562913 | Z18: 9790.4827 | AA18: 1.589662e+08 | AB18: 8956.9794 | AC18: 73890090 | AD18: 0.30571684 | AE18: 0.55298096 | AF18: 15
A19: 1535 | B19: 45447 | C19: 35 | D19: 02:21:11pm | E19: 4.71 | F19: 905 | G19: U1 | H19: 45.432926 | I19: -73.939096 | J19: 39.021 | K19: 0 | L19: 0 | N19: 1 | O19: 500939272161cf8e | P19: 2 | Q19: 1 | R19: 110 | S19: 110 | T19: 0.28747373 | U19: 0.066712106 | V19: 0.074118911 | W19: 0.019946755 | X19: -0.038143392 | Y19: 0.0012967507 | Z19: 8571.4011 | AA19: 1.404363e+08 | AB19: 9798.6768 | AC19: 65172224 | AD19: 0.27612301 | AE19: 0.68587745 | AF19: 27
... A57: 1573 | B57: 45447 | C57: 35 | D57: 02:36:33pm | E57: 4.71 | F57: 905 | G57: U13 | H57: 45.432989 | I57: -73.938545 | J57: 39.019 | K57: 0 | L57: 0 | N57: 1 | O57: 50093cc1072c464e | P57: 6 | Q57: 7 | R57: 414 | S57: 414 | T57: 0.25485986 | U57: 0.051701114 | V57: 0.073446572 | W57: 0.016826262 | X57: -0.033298175 | Y57: 0.0012318308 | Z57: 6440.0538 | AA57: 1.218521e+08 | AB57: 11413.696 | AC57: 53465212 | AD57: 0.18740235 | AE57: 0.41580263 | AF57: 13
A58: 77777 | B58: 45771 | C58: 35 | T58: 0.059061046 | U58: 0.023827873 | V58: -0.1363687 | W58: 0.037365785 | X58: -0.066651966 | Y58: 0.010421854 | Z58: -961.45178 | AA58: 3786260.8 | AB58: 15010.595 | AC58: 55625917 | AD58: 0.0014794889 | AF58: 0

Sheet 715
A1: fid | B1: Date | C1: DAS | D1: Time | E1: Version | F1: Id | G1: Name | H1: Latitude | I1: Longitude | J1: Height | K1: AlarmRad | L1: WarningRad | M1: Status_Txt | N1: Visible | O1: UniqueID | P1: joined_row_index | Q1: joined_col_index | R1: joined_PlotID | S1: joined_PlotIDstring | T1: NDVI_mean | U1: Thresholdsum | V1: Thresholdmean | W1: 715SAVI_mean | X1: 715NDVI_mean | Y1: 715NDVI_variance | Z1: 715gNDVI_mean | AA1: 715gNDVI_variance | AB1: 715NDRE_mean | AC1: 715NDRE_variance | AD1: 715ExG_mean | AE1: 715ExG_variance | AF1: 715ExR_mean | AG1: 715ExR_variance | AH1: HA_mean | AI1: 715PLTCOUNT_
A2: 1517 | B2: 45447 | C2: 40 | D2: 01:48:44pm | E2: 4.71 | F2: 905 | G2: U-1 | H2: 45.43295 | I2: -73.939211 | J2: 39.021 | K2: 0 | L2: 0 | N2: 1 | O2: 5009318c201f855b | P2: 0 | Q2: 0 | R2: 101 | S2: 101 | T2: 0.52731836 | U2: 71841 | V2: 0.46975166 | W2: 1.0530753 | X2: 0.52731836 | Y2: 0.058714147 | Z2: 0.53581297 | AA2: 0.01973423 | AB2: 0.12722867 | AC2: 0.0025870455 | AD2: 9174.314 | AE2: 1.0457618e+08 | AF2: 8286.2276 | AG2: 94563137 | AH2: 1 | AI2: 131
A3: 1519 | B3: 45447 | C3: 40 | D3: 02:15:42pm | E3: 4.71 | F3: 905 | G3: U1 | H3: 45.432976 | I3: -73.93913 | J3: 39.021 | K3: 0 | L3: 0 | N3: 1 | O3: 500937de01a1bd1f | P3: 0 | Q3: 1 | R3: 108 | S3: 108 | T3: 0.61267219 | U3: 93204 | V3: 0.60942343 | W3: 1.2236028 | X3: 0.61267219 | Y3: 0.057726836 | Z3: 0.57944418 | AA3: 0.021035902 | AB3: 0.13566002 | AC3: 0.0032425569 | AD3: 12012.919 | AE3: 1.1946377e+08 | AF3: 6654.8944 | AG3: 1.1393011e+08 | AH3: 1 | AI3: 73
A4: 1520 | B4: 45447 | C4: 40 | D4: 02:15:55pm | E4: 4.71 | F4: 905 | G4: U3 | H4: 45.433004 | I4: -73.939049 | J4: 39.021 | K4: 0 | L4: 0 | N4: 1 | O4: 500937eb32eb8e40 | P4: 0 | Q4: 2 | R4: 201 | S4: 201 | T4: 0.59207317 | U4: 87858 | V4: 0.5744756 | W4: 1.1824744 | X4: 0.59207317 | Y4: 0.061402806 | Z4: 0.56448544 | AA4: 0.020736816 | AB4: 0.14161999 | AC4: 0.0033055989 | AD4: 12065.403 | AE4: 1.5376329e+08 | AF4: 6998.6739 | AG4: 1.1993516e+08 | AH4: 1 | AI4: 138
A5: 1521 | B5: 45447 | C5: 40 | D5: 02:16:07pm | E5: 4.71 | F5: 905 | G5: U5 | H5: 45.43303 | I5: -73.938968 | J5: 39.021 | K5: 0 | L5: 0 | N5: 1 | O5: 500937f72fc8d1c6 | P5: 0 | Q5: 3 | R5: 208 | S5: 208 | T5: 0.58681423 | U5: 94026 | V5: 0.61479815 | W5: 1.1719582 | X5: 0.58681423 | Y5: 0.054666979 | Z5: 0.53886538 | AA5: 0.013309593 | AB5: 0.13996381 | AC5: 0.0025898488 | AD5: 15344.56 | AE5: 2.0518744e+08 | AF5: 5908.9346 | AG5: 99162620 | AH5: 1 | AI5: 100
A6: 1522 | B6: 45447 | C6: 40 | D6: 02:16:20pm | E6: 4.71 | F6: 905 | G6: U7 | H6: 45.433057 | I6: -73.938887 | J6: 39.021 | K6: 0 | L6: 0 | N6: 1 | O6: 5009380464b28f42 | P6: 0 | Q6: 4 | R6: 301 | S6: 301 | T6: 0.47911573 | U6: 58483 | V6: 0.38240429 | W6: 0.95703158 | X6: 0.47911573 | Y6: 0.057893802 | Z6: 0.48206222 | AA6: 0.016216778 | AB6: 0.13903211 | AC6: 0.001674186 | AD6: 10254.53 | AE6: 1.8941166e+08 | AF6: 7872.9829 | AG6: 92173701 | AH6: 1 | AI6: 20
A7: 1523 | B7: 45447 | C7: 40 | D7: 02:16:32pm | E7: 4.71 | F7: 905 | G7: U9 | H7: 45.433084 | I7: -73.938806 | J7: 39.021 | K7: 0 | L7: 0 | N7: 1 | O7: 5.009381e+15 | P7: 0 | Q7: 5 | R7: 308 | S7: 308 | T7: 0.45038799 | U7: 51048 | V7: 0.33378886 | W7: 0.8995711 | X7: 0.45038799 | Y7: 0.048421299 | Z7: 0.4581503 | AA7: 0.013766609 | AB7: 0.14420874 | AC7: 0.0018857177 | AD7: 8252.1954 | AE7: 1.3068204e+08 | AF7: 10726.314 | AG7: 79333061 | AH7: 1 | AI7: 90
A8: 1524 | B8: 45447 | C8: 40 | D8: 02:17:01pm | E8: 4.71 | F8: 905 | G8: U11 | H8: 45.433111 | I8: -73.938725 | J8: 39.021 | K8: 0 | L8: 0 | N8: 1 | O8: 5009382d1f03b98f | P8: 0 | Q8: 6 | R8: 401 | S8: 401 | T8: 0.55016466 | U8: 80844 | V8: 0.52861328 | W8: 1.0989156 | X8: 0.55016466 | Y8: 0.051860973 | Z8: 0.47500697 | AA8: 0.012560239 | AB8: 0.12435191 | AC8: 0.0017186861 | AD8: 14754.76 | AE8: 2.210931e+08 | AF8: 5525.7194 | AG8: 76397218 | AH8: 1 | AI8: 36
A9: 1525 | B9: 45447 | C9: 40 | D9: 02:17:13pm | E9: 4.71 | F9: 905 | G9: U13 | H9: 45.433138 | I9: -73.938644 | J9: 39.021 | K9: 0 | L9: 0 | N9: 1 | O9: 500938393916ae56 | P9: 0 | Q9: 6 | R9: 408 | S9: 408 | T9: 0.57652645 | U9: 90457 | V9: 0.59146577 | W9: 1.1514283 | X9: 0.57652645 | Y9: 0.046466941 | Z9: 0.51489816 | AA9: 0.010647779 | AB9: 0.10727609 | AC9: 0.0033033078 | AD9: 14864.819 | AE9: 2.0013638e+08 | AF9: 6739.3612 | AG9: 85424015 | AH9: 1 | AI9: 180
A10: 1526 | B10: 45447 | C10: 40 | D10: 02:18:31pm | E10: 4.71 | F10: 905 | G10: D13 | H10: 45.433113 | I10: -73.938628 | J10: 39.02 | K10: 0 | L10: 0 | N10: 1 | O10: 500938877536384a | P10: 1 | Q10: 7 | R10: 409 | S10: 409 | T10: 0.40898784 | U10: 42167 | V10: 0.27571123 | W10: 0.81680829 | X10: 0.40898784 | Y10: 0.049839369 | Z10: 0.44020799 | AA10: 0.014699282 | AB10: 0.10215902 | AC10: 0.0022943274 | AD10: 6676.5225 | AE10: 1.088119e+08 | AF10: 12664.6 | AG10: 80979986 | AH10: 1 | AI10: 74
A11: 1527 | B11: 45447 | C11: 40 | D11: 02:18:44pm | E11: 4.71 | F11: 905 | G11: D11 | H11: 45.433086 | I11: -73.938709 | J11: 39.02 | K11: 0 | L11: 0 | N11: 1 | O11: 50093894752ce1b7 | P11: 1 | Q11: 6 | R11: 402 | S11: 402 | T11: 0.55016517 | U11: 73437 | V11: 0.48018125 | W11: 1.0989423 | X11: 0.55016517 | Y11: 0.052280849 | Z11: 0.48729273 | AA11: 0.014059032 | AB11: 0.13858697 | AC11: 0.0015650075 | AD11: 13282.388 | AE11: 2.1560072e+08 | AF11: 5498.4885 | AG11: 77293523 | AH11: 1 | AI11: 43
A12: 1528 | B12: 45447 | C12: 40 | D12: 02:18:57pm | E12: 4.71 | F12: 905 | G12: D9 | H12: 45.433059 | I12: -73.93879 | J12: 39.021 | K12: 0 | L12: 0 | N12: 1 | O12: 500938a125f6843f | P12: 1 | Q12: 5 | R12: 309 | S12: 309 | T12: 0.5920933 | U12: 95406 | V12: 0.62382958 | W12: 1.1827227 | X12: 0.5920933 | Y12: 0.038453422 | Z12: 0.5107015 | AA12: 0.0087438969 | AB12: 0.12461799 | AC12: 0.0016602378 | AD12: 16205.953 | AE12: 2.3207102e+08 | AF12: 5564.935 | AG12: 83021904 | AH12: 1 | AI12: 170
A13: 1529 | B13: 45447 | C13: 40 | D13: 02:19:09pm | E13: 4.71 | F13: 905 | G13: D7 | H13: 45.433032 | I13: -73.938871 | J13: 39.021 | K13: 0 | L13: 0 | N13: 1 | O13: 500938ad2f841179 | P13: 1 | Q13: 4 | R13: 302 | S13: 302 | T13: 0.60389065 | U13: 91741 | V13: 0.5998653 | W13: 1.2063314 | X13: 0.60389065 | Y13: 0.049385645 | Z13: 0.5277549 | AA13: 0.012144647 | AB13: 0.13579854 | AC13: 0.001598549 | AD13: 16602.69 | AE13: 2.2090886e+08 | AF13: 3235.1474 | AG13: 87014671 | AH13: 1 | AI13: 38
A14: 1530 | B14: 45447 | C14: 40 | D14: 02:19:22pm | E14: 4.71 | F14: 905 | G14: D5 | H14: 45.433006 | I14: -73.938952 | J14: 39.021 | K14: 0 | L14: 0 | N14: 1 | O14: 500938ba669012e1 | P14: 1 | Q14: 3 | R14: 209 | S14: 209 | T14: 0.52202784 | U14: 74674 | V14: 0.4882696 | W14: 1.0426277 | X14: 0.52202784 | Y14: 0.053287222 | Z14: 0.48872918 | AA14: 0.012895469 | AB14: 0.12013311 | AC14: 0.0032129334 | AD14: 12833.578 | AE14: 2.0388337e+08 | AF14: 8792.9044 | AG14: 1.0019826e+08 | AH14: 1 | AI14: 140
A15: 1531 | B15: 45447 | C15: 40 | D15: 02:19:34pm | E15: 4.71 | F15: 905 | G15: D3 | H15: 45.432979 | I15: -73.939032 | J15: 39.021 | K15: 0 | L15: 0 | N15: 1 | O15: 500938c669fc4194 | P15: 1 | Q15: 2 | R15: 202 | S15: 202 | T15: 0.55364621 | U15: 80083 | V15: 0.52363734 | W15: 1.1057555 | X15: 0.55364621 | Y15: 0.054437805 | Z15: 0.52866243 | AA15: 0.019883661 | AB15: 0.12237142 | AC15: 0.0024872863 | AD15: 10194.29 | AE15: 1.0696639e+08 | AF15: 9295.429 | AG15: 1.0243096e+08 | AH15: 1 | AI15: 216
A16: 1532 | B16: 45447 | C16: 40 | D16: 02:19:47pm | E16: 4.71 | F16: 905 | G16: D1 | H16: 45.432952 | I16: -73.939113 | J16: 39.021 | K16: 0 | L16: 0 | N16: 1 | O16: 500938d31d4cc688 | P16: 1 | Q16: 1 | R16: 109 | S16: 109 | T16: 0.60021509 | U16: 88740 | V16: 0.58023513 | W16: 1.1987387 | X16: 0.60021509 | Y16: 0.05938803 | Z16: 0.55410422 | AA16: 0.019522579 | AB16: 0.13270927 | AC16: 0.0034951096 | AD16: 12820.285 | AE16: 1.6769947e+08 | AF16: 7133.5429 | AG16: 1.2316087e+08 | AH16: 1 | AI16: 76
