Workbook

Sheet 704 
A1: fid | B1: id | C1: Trial Name | D1: DAS | E1: layer | F1: path | G1: 704ExG_mean | H1: 704ExG_variance | I1: 704ExR_mean | J1: 704ExR_variance | K1: 704gNDVI_mean | L1: 704gNDVI_variance | M1: 704gNDRE_mean | N1: 704gNDRE_variance | O1: 704NDVI_mean | P1: 704NDVI_variance | Q1: 704THRESH_mean | R1: 704THRESH_variance | S1: 704HA_mean | T1: 704HA_variance | U1: 704PLT_
A2: 1 | B2: 101 | C2: AYT Trial | D2: 10 | E2: 7-04 ayt plot files â€” ayttrialdata_rows_polygons__ayt_plots_dissolved | F2: D:/Drone Imagery/2025 summer/20250704/shapefiles/7-04 ayt plot files.gpkg|layername=ayttrialdata_rows_polygons__ayt_plots_dissolved | G2: 2704.6762 | H2: 10293556 | I2: 2704.6762 | J2: 10293556 | K2: 0.063690008 | L2: 0.0090996723 | M2: -0.033861884 | N2: 0.00073684243 | O2: 0.25585097 | P2: 0.018101762 | Q2: 0.091019998 | R2: 0.082735358 | S2: 0.96994594 | T2: 0.02915081 | U2: 72
A3: 2 | B3: 102 | C3: AYT Trial | D3: 10 | E3: 7-04 ayt plot files â€” ayttrialdata_rows_polygons__ayt_plots_dissolved | F3: D:/Drone Imagery/2025 summer/20250704/shapefiles/7-04 ayt plot files.gpkg|layername=ayttrialdata_rows_polygons__ayt_plots_dissolved | G3: 3744.3685 | H3: 40554902 | I3: 3744.3685 | J3: 40554902 | K3: 0.072802684 | L3: 0.0069335091 | M3: -0.030261519 | N3: 0.00077486177 | O3: 0.27532694 | P3: 0.020750776 | Q3: 0.11319875 | R3: 0.10038479 | S3: 0.90491395 | T3: 0.086044689 | U3: 57
A4: 3 | B4: 103 | C4: AYT Trial | D4: 10 | E4: 7-04 ayt plot files â€” ayttrialdata_rows_polygons__ayt_plots_dissolved | F4: D:/Drone Imagery/2025 summer/20250704/shapefiles/7-04 ayt plot files.gpkg|layername=ayttrialdata_rows_polygons__ayt_plots_dissolved | G4: 3370.7805 | H4: 27904618 | I4: 3370.7805 | J4: 27904618 | K4: 0.078040029 | L4: 0.0079329347 | M4: -0.025044146 | N4: 0.00070578081 | O4: 0.28121831 | P4: 0.019766732 | Q4: 0.10325035 | R4: 0.092589712 | S4: 0.94013334 | T4: 0.056282639 | U4: 84
A5: 4 | B5: 104 | C5: AYT Trial | D5: 10 | E5: 7-04 ayt plot files â€” ayttrialdata_rows_polygons__ayt_plots_dissolved | F5: D:/Drone Imagery/2025 summer/20250704/shapefiles/7-04 ayt plot files.gpkg|layername=ayttrialdata_rows_polygons__ayt_plots_dissolved | G5: 3920.1302 | H5: 39937947 | I5: 3920.1302 | J5: 39937947 | K5: 0.068368519 | L5: 0.0089967866 | M5: -0.030878627 | N5: 0.00084212816 | O5: 0.27670967 | P5: 0.023543382 | Q5: 0.11446292 | R5: 0.10136116 | S5: 0.93327381 | T5: 0.062273808 | U5: 59
A6: 5 | B6: 105 | C6: AYT Trial | D6: 10 | E6: 7-04 ayt plot files â€” ayttrialdata_rows_polygons__ayt_plots_dissolved | F6: D:/Drone Imagery/2025 summer/20250704/shapefiles/7-04 ayt plot files.gpkg|layername=ayttrialdata_rows_polygons__ayt_plots_dissolved | G6: 4852.085 | H6: 54276747 | I6: 4852.085 | J6: 54276747 | K6: 0.090191458 | L6: 0.0091880314 | M6: -0.026284081 | N6: 0.0012883554 | O6: 0.30446813 | P6: 0.026882291 | Q6: 0.14608241 | R6: 0.12474234 | S6: 0.94198074 | T6: 0.054653026 | U6: 63
A7: 6 | B7: 106 | C7: AYT Trial | D7: 10 | E7: 7-04 ayt plot files â€” ayttrialdata_rows_polygons__ayt_plots_dissolved | F7: D:/Drone Imagery/2025 summer/20250704/shapefiles/7-04 ayt plot files.gpkg|layername=ayttrialdata_rows_polygons__ayt_plots_dissolved | G7: 2843.6147 | H7: 19437533 | I7: 2843.6147 | J7: 19437533 | K7: 0.071526475 | L7: 0.0054133348 | M7: -0.026268315 | N7: 0.0013123126 | O7: 0.26059313 | P7: 0.012870042 | Q7: 0.063626681 | R7: 0.059578327 | S7: 0.94314641 | T7: 0.053621262 | U7: 48
A8: 7 | B8: 107 | C8: AYT Trial | D8: 10 | E8: 7-04 ayt plot files â€” ayttrialdata_rows_polygons__ayt_plots_dissolved | F8: D:/Drone Imagery/2025 summer/20250704/shapefiles/7-04 ayt plot files.gpkg|layername=ayttrialdata_rows_polygons__ayt_plots_dissolved | G8: 3078.0814 | H8: 33247213 | I8: 3078.0814 | J8: 33247213 | K8: 0.083826089 | L8: 0.0055260245 | M8: -0.026677735 | N8: 0.00160842 | O8: 0.28082221 | P8: 0.015883089 | Q8: 0.092593945 | R8: 0.084020306 | S8: 0.94130173 | T8: 0.055252784 | U8: 59
A9: 8 | B9: 108 | C9: AYT Trial | D9: 10 | E9: 7-04 ayt plot files â€” ayttrialdata_rows_polygons__ayt_plots_dissolved | F9: D:/Drone Imagery/2025 summer/20250704/shapefiles/7-04 ayt plot files.gpkg|layername=ayttrialdata_rows_polygons__ayt_plots_dissolved | G9: 3965.4551 | H9: 62353202 | I9: 3965.4551 | J9: 62353202 | K9: 0.090750941 | L9: 0.00529848 | M9: -0.026935347 | N9: 0.0007690851 | O9: 0.29691723 | P9: 0.021248439 | Q9: 0.12999952 | R9: 0.11309965 | S9: 0.89432139 | T9: 0.094510642 | U9: 64
A10: 9 | B10: 109 | C10: AYT Trial | D10: 10 | E10: 7-04 ayt plot files â€” ayttrialdata_rows_polygons__ayt_plots_dissolved | F10: D:/Drone Imagery/2025 summer/20250704/shapefiles/7-04 ayt plot files.gpkg|layername=ayttrialdata_rows_polygons__ayt_plots_dissolved | G10: 2630.6495 | H10: 32894378 | I10: 2630.6495 | J10: 32894378 | K10: 0.088685699 | L10: 0.0060005275 | M10: -0.027021156 | N10: 0.00063429453 | O10: 0.28583664 | P10: 0.016629933 | Q10: 0.092424714 | R10: 0.083882386 | S10: 0.96895294 | T10: 0.030083141 | U10: 92
A11: 10 | B11: 110 | C11: AYT Trial | D11: 10 | E11: 7-04 ayt plot files â€” ayttrialdata_rows_polygons__ayt_plots_dissolved | F11: D:/Drone Imagery/2025 summer/20250704/shapefiles/7-04 ayt plot files.gpkg|layername=ayttrialdata_rows_polygons__ayt_plots_dissolved | G11: 3965.0876 | H11: 72572676 | I11: 3965.0876 | J11: 72572676 | K11: 0.091703269 | L11: 0.0064920963 | M11: -0.026150972 | N11: 0.00066916756 | O11: 0.30760704 | P11: 0.023522844 | Q11: 0.13520786 | R11: 0.1169267 | S11: 0.90340365 | T11: 0.087265491 | U11: 67
A12: 11 | B12: 201 | C12: AYT Trial | D12: 10 | E12: 7-04 ayt plot files â€” ayttrialdata_rows_polygons__ayt_plots_dissolved | F12: D:/Drone Imagery/2025 summer/20250704/shapefiles/7-04 ayt plot files.gpkg|layername=ayttrialdata_rows_polygons__ayt_plots_dissolved | G12: 2822.0601 | H12: 9746082.1 | I12: 2822.0601 | J12: 9746082.1 | K12: 0.035246088 | L12: 0.0090884552 | M12: -0.044973045 | N12: 0.00066445409 | O12: 0.22418679 | P12: 0.017570649 | Q12: 0.079701136 | R12: 0.073348865 | S12: 0.946111 | T12: 0.050984979 | U12: 83
A13: 12 | B13: 202 | C13: AYT Trial | D13: 10 | E13: 7-04 ayt plot files â€” ayttrialdata_rows_polygons__ayt_plots_dissolved | F13: D:/Drone Imagery/2025 summer/20250704/shapefiles/7-04 ayt plot files.gpkg|layername=ayttrialdata_rows_polygons__ayt_plots_dissolved | G13: 2482.2425 | H13: 7680483.2 | I13: 2482.2425 | J13: 7680483.2 | K13: 0.027306101 | L13: 0.0059068889 | M13: -0.045049368 | N13: 0.00056085006 | O13: 0.21203048 | P13: 0.011734199 | Q13: 0.051638982 | R13: 0.048972397 | S13: 0.95119297 | T13: 0.046424906 | U13: 76
... A165: 164 | B165: 612 | C165: PYT Trial | D165: 10 | E165: PYT plots | F165: D:/Drone Imagery/2025 summer/20250704/shapefiles/7-04 reg plot polygons.gpkg|layername=pyt_trial_data_rows_polygons__pyt_trial_data_row_polygons | G165: 3177.906 | H165: 5281778.1 | I165: 3177.906 | J165: 5281778.1 | K165: 0.052814919 | L165: 0.0023167525 | M165: -0.031813119 | N165: 0.00054481704 | O165: 0.2313696 | P165: 0.0042864093 | Q165: 0.016999004 | R165: 0.016710037 | S165: 0.83581642 | T165: 0.13722733 | U165: 61
A166: 165 | C166: PYT Trial | D166: 10 | E166: PYT plots | F166: D:/Drone Imagery/2025 summer/20250704/shapefiles/7-04 reg plot polygons.gpkg|layername=pyt_trial_data_rows_polygons__pyt_trial_data_row_polygons | G166: 1392.5653 | H166: 321273.52 | I166: 1392.5653 | J166: 321273.52 | K166: 0.028927717 | L166: 0.001540259 | M166: -0.035423331 | N166: 0.00045927125 | O166: 0.21366349 | P166: 0.00094946271 | Q166: 0 | R166: 0 | S166: 0 | T166: 0 | U166: 0
A167: 166 | C167: PYT Trial | D167: 10 | E167: PYT plots | F167: D:/Drone Imagery/2025 summer/20250704/shapefiles/7-04 reg plot polygons.gpkg|layername=pyt_trial_data_rows_polygons__pyt_trial_data_row_polygons | G167: 150.53517 | H167: 2443874.4 | I167: 150.53517 | J167: 2443874.4 | K167: -0.048769832 | L167: 0.044632959 | M167: -0.025160478 | N167: 0.012115284 | O167: 0.18291008 | P167: 0.029187201 | Q167: 0.020821609 | R167: 0.02038807 | S167: 0 | T167: 0 | U167: 0
A168: 167 | B168: 801 | C168: Registration | D168: 10 | E168: Registration Plots | F168: D:/Drone Imagery/2025 summer/20250704/shapefiles/7-04 reg plot files.gpkg|layername=registrationtrialdatarows | G168: 3354.6346 | H168: 13968109 | I168: 3354.6346 | J168: 13968109 | K168: 0.083563806 | L168: 0.0076138674 | M168: -0.029225603 | N168: 0.0006112483 | O168: 0.28470247 | P168: 0.016365323 | Q168: 0.094161125 | R168: 0.085294808 | S168: 0.88945763 | T168: 0.098322752 | U168: 94
A169: 168 | B169: 802 | C169: Registration | D169: 10 | E169: Registration Plots | F169: D:/Drone Imagery/2025 summer/20250704/shapefiles/7-04 reg plot files.gpkg|layername=registrationtrialdatarows | G169: 2657.1947 | H169: 5470673.9 | I169: 2657.1947 | J169: 5470673.9 | K169: 0.061499673 | L169: 0.0065791581 | M169: -0.034845118 | N169: 0.00053402548 | O169: 0.25682707 | P169: 0.011565342 | Q169: 0.061441621 | R169: 0.057666549 | S169: 0.94922007 | T169: 0.048201332 | U169: 95
A170: 169 | B170: 803 | C170: Registration | D170: 10 | E170: Registration Plots | F170: D:/Drone Imagery/2025 summer/20250704/shapefiles/7-04 reg plot files.gpkg|layername=registrationtrialdatarows | G170: 3868.0896 | H170: 36044716 | I170: 3868.0896 | J170: 36044716 | K170: 0.072998388 | L170: 0.0069182919 | M170: -0.028931945 | N170: 0.00082716064 | O170: 0.28134719 | P170: 0.019645798 | Q170: 0.11529483 | R170: 0.10200193 | S170: 0.86788576 | T170: 0.11466007 | U170: 71
A171: 170 | B171: 804 | C171: Registration | D171: 10 | E171: Registration Plots | F171: D:/Drone Imagery/2025 summer/20250704/shapefiles/7-04 reg plot files.gpkg|layername=registrationtrialdatarows | G171: 4464.7419 | H171: 39331353 | I171: 4464.7419 | J171: 39331353 | K171: 0.084514658 | L171: 0.009188135 | M171: -0.024470962 | N171: 0.0010740852 | O171: 0.29944813 | P171: 0.026731796 | Q171: 0.15578864 | R171: 0.13151854 | S171: 0.91299781 | T171: 0.079432807 | U171: 78
A172: 171 | B172: 805 | C172: Registration | D172: 10 | E172: Registration Plots | F172: D:/Drone Imagery/2025 summer/20250704/shapefiles/7-04 reg plot files.gpkg|layername=registrationtrialdatarows | G172: 3750.2561 | H172: 39252674 | I172: 3750.2561 | J172: 39252674 | K172: 0.079395428 | L172: 0.007503804 | M172: -0.020915213 | N172: 0.00087326868 | O172: 0.28429707 | P172: 0.02257632 | Q172: 0.12089382 | R172: 0.1062785 | S172: 0.89260254 | T172: 0.095863242 | U172: 93
A173: 172 | B173: 806 | C173: Registration | D173: 10 | E173: Registration Plots | F173: D:/Drone Imagery/2025 summer/20250704/shapefiles/7-04 reg plot files.gpkg|layername=registrationtrialdatarows | G173: 3693.7542 | H173: 61294953 | I173: 3693.7542 | J173: 61294953 | K173: 0.082331305 | L173: 0.0057375382 | M173: -0.022710917 | N173: 0.00079588634 | O173: 0.28732417 | P173: 0.021795455 | Q173: 0.12433461 | R173: 0.10887552 | S173: 0.96063348 | T173: 0.037816793 | U173: 105
A174: 173 | B174: 807 | C174: Registration | D174: 10 | E174: Registration Plots | F174: D:/Drone Imagery/2025 summer/20250704/shapefiles/7-04 reg plot files.gpkg|layername=registrationtrialdatarows | G174: 3993.611 | H174: 62678483 | I174: 3993.611 | J174: 62678483 | K174: 0.083888806 | L174: 0.00692092 | M174: -0.028549625 | N174: 0.00084967126 | O174: 0.2965938 | P174: 0.024210219 | Q174: 0.14462062 | R174: 0.1237055 | S174: 0.97125327 | T174: 0.02792036 | U174: 128
A175: 174 | B175: 808 | C175: Registration | D175: 10 | E175: Registration Plots | F175: D:/Drone Imagery/2025 summer/20250704/shapefiles/7-04 reg plot files.gpkg|layername=registrationtrialdatarows | G175: 3373.3973 | H175: 48952724 | I175: 3373.3973 | J175: 48952724 | K175: 0.078327881 | L175: 0.0059330422 | M175: -0.031721948 | N175: 0.00063711065 | O175: 0.28375594 | P175: 0.0199425 | Q175: 0.11622363 | R175: 0.1027157 | S175: 0.97405646 | T175: 0.025270471 | U175: 136
A176: 175 | B176: 809 | C176: Registration | D176: 10 | E176: Registration Plots | F176: D:/Drone Imagery/2025 summer/20250704/shapefiles/7-04 reg plot files.gpkg|layername=registrationtrialdatarows | G176: 2647.9833 | H176: 40421431 | I176: 2647.9833 | J176: 40421431 | K176: 0.075741601 | L176: 0.0047782881 | M176: -0.030390978 | N176: 0.00099150394 | O176: 0.26941718 | P176: 0.015465341 | Q176: 0.083752915 | R176: 0.076738364 | S176: 0.94253217 | T176: 0.054165276 | U176: 111
A177: 176 | B177: 701 | C177: Registration | D177: 10 | E177: Registration Plots | F177: D:/Drone Imagery/2025 summer/20250704/shapefiles/7-04 reg plot files.gpkg|layername=registrationtrialdatarows | G177: 3840.9586 | H177: 36938638 | I177: 3840.9586 | J177: 36938638 | K177: 0.075398201 | L177: 0.0068575635 | M177: -0.031351003 | N177: 0.00064137255 | O177: 0.28161453 | P177: 0.020839948 | Q177: 0.11787151 | R177: 0.10397781 | S177: 0.9238563 | T177: 0.070345839 | U177: 98
A178: 177 | B178: 702 | C178: Registration | D178: 10 | E178: Registration Plots | F178: D:/Drone Imagery/2025 summer/20250704/shapefiles/7-04 reg plot files.gpkg|layername=registrationtrialdatarows | G178: 3720.9924 | H178: 37315762 | I178: 3720.9924 | J178: 37315762 | K178: 0.06494879 | L178: 0.0076113686 | M178: -0.032745561 | N178: 0.00067113546 | O178: 0.27061297 | P178: 0.022727529 | Q178: 0.11534779 | R178: 0.10204267 | S178: 0.95709393 | T178: 0.041065142 | U178: 120
A179: 178 | B179: 703 | C179: Registration | D179: 10 | E179: Registration Plots | F179: D:/Drone Imagery/2025 summer/20250704/shapefiles/7-04 reg plot files.gpkg|layername=registrationtrialdatarows | G179: 4188.3014 | H179: 36362179 | I179: 4188.3014 | J179: 36362179 | K179: 0.081973767 | L179: 0.009049742 | M179: -0.027821861 | N179: 0.00081591105 | O179: 0.28588972 | P179: 0.025084218 | Q179: 0.13943196 | R179: 0.11999069 | S179: 0.93182094 | T179: 0.063530672 | U179: 149
... A241: 240 | B241: 66666 | C241: Registration | D241: 10 | E241: Registration Plots | F241: D:/Drone Imagery/2025 summer/20250704/shapefiles/7-04 reg plot files.gpkg|layername=registrationtrialdatarows | G241: 2186.1341 | H241: 2759488.6 | I241: 2186.1341 | J241: 2759488.6 | K241: 0.01924764 | L241: 0.018175326 | M241: -0.029566713 | N241: 0.0051213258 | O241: 0.22658046 | P241: 0.010732822 | Q241: 0.0094998603 | R241: 0.009409613 | S241: 0 | T241: 0 | U241: 0

Sheet 710
A1: fid | B1: id | C1: Trial Name | D1: DAS | E1: layer | F1: path | G1: 710ExG_mean | H1: 710ExG_variance | I1: 710ExR_mean | J1: 710ExR_variance | K1: 710gNDVI_mean | L1: 710gNDVI_variance | M1: 710NDRE_mean | N1: 710NDRE_variance | O1: 710NDVI_mean | P1: 710NDVI_variance | Q1: 710THRESH_mean | R1: 710THRESH_variance | S1: 710HA_mean | T1: 710HA_variance | U1: 710PLTCOUNT_
A2: 1 | B2: 101 | C2: AYT Trial | D2: 16 | E2: 7-04 ayt plot files â€” ayttrialdata_rows_polygons__ayt_plots_dissolved | F2: D:/Drone Imagery/2025 summer/20250704/shapefiles/7-04 ayt plot files.gpkg|layername=ayttrialdata_rows_polygons__ayt_plots_dissolved | G2: 3973.4536 | H2: 31517480 | I2: 15158.061 | J2: 51530410 | K2: 0.080697938 | L2: 0.020720947 | M2: -0.034021859 | N2: 0.001557897 | O2: 0.28850773 | P2: 0.043256571 | Q2: 0.17821562 | R2: 0.14645481 | S2: 0.47725098 | T2: 0.24948248 | U2: 10
A3: 2 | B3: 102 | C3: AYT Trial | D3: 16 | E3: 7-04 ayt plot files â€” ayttrialdata_rows_polygons__ayt_plots_dissolved | F3: D:/Drone Imagery/2025 summer/20250704/shapefiles/7-04 ayt plot files.gpkg|layername=ayttrialdata_rows_polygons__ayt_plots_dissolved | G3: 5194.7756 | H3: 55726104 | I3: 14124.596 | J3: 52347950 | K3: 0.087687512 | L3: 0.017659488 | M3: -0.03414026 | N3: 0.001552583 | O3: 0.30060168 | P3: 0.044597697 | Q3: 0.19635999 | R3: 0.15780275 | S3: 0.61160079 | T3: 0.23754526 | U3: 19
A4: 3 | B4: 103 | C4: AYT Trial | D4: 16 | E4: 7-04 ayt plot files â€” ayttrialdata_rows_polygons__ayt_plots_dissolved | F4: D:/Drone Imagery/2025 summer/20250704/shapefiles/7-04 ayt plot files.gpkg|layername=ayttrialdata_rows_polygons__ayt_plots_dissolved | G4: 4781.1616 | H4: 57153275 | I4: 14509.178 | J4: 48521902 | K4: 0.086392257 | L4: 0.016102273 | M4: -0.030812049 | N4: 0.001289666 | O4: 0.29965418 | P4: 0.038945837 | Q4: 0.18097567 | R4: 0.14822348 | S4: 0.77498202 | T4: 0.17438489 | U4: 17
A5: 4 | B5: 104 | C5: AYT Trial | D5: 16 | E5: 7-04 ayt plot files â€” ayttrialdata_rows_polygons__ayt_plots_dissolved | F5: D:/Drone Imagery/2025 summer/20250704/shapefiles/7-04 ayt plot files.gpkg|layername=ayttrialdata_rows_polygons__ayt_plots_dissolved | G5: 6005.9342 | H5: 67626000 | I5: 13469.209 | J5: 57597314 | K5: 0.098846367 | L5: 0.021083473 | M5: -0.027137765 | N5: 0.001651845 | O5: 0.32370159 | P5: 0.049508987 | Q5: 0.22154848 | R5: 0.17246475 | S5: 0.60906392 | T5: 0.23810506 | U5: 17
A6: 5 | B6: 105 | C6: AYT Trial | D6: 16 | E6: 7-04 ayt plot files â€” ayttrialdata_rows_polygons__ayt_plots_dissolved | F6: D:/Drone Imagery/2025 summer/20250704/shapefiles/7-04 ayt plot files.gpkg|layername=ayttrialdata_rows_polygons__ayt_plots_dissolved | G6: 7195.9773 | H6: 77778040 | I6: 12543.351 | J6: 64671707 | K6: 0.12237219 | L6: 0.021643979 | M6: -0.022402257 | N6: 0.001799943 | O6: 0.35623286 | P6: 0.053162112 | Q6: 0.26098986 | R6: 0.19287415 | S6: 0.47889036 | T6: 0.24955438 | U6: 12
A7: 6 | B7: 106 | C7: AYT Trial | D7: 16 | E7: 7-04 ayt plot files â€” ayttrialdata_rows_polygons__ayt_plots_dissolved | F7: D:/Drone Imagery/2025 summer/20250704/shapefiles/7-04 ayt plot files.gpkg|layername=ayttrialdata_rows_polygons__ayt_plots_dissolved | G7: 4989.9607 | H7: 50263332 | I7: 14845.16 | J7: 39460211 | K7: 0.083096311 | L7: 0.012090263 | M7: -0.024722658 | N7: 0.001459909 | O7: 0.28888468 | P7: 0.031831091 | Q7: 0.15189718 | R7: 0.12882443 | S7: 0.87010084 | T7: 0.11302537 | U7: 27
A8: 7 | B8: 107 | C8: AYT Trial | D8: 16 | E8: 7-04 ayt plot files â€” ayttrialdata_rows_polygons__ayt_plots_dissolved | F8: D:/Drone Imagery/2025 summer/20250704/shapefiles/7-04 ayt plot files.gpkg|layername=ayttrialdata_rows_polygons__ayt_plots_dissolved | G8: 5356.6983 | H8: 56756327 | I8: 14485.063 | J8: 44346315 | K8: 0.10300642 | L8: 0.012912997 | M8: -0.019883959 | N8: 0.001332554 | O8: 0.31288252 | P8: 0.035284577 | Q8: 0.17388596 | R8: 0.14364963 | S8: 0.73421033 | T8: 0.19514552 | U8: 19
A9: 8 | B9: 108 | C9: AYT Trial | D9: 16 | E9: 7-04 ayt plot files â€” ayttrialdata_rows_polygons__ayt_plots_dissolved | F9: D:/Drone Imagery/2025 summer/20250704/shapefiles/7-04 ayt plot files.gpkg|layername=ayttrialdata_rows_polygons__ayt_plots_dissolved | G9: 6630.9143 | H9: 75775519 | I9: 13594.953 | J9: 54521050 | K9: 0.12768325 | L9: 0.016080316 | M9: -0.015621806 | N9: 0.001435242 | O9: 0.34650443 | P9: 0.043976121 | Q9: 0.22483165 | R9: 0.17428238 | S9: 0.6468562 | T9: 0.22843326 | U9: 18
A10: 9 | B10: 109 | C10: AYT Trial | D10: 16 | E10: 7-04 ayt plot files â€” ayttrialdata_rows_polygons__ayt_plots_dissolved | F10: D:/Drone Imagery/2025 summer/20250704/shapefiles/7-04 ayt plot files.gpkg|layername=ayttrialdata_rows_polygons__ayt_plots_dissolved | G10: 5071.6634 | H10: 45730767 | I10: 14922.833 | J10: 40702958 | K10: 0.10057642 | L10: 0.012553454 | M10: -0.019225876 | N10: 0.001303942 | O10: 0.29967027 | P10: 0.031199672 | Q10: 0.14015362 | R10: 0.12051059 | S10: 0.84582541 | T10: 0.13040479 | U10: 27
A11: 10 | B11: 110 | C11: AYT Trial | D11: 16 | E11: 7-04 ayt plot files â€” ayttrialdata_rows_polygons__ayt_plots_dissolved | F11: D:/Drone Imagery/2025 summer/20250704/shapefiles/7-04 ayt plot files.gpkg|layername=ayttrialdata_rows_polygons__ayt_plots_dissolved | G11: 7166.9697 | H11: 1.0051251e+08 | I11: 13413.673 | J11: 60958785 | K11: 0.12759955 | L11: 0.014278594 | M11: -0.01405992 | N11: 0.001642135 | O11: 0.35262482 | P11: 0.042668996 | Q11: 0.2246522 | R11: 0.17418359 | S11: 0.55090472 | T11: 0.24740871 | U11: 14
A12: 11 | B12: 201 | C12: AYT Trial | D12: 16 | E12: 7-04 ayt plot files â€” ayttrialdata_rows_polygons__ayt_plots_dissolved | F12: D:/Drone Imagery/2025 summer/20250704/shapefiles/7-04 ayt plot files.gpkg|layername=ayttrialdata_rows_polygons__ayt_plots_dissolved | G12: 3812.0437 | H12: 27750147 | I12: 15418.975 | J12: 41061830 | K12: 0.040059207 | L12: 0.019612766 | M12: -0.042160125 | N12: 0.001290504 | O12: 0.24284881 | P12: 0.040001234 | Q12: 0.15006806 | R12: 0.12754764 | S12: 0.77261647 | T12: 0.17568026 | U12: 23
A13: 12 | B13: 202 | C13: AYT Trial | D13: 16 | E13: 7-04 ayt plot files â€” ayttrialdata_rows_polygons__ayt_plots_dissolved | F13: D:/Drone Imagery/2025 summer/20250704/shapefiles/7-04 ayt plot files.gpkg|layername=ayttrialdata_rows_polygons__ayt_plots_dissolved | G13: 3211.3717 | H13: 27096508 | I13: 15039.561 | J13: 33994391 | K13: 0.03403022 | L13: 0.016757467 | M13: -0.042761552 | N13: 0.001293443 | O13: 0.2306097 | P13: 0.034587572 | Q13: 0.13105175 | R13: 0.11387719 | S13: 0.74017151 | T13: 0.19231765 | U13: 22
... A165: 164 | B165: 612 | C165: PYT Trial | D165: 16 | E165: PYT plots | F165: D:/Drone Imagery/2025 summer/20250704/shapefiles/7-04 reg plot polygons.gpkg|layername=pyt_trial_data_rows_polygons__pyt_trial_data_row_polygons | G165: 3901.2463 | H165: 23338693 | I165: 16448.532 | J165: 20276710 | K165: 0.040848031 | L165: 0.004719423 | M165: -0.03770129 | N165: 0.000993423 | O165: 0.21327535 | P165: 0.013164043 | Q165: 0.06072965 | R165: 0.057041559 | S165: 0.6401868 | T165: 0.23034766 | U165: 18
A166: 165 | C166: PYT Trial | D166: 16 | E166: PYT plots | F166: D:/Drone Imagery/2025 summer/20250704/shapefiles/7-04 reg plot polygons.gpkg|layername=pyt_trial_data_rows_polygons__pyt_trial_data_row_polygons | G166: 1981.7388 | H166: 504019.08 | I166: 15196.557 | J166: 8700602.2 | K166: 0.045657754 | L166: 0.002012884 | M166: -0.026180246 | N166: 0.000431829 | O166: 0.22263014 | P166: 0.001867641 | Q166: 0 | R166: 0 | S166: 0 | T166: 0 | U166: 0
A167: 166 | C167: PYT Trial | D167: 16 | E167: PYT plots | F167: D:/Drone Imagery/2025 summer/20250704/shapefiles/7-04 reg plot polygons.gpkg|layername=pyt_trial_data_rows_polygons__pyt_trial_data_row_polygons | G167: 311.94652 | H167: 4052354 | I167: 15557.242 | J167: 45746497 | K167: -0.0692731 | L167: 0.037568126 | M167: -0.038437369 | N167: 0.008569879 | O167: 0.16924347 | P167: 0.024653907 | Q167: 0.015706806 | R167: 0.015460103 | S167: 0 | T167: 0 | U167: 0
A168: 167 | B168: 801 | C168: Registration | D168: 16 | E168: Registration Plots | F168: D:/Drone Imagery/2025 summer/20250704/shapefiles/7-04 reg plot files.gpkg|layername=registrationtrialdatarows | G168: 4465.2482 | H168: 27702690 | I168: 14037.927 | J168: 43129387 | K168: 0.11590809 | L168: 0.016301149 | M168: -0.019621376 | N168: 0.001214148 | O168: 0.31925858 | P168: 0.035805957 | Q168: 0.17877219 | R168: 0.1468127 | S168: 0.85601005 | T168: 0.12325685 | U168: 33
A169: 168 | B169: 802 | C169: Registration | D169: 16 | E169: Registration Plots | F169: D:/Drone Imagery/2025 summer/20250704/shapefiles/7-04 reg plot files.gpkg|layername=registrationtrialdatarows | G169: 2956.3804 | H169: 13336673 | I169: 15841.543 | J169: 30469515 | K169: 0.077215371 | L169: 0.012592056 | M169: -0.027435262 | N169: 0.00108219 | O169: 0.26890472 | P169: 0.024581068 | Q169: 0.11766353 | R169: 0.10381882 | S169: 0.88382702 | T169: 0.10267682 | U169: 27
A170: 169 | B170: 803 | C170: Registration | D170: 16 | E170: Registration Plots | F170: D:/Drone Imagery/2025 summer/20250704/shapefiles/7-04 reg plot files.gpkg|layername=registrationtrialdatarows | G170: 5895.2179 | H170: 60944620 | I170: 14228.068 | J170: 52205984 | K170: 0.10124569 | L170: 0.015896541 | M170: -0.023853907 | N170: 0.001688582 | O170: 0.31983779 | P170: 0.042287103 | Q170: 0.20608701 | R170: 0.16361515 | S170: 0.41601517 | T170: 0.24294655 | U170: 11
A171: 170 | B171: 804 | C171: Registration | D171: 16 | E171: Registration Plots | F171: D:/Drone Imagery/2025 summer/20250704/shapefiles/7-04 reg plot files.gpkg|layername=registrationtrialdatarows | G171: 7754.3866 | H171: 70896947 | I171: 12469.718 | J171: 65485274 | K171: 0.14316 | L171: 0.020891089 | M171: -0.017216398 | N171: 0.001859069 | O171: 0.37796136 | P171: 0.053778931 | Q171: 0.30141916 | R171: 0.21056565 | S171: 0.74435059 | T171: 0.19029279 | U171: 26
A172: 171 | B172: 805 | C172: Registration | D172: 16 | E172: Registration Plots | F172: D:/Drone Imagery/2025 summer/20250704/shapefiles/7-04 reg plot files.gpkg|layername=registrationtrialdatarows | G172: 5421.455 | H172: 53540993 | I172: 14167.997 | J172: 48300047 | K172: 0.094088651 | L172: 0.015754049 | M172: -0.025627619 | N172: 0.001133869 | O172: 0.30134689 | P172: 0.041298962 | Q172: 0.181922 | R172: 0.14882639 | S172: 0.70323697 | T172: 0.20869473 | U172: 19
A173: 172 | B173: 806 | C173: Registration | D173: 16 | E173: Registration Plots | F173: D:/Drone Imagery/2025 summer/20250704/shapefiles/7-04 reg plot files.gpkg|layername=registrationtrialdatarows | G173: 6049.4435 | H173: 77517554 | I173: 13630.605 | J173: 50932054 | K173: 0.096515175 | L173: 0.015180116 | M173: -0.026255269 | N173: 0.001399527 | O173: 0.31016656 | P173: 0.04506383 | Q173: 0.19982662 | R173: 0.15989594 | S173: 0.46142688 | T173: 0.24851211 | U173: 14
A174: 173 | B174: 807 | C174: Registration | D174: 16 | E174: Registration Plots | F174: D:/Drone Imagery/2025 summer/20250704/shapefiles/7-04 reg plot files.gpkg|layername=registrationtrialdatarows | G174: 6492.347 | H174: 85673486 | I174: 13167.668 | J174: 58979791 | K174: 0.10154556 | L174: 0.016847927 | M174: -0.028115623 | N174: 0.001622862 | O174: 0.32461199 | P174: 0.050108203 | Q174: 0.23062136 | R174: 0.17743515 | S174: 0.50836462 | T174: 0.24993003 | U174: 19
A175: 174 | B175: 808 | C175: Registration | D175: 16 | E175: Registration Plots | F175: D:/Drone Imagery/2025 summer/20250704/shapefiles/7-04 reg plot files.gpkg|layername=registrationtrialdatarows | G175: 6100.838 | H175: 80315503 | I175: 13564.473 | J175: 55690812 | K175: 0.096799378 | L175: 0.016446849 | M175: -0.02793081 | N175: 0.002010103 | O175: 0.31278193 | P175: 0.044411045 | Q175: 0.21429772 | R175: 0.16837421 | S175: 0.78309859 | T175: 0.16985519 | U175: 28
A176: 175 | B176: 809 | C176: Registration | D176: 16 | E176: Registration Plots | F176: D:/Drone Imagery/2025 summer/20250704/shapefiles/7-04 reg plot files.gpkg|layername=registrationtrialdatarows | G176: 4499.9336 | H176: 60708266 | I176: 14352.451 | J176: 35682712 | K176: 0.081006438 | L176: 0.010044505 | M176: -0.024179005 | N176: 0.00158682 | O176: 0.27835214 | P176: 0.029827064 | Q176: 0.13913624 | R176: 0.11977735 | S176: 0.78486947 | T176: 0.16884939 | U176: 27
A177: 176 | B177: 701 | C177: Registration | D177: 16 | E177: Registration Plots | F177: D:/Drone Imagery/2025 summer/20250704/shapefiles/7-04 reg plot files.gpkg|layername=registrationtrialdatarows | G177: 5501.8333 | H177: 52191617 | I177: 13872.089 | J177: 44460921 | K177: 0.090826029 | L177: 0.016001018 | M177: -0.02825153 | N177: 0.001396649 | O177: 0.30014057 | P177: 0.042538647 | Q177: 0.19017338 | R177: 0.15400746 | S177: 0.76928332 | T177: 0.17748649 | U177: 28
A178: 177 | B178: 702 | C178: Registration | D178: 16 | E178: Registration Plots | F178: D:/Drone Imagery/2025 summer/20250704/shapefiles/7-04 reg plot files.gpkg|layername=registrationtrialdatarows | G178: 5431.7728 | H178: 46808640 | I178: 14448.443 | J178: 44815176 | K178: 0.07987678 | L178: 0.016332103 | M178: -0.02747121 | N178: 0.001409732 | O178: 0.28688717 | P178: 0.041580858 | Q178: 0.17852042 | R178: 0.14665088 | S178: 0.59568852 | T178: 0.24084371 | U178: 14
A179: 178 | B179: 703 | C179: Registration | D179: 16 | E179: Registration Plots | F179: D:/Drone Imagery/2025 summer/20250704/shapefiles/7-04 reg plot files.gpkg|layername=registrationtrialdatarows | G179: 7233.2539 | H179: 79754350 | I179: 12570.24 | J179: 61995009 | K179: 0.11657292 | L179: 0.019501451 | M179: -0.02027499 | N179: 0.002020203 | O179: 0.34572399 | P179: 0.052575293 | Q179: 0.26366414 | R179: 0.19414536 | S179: 0.65590234 | T179: 0.22569446 | U179: 21
... A241: 240 | B241: 66666 | C241: Registration | D241: 16 | E241: Registration Plots | F241: D:/Drone Imagery/2025 summer/20250704/shapefiles/7-04 reg plot files.gpkg|layername=registrationtrialdatarows | G241: 485.91671 | H241: 1636130.4 | I241: 15081.277 | J241: 55169251 | K241: -0.060341888 | L241: 0.033362045 | M241: -0.035900225 | N241: 0.01000958 | O241: 0.18159625 | P241: 0.01993072 | Q241: 0 | R241: 0 | S241: 0 | T241: 0 | U241: 0

Sheet 717
A1: fid | B1: id | C1: Trial Name | D1: DAS | E1: layer | F1: path | G1: 717ExG_mean | H1: 717ExG_variance | I1: 717ExR_mean | J1: 717ExR_variance | K1: 717gNDVI_mean | L1: 717gNDVI_variance | M1: 717gNDRE_mean | N1: 717gNDRE_variance | O1: 717THRESH_mean | P1: 717THRESH_variance | Q1: 717HA_mean | R1: 717HA_variance | S1: NUMPOINTS | T1: 717NDV_mean | U1: 717NDV_variance
A2: 1 | B2: 101 | C2: AYT Trial | D2: 23 | E2: 7-04 ayt plot files â€” ayttrialdata_rows_polygons__ayt_plots_dissolved | F2: D:/Drone Imagery/2025 summer/20250704/shapefiles/7-04 ayt plot files.gpkg|layername=ayttrialdata_rows_polygons__ayt_plots_dissolved | G2: 16744.397 | H2: 3.1162435e+08 | I2: 7226.3209 | J2: 1.037187e+08 | K2: 0.57557811 | L2: 0.0084626579 | M2: 0.15874787 | N2: 0.0019811588 | O2: 0.48158203 | P2: 0.24966078 | Q2: 0.63995072 | R2: 0.2304138 | S2: 42 | T2: 0.55285267 | U2: 0.052296972
A3: 2 | B3: 102 | C3: AYT Trial | D3: 23 | E3: 7-04 ayt plot files â€” ayttrialdata_rows_polygons__ayt_plots_dissolved | F3: D:/Drone Imagery/2025 summer/20250704/shapefiles/7-04 ayt plot files.gpkg|layername=ayttrialdata_rows_polygons__ayt_plots_dissolved | G3: 15932.695 | H3: 3.3409323e+08 | I3: 9268.6983 | J3: 79922752 | K3: 0.55808193 | L3: 0.0062948228 | M3: 0.15481794 | N3: 0.0022593594 | O3: 0.43882164 | P3: 0.24625721 | Q3: 0.58490814 | R3: 0.24279061 | S3: 48 | T3: 0.52049476 | U3: 0.046103953
A4: 3 | B4: 103 | C4: AYT Trial | D4: 23 | E4: 7-04 ayt plot files â€” ayttrialdata_rows_polygons__ayt_plots_dissolved | F4: D:/Drone Imagery/2025 summer/20250704/shapefiles/7-04 ayt plot files.gpkg|layername=ayttrialdata_rows_polygons__ayt_plots_dissolved | G4: 15157.851 | H4: 3.1102272e+08 | I4: 9502.2904 | J4: 76931432 | K4: 0.54786933 | L4: 0.0060968942 | M4: 0.15103167 | N4: 0.0018414185 | O4: 0.42559549 | P4: 0.24446397 | Q4: 0.72631215 | R4: 0.19878281 | S4: 39 | T4: 0.52063395 | U4: 0.042616688
A5: 4 | B5: 104 | C5: AYT Trial | D5: 23 | E5: 7-04 ayt plot files â€” ayttrialdata_rows_polygons__ayt_plots_dissolved | F5: D:/Drone Imagery/2025 summer/20250704/shapefiles/7-04 ayt plot files.gpkg|layername=ayttrialdata_rows_polygons__ayt_plots_dissolved | G5: 17782.229 | H5: 3.5006007e+08 | I5: 6710.8659 | J5: 96022093 | K5: 0.5617843 | L5: 0.0077906432 | M5: 0.15264188 | N5: 0.0020511069 | O5: 0.48967157 | P5: 0.24989332 | Q5: 0.62405289 | R5: 0.23461088 | S5: 42 | T5: 0.56552764 | U5: 0.045115307
A6: 5 | B6: 105 | C6: AYT Trial | D6: 23 | E6: 7-04 ayt plot files â€” ayttrialdata_rows_polygons__ayt_plots_dissolved | F6: D:/Drone Imagery/2025 summer/20250704/shapefiles/7-04 ayt plot files.gpkg|layername=ayttrialdata_rows_polygons__ayt_plots_dissolved | G6: 19579.708 | H6: 3.5584881e+08 | I6: 5503.0158 | J6: 86530477 | K6: 0.56958533 | L6: 0.0072342605 | M6: 0.16095841 | N6: 0.0028822875 | O6: 0.59612158 | P6: 0.24076064 | Q6: 0.83248999 | R6: 0.13945041 | S6: 64 | T6: 0.60592747 | U6: 0.041685315
A7: 6 | B7: 106 | C7: AYT Trial | D7: 23 | E7: 7-04 ayt plot files â€” ayttrialdata_rows_polygons__ayt_plots_dissolved | F7: D:/Drone Imagery/2025 summer/20250704/shapefiles/7-04 ayt plot files.gpkg|layername=ayttrialdata_rows_polygons__ayt_plots_dissolved | G7: 11590.345 | H7: 2.1293672e+08 | I7: 12414.68 | J7: 86918614 | K7: 0.51766085 | L7: 0.0083790317 | M7: 0.159976 | N7: 0.0034121105 | O7: 0.37699357 | P7: 0.23486942 | Q7: 0.65377636 | R7: 0.22635283 | S7: 21 | T7: 0.50895416 | U7: 0.040967786
A8: 7 | B8: 107 | C8: AYT Trial | D8: 23 | E8: 7-04 ayt plot files â€” ayttrialdata_rows_polygons__ayt_plots_dissolved | F8: D:/Drone Imagery/2025 summer/20250704/shapefiles/7-04 ayt plot files.gpkg|layername=ayttrialdata_rows_polygons__ayt_plots_dissolved | G8: 13818.956 | H8: 2.5030836e+08 | I8: 10241.243 | J8: 89143336 | K8: 0.54286712 | L8: 0.0090263649 | M8: 0.1676952 | N8: 0.0035886656 | O8: 0.46166577 | P8: 0.24853049 | Q8: 0.87693169 | R8: 0.1079225 | S8: 45 | T8: 0.55965308 | U8: 0.042908278
A9: 8 | B9: 108 | C9: AYT Trial | D9: 23 | E9: 7-04 ayt plot files â€” ayttrialdata_rows_polygons__ayt_plots_dissolved | F9: D:/Drone Imagery/2025 summer/20250704/shapefiles/7-04 ayt plot files.gpkg|layername=ayttrialdata_rows_polygons__ayt_plots_dissolved | G9: 17636.066 | H9: 3.0680477e+08 | I9: 7643.2382 | J9: 97081194 | K9: 0.55983754 | L9: 0.0083485285 | M9: 0.15997606 | N9: 0.0026767574 | O9: 0.53983423 | P9: 0.24841323 | Q9: 0.70954277 | R9: 0.20609183 | S9: 39 | T9: 0.5946809 | U9: 0.044793084
A10: 9 | B10: 109 | C10: AYT Trial | D10: 23 | E10: 7-04 ayt plot files â€” ayttrialdata_rows_polygons__ayt_plots_dissolved | F10: D:/Drone Imagery/2025 summer/20250704/shapefiles/7-04 ayt plot files.gpkg|layername=ayttrialdata_rows_polygons__ayt_plots_dissolved | G10: 13134.35 | H10: 2.7074591e+08 | I10: 10368.253 | J10: 91445075 | K10: 0.52073875 | L10: 0.0074444075 | M10: 0.14211081 | N10: 0.0016677729 | O10: 0.37055819 | P10: 0.23324482 | Q10: 0.66820552 | R10: 0.2217069 | S10: 37 | T10: 0.50060043 | U10: 0.042878447
A11: 10 | B11: 110 | C11: AYT Trial | D11: 23 | E11: 7-04 ayt plot files â€” ayttrialdata_rows_polygons__ayt_plots_dissolved | F11: D:/Drone Imagery/2025 summer/20250704/shapefiles/7-04 ayt plot files.gpkg|layername=ayttrialdata_rows_polygons__ayt_plots_dissolved | G11: 19188.03 | H11: 3.5595842e+08 | I11: 6057.8462 | J11: 90168817 | K11: 0.55838101 | L11: 0.0082002044 | M11: 0.15175706 | N11: 0.0021847088 | O11: 0.54982419 | P11: 0.24751755 | Q11: 0.6853008 | R11: 0.21566361 | S11: 46 | T11: 0.59194911 | U11: 0.046263452
A12: 11 | B12: 201 | C12: AYT Trial | D12: 23 | E12: 7-04 ayt plot files â€” ayttrialdata_rows_polygons__ayt_plots_dissolved | F12: D:/Drone Imagery/2025 summer/20250704/shapefiles/7-04 ayt plot files.gpkg|layername=ayttrialdata_rows_polygons__ayt_plots_dissolved | G12: 14635.739 | H12: 2.7724212e+08 | I12: 8948.8947 | J12: 93610534 | K12: 0.54785545 | L12: 0.0091444039 | M12: 0.1529389 | N12: 0.0016569407 | O12: 0.42363854 | P12: 0.24416893 | Q12: 0.27001401 | R12: 0.19710645 | S12: 7 | T12: 0.51741468 | U12: 0.049457144
A13: 12 | B13: 202 | C13: AYT Trial | D13: 23 | E13: 7-04 ayt plot files â€” ayttrialdata_rows_polygons__ayt_plots_dissolved | F13: D:/Drone Imagery/2025 summer/20250704/shapefiles/7-04 ayt plot files.gpkg|layername=ayttrialdata_rows_polygons__ayt_plots_dissolved | G13: 11139.984 | H13: 1.9108459e+08 | I13: 10402.672 | J13: 90101807 | K13: 0.54823182 | L13: 0.010877284 | M13: 0.16122491 | N13: 0.0015451523 | O13: 0.36715583 | P13: 0.23235243 | Q13: 0.57117057 | R13: 0.24493475 | S13: 31 | T13: 0.49253289 | U13: 0.046827156
... A165: 164 | B165: 612 | C165: PYT Trial | D165: 23 | E165: PYT plots | F165: D:/Drone Imagery/2025 summer/20250704/shapefiles/7-04 reg plot polygons.gpkg|layername=pyt_trial_data_rows_polygons__pyt_trial_data_row_polygons | G165: 4451.2114 | H165: 98097635 | I165: 15270.892 | J165: 38112391 | K165: 0.50864773 | L165: 0.0035968127 | M165: 0.14086731 | N165: 0.0015309656 | O165: 0.13052247 | P165: 0.11348636 | Q165: 0.82336134 | R165: 0.14543744 | S165: 68 | T165: 0.39525042 | U165: 0.016120519
A166: 165 | C166: PYT Trial | D166: 23 | E166: PYT plots | F166: D:/Drone Imagery/2025 summer/20250704/shapefiles/7-04 reg plot polygons.gpkg|layername=pyt_trial_data_rows_polygons__pyt_trial_data_row_polygons | G166: 1494.4664 | H166: 1690126.9 | I166: 12902.674 | J166: 14572177 | K166: 0.44224063 | L166: 0.0020853729 | M166: 0.1298049 | N166: 0.00068399827 | O166: 0.014693878 | P166: 0.014477968 | Q166: 0 | R166: 0 | S166: 0 | T166: 0.33084611 | U166: 0.0028065783
A167: 166 | C167: PYT Trial | D167: 23 | E167: PYT plots | F167: D:/Drone Imagery/2025 summer/20250704/shapefiles/7-04 reg plot polygons.gpkg|layername=pyt_trial_data_rows_polygons__pyt_trial_data_row_polygons | G167: 1229.1814 | H167: 5614367 | I167: 15372.71 | J167: 51026588 | K167: 0.35086735 | L167: 0.026247519 | M167: 0.11071617 | N167: 0.004392619 | O167: 0.07257384 | P167: 0.067306877 | Q167: 0 | R167: 0 | S167: 0 | T167: 0.27105727 | U167: 0.032028407
A168: 167 | B168: 801 | C168: Registration | D168: 23 | E168: Registration Plots | F168: D:/Drone Imagery/2025 summer/20250704/shapefiles/7-04 reg plot files.gpkg|layername=registrationtrialdatarows | G168: 16497.569 | H168: 2.6365578e+08 | I168: 5737.9147 | J168: 1.0271275e+08 | K168: 0.57322859 | L168: 0.0091469477 | M168: 0.15129985 | N168: 0.0014982815 | O168: 0.49701021 | P168: 0.24999106 | Q168: 0.46212909 | R168: 0.24856579 | S168: 16 | T168: 0.56071192 | U168: 0.048321409
A169: 168 | B169: 802 | C169: Registration | D169: 23 | E169: Registration Plots | F169: D:/Drone Imagery/2025 summer/20250704/shapefiles/7-04 reg plot files.gpkg|layername=registrationtrialdatarows | G169: 11486.293 | H169: 1.8966664e+08 | I169: 10008.805 | J169: 79976204 | K169: 0.52513862 | L169: 0.0094918267 | M169: 0.13496506 | N169: 0.0015393196 | O169: 0.34161371 | P169: 0.22491378 | Q169: 0.36758865 | R169: 0.23246723 | S169: 11 | T169: 0.48473833 | U169: 0.043754451
A170: 169 | B170: 803 | C170: Registration | D170: 23 | E170: Registration Plots | F170: D:/Drone Imagery/2025 summer/20250704/shapefiles/7-04 reg plot files.gpkg|layername=registrationtrialdatarows | G170: 19711.587 | H170: 3.253956e+08 | I170: 5630.4223 | J170: 92034635 | K170: 0.55169481 | L170: 0.0096730635 | M170: 0.12639985 | N170: 0.0021923586 | O170: 0.54021228 | P170: 0.24838297 | Q170: 0.63561424 | R170: 0.23160878 | S170: 34 | T170: 0.59262028 | U170: 0.048336931
A171: 170 | B171: 804 | C171: Registration | D171: 23 | E171: Registration Plots | F171: D:/Drone Imagery/2025 summer/20250704/shapefiles/7-04 reg plot files.gpkg|layername=registrationtrialdatarows | G171: 26241.75 | H171: 2.910153e+08 | I171: 2346.4176 | J171: 99339396 | K171: 0.60266422 | L171: 0.0086978176 | M171: 0.12634844 | N171: 0.0041633993 | O171: 0.78713969 | P171: 0.1675508 | Q171: 0.62613427 | R171: 0.23409014 | S171: 23 | T171: 0.71299341 | U171: 0.035952057
A172: 171 | B172: 805 | C172: Registration | D172: 23 | E172: Registration Plots | F172: D:/Drone Imagery/2025 summer/20250704/shapefiles/7-04 reg plot files.gpkg|layername=registrationtrialdatarows | G172: 17057.403 | H172: 3.0056959e+08 | I172: 7832.6103 | J172: 97804015 | K172: 0.5548445 | L172: 0.0087425461 | M172: 0.13059922 | N172: 0.0030999121 | O172: 0.52853041 | P172: 0.24918602 | Q172: 0.86357055 | R172: 0.11781645 | S172: 72 | T172: 0.58682125 | U172: 0.044993739
A173: 172 | B173: 806 | C173: Registration | D173: 23 | E173: Registration Plots | F173: D:/Drone Imagery/2025 summer/20250704/shapefiles/7-04 reg plot files.gpkg|layername=registrationtrialdatarows | G173: 15179.354 | H173: 2.9673208e+08 | I173: 9786.81 | J173: 99140601 | K173: 0.52537441 | L173: 0.0092185563 | M173: 0.13117874 | N173: 0.001945805 | O173: 0.44102851 | P173: 0.24652236 | Q173: 0.79433058 | R173: 0.16336951 | S173: 53 | T173: 0.52407464 | U173: 0.050099964
A174: 173 | B174: 807 | C174: Registration | D174: 23 | E174: Registration Plots | F174: D:/Drone Imagery/2025 summer/20250704/shapefiles/7-04 reg plot files.gpkg|layername=registrationtrialdatarows | G174: 19725.721 | H174: 3.5944433e+08 | I174: 6561.0172 | J174: 1.0271802e+08 | K174: 0.55300297 | L174: 0.008352187 | M174: 0.13971168 | N174: 0.0020368183 | O174: 0.54126523 | P174: 0.24829718 | Q174: 0.55649385 | R174: 0.24680845 | S174: 27 | T174: 0.58468347 | U174: 0.052373945
A175: 174 | B175: 808 | C175: Registration | D175: 23 | E175: Registration Plots | F175: D:/Drone Imagery/2025 summer/20250704/shapefiles/7-04 reg plot files.gpkg|layername=registrationtrialdatarows | G175: 20324.906 | H175: 3.3525222e+08 | I175: 5976.4848 | J175: 93007150 | K175: 0.56212349 | L175: 0.0075742883 | M175: 0.12745696 | N175: 0.0043218735 | O175: 0.61189034 | P175: 0.23748055 | Q175: 0.73258936 | R175: 0.19590219 | S175: 47 | T175: 0.60778579 | U175: 0.045193735
A176: 175 | B176: 809 | C176: Registration | D176: 23 | E176: Registration Plots | F176: D:/Drone Imagery/2025 summer/20250704/shapefiles/7-04 reg plot files.gpkg|layername=registrationtrialdatarows | G176: 12753.047 | H176: 2.8261458e+08 | I176: 10269.384 | J176: 90883643 | K176: 0.5280587 | L176: 0.0070191057 | M176: 0.11707359 | N176: 0.0033917756 | O176: 0.39749324 | P176: 0.23949236 | Q176: 0.90600744 | R176: 0.085157959 | S176: 98 | T176: 0.5110832 | U176: 0.041479981
A177: 176 | B177: 701 | C177: Registration | D177: 23 | E177: Registration Plots | F177: D:/Drone Imagery/2025 summer/20250704/shapefiles/7-04 reg plot files.gpkg|layername=registrationtrialdatarows | G177: 17067.805 | H177: 2.9602438e+08 | I177: 7455.7957 | J177: 91796647 | K177: 0.54498016 | L177: 0.0082794104 | M177: 0.13606735 | N177: 0.0017660807 | O177: 0.46651627 | P177: 0.24887884 | Q177: 0.40349068 | R177: 0.24068595 | S177: 17 | T177: 0.53503317 | U177: 0.047343457
A178: 177 | B178: 702 | C178: Registration | D178: 23 | E178: Registration Plots | F178: D:/Drone Imagery/2025 summer/20250704/shapefiles/7-04 reg plot files.gpkg|layername=registrationtrialdatarows | G178: 14941.696 | H178: 2.703175e+08 | I178: 8921.3837 | J178: 81661193 | K178: 0.52859045 | L178: 0.0082933633 | M178: 0.13555542 | N178: 0.0017827914 | O178: 0.41151485 | P178: 0.24217038 | Q178: 0.47169024 | R178: 0.24919856 | S178: 19 | T178: 0.51834418 | U178: 0.044851339
A179: 178 | B179: 703 | C179: Registration | D179: 23 | E179: Registration Plots | F179: D:/Drone Imagery/2025 summer/20250704/shapefiles/7-04 reg plot files.gpkg|layername=registrationtrialdatarows | G179: 25261.933 | H179: 3.1024392e+08 | I179: 2209.2207 | J179: 85428672 | K179: 0.59255938 | L179: 0.0087418168 | M179: 0.14233195 | N179: 0.0027616894 | O179: 0.74312774 | P179: 0.1908889 | Q179: 0.54312462 | R179: 0.24814027 | S179: 53 | T179: 0.67953406 | U179: 0.039101195
... A241: 240 | B241: 66666 | C241: Registration | D241: 23 | E241: Registration Plots | F241: D:/Drone Imagery/2025 summer/20250704/shapefiles/7-04 reg plot files.gpkg|layername=registrationtrialdatarows | G241: 277.5779 | H241: 2627612.1 | I241: 16652.961 | J241: 41653264 | K241: 0.27680381 | L241: 0.029614312 | M241: 0.078895963 | N241: 0.0073920702 | O241: 0 | P241: 0 | Q241: 0 | R241: 0 | S241: 0 | T241: 0.18578406 | U241: 0.018751956

Sheet 724
A1: fid | B1: id | C1: Trial Name | D1: DAS | E1: layer | F1: path | G1: 724ExG_mean | H1: 724ExG_variance | I1: 724ExR_mean | J1: 724ExR_variance | K1: 724gNDVI_mean | L1: 724gNDVI_variance | M1: 724NDRE_mean | N1: 724NDRE_variance | O1: 724THRESH_mean | P1: 724THRESH_variance | Q1: 724HA_mean | R1: 724HA_variance | S1: NDVI_mean | T1: NDVI_variance | U1: 724PLT_
A2: 1 | B2: 101 | C2: AYT Trial | D2: 30 | E2: 7-04 ayt plot files â€” ayttrialdata_rows_polygons__ayt_plots_dissolved | F2: D:/Drone Imagery/2025 summer/20250704/shapefiles/7-04 ayt plot files.gpkg|layername=ayttrialdata_rows_polygons__ayt_plots_dissolved | G2: 14080.103 | H2: 1.5534008e+08 | I2: 6695.8811 | J2: 82268525 | K2: 0.1745339 | L2: 0.030927931 | M2: -0.029440246 | N2: 0.0018020866 | O2: 0.47798735 | P2: 0.24951544 | Q2: 0.86159016 | R2: 0.11925255 | S2: 0.44310312 | T2: 0.081810312 | U2: 44
A3: 2 | B3: 102 | C3: AYT Trial | D3: 30 | E3: 7-04 ayt plot files â€” ayttrialdata_rows_polygons__ayt_plots_dissolved | F3: D:/Drone Imagery/2025 summer/20250704/shapefiles/7-04 ayt plot files.gpkg|layername=ayttrialdata_rows_polygons__ayt_plots_dissolved | G3: 12007.077 | H3: 1.6816989e+08 | I3: 9752.5858 | J3: 86762604 | K3: 0.11942094 | L3: 0.031363638 | M3: -0.035491387 | N3: 0.0018796154 | O3: 0.3936571 | P3: 0.23869119 | Q3: 0.76461794 | R3: 0.17997734 | S3: 0.36848115 | T3: 0.085904598 | U3: 25
A4: 3 | B4: 103 | C4: AYT Trial | D4: 30 | E4: 7-04 ayt plot files â€” ayttrialdata_rows_polygons__ayt_plots_dissolved | F4: D:/Drone Imagery/2025 summer/20250704/shapefiles/7-04 ayt plot files.gpkg|layername=ayttrialdata_rows_polygons__ayt_plots_dissolved | G4: 13362.195 | H4: 1.9195344e+08 | I4: 8844.4778 | J4: 87585169 | K4: 0.13114313 | L4: 0.026129458 | M4: -0.031232623 | N4: 0.0017442197 | O4: 0.42215768 | P4: 0.24394057 | Q4: 0.70976574 | R4: 0.20599833 | S4: 0.39429276 | T4: 0.079617255 | U4: 20
A5: 4 | B5: 104 | C5: AYT Trial | D5: 30 | E5: 7-04 ayt plot files â€” ayttrialdata_rows_polygons__ayt_plots_dissolved | F5: D:/Drone Imagery/2025 summer/20250704/shapefiles/7-04 ayt plot files.gpkg|layername=ayttrialdata_rows_polygons__ayt_plots_dissolved | G5: 14377.542 | H5: 1.8271338e+08 | I5: 7378.1391 | J5: 86929542 | K5: 0.15197531 | L5: 0.033008439 | M5: -0.030325308 | N5: 0.0019858163 | O5: 0.47314436 | P5: 0.24927877 | Q5: 0.55731039 | R5: 0.24671552 | S5: 0.41810693 | T5: 0.091385641 | U5: 19
A6: 5 | B6: 105 | C6: AYT Trial | D6: 30 | E6: 7-04 ayt plot files â€” ayttrialdata_rows_polygons__ayt_plots_dissolved | F6: D:/Drone Imagery/2025 summer/20250704/shapefiles/7-04 ayt plot files.gpkg|layername=ayttrialdata_rows_polygons__ayt_plots_dissolved | G6: 16661.516 | H6: 2.0679204e+08 | I6: 5826.0036 | J6: 67051797 | K6: 0.16961777 | L6: 0.022596746 | M6: -0.027468448 | N6: 0.0018938438 | O6: 0.51817846 | P6: 0.24966954 | Q6: 0.58465339 | R6: 0.2428338 | S6: 0.45436807 | T6: 0.072561083 | U6: 18
A7: 6 | B7: 106 | C7: AYT Trial | D7: 30 | E7: 7-04 ayt plot files â€” ayttrialdata_rows_polygons__ayt_plots_dissolved | F7: D:/Drone Imagery/2025 summer/20250704/shapefiles/7-04 ayt plot files.gpkg|layername=ayttrialdata_rows_polygons__ayt_plots_dissolved | G7: 14035.735 | H7: 1.7241292e+08 | I7: 7351.2893 | J7: 88068191 | K7: 0.15845704 | L7: 0.02936476 | M7: -0.028403258 | N7: 0.0018835683 | O7: 0.45248113 | P7: 0.24774196 | Q7: 0.66691651 | R7: 0.22213888 | S7: 0.41647561 | T7: 0.083012959 | U7: 24
A8: 7 | B8: 107 | C8: AYT Trial | D8: 30 | E8: 7-04 ayt plot files â€” ayttrialdata_rows_polygons__ayt_plots_dissolved | F8: D:/Drone Imagery/2025 summer/20250704/shapefiles/7-04 ayt plot files.gpkg|layername=ayttrialdata_rows_polygons__ayt_plots_dissolved | G8: 16154.726 | H8: 1.7329647e+08 | I8: 5173.7748 | J8: 75805266 | K8: 0.21094569 | L8: 0.027805847 | M8: -0.013740553 | N8: 0.0019364838 | O8: 0.5374095 | P8: 0.24860053 | Q8: 0.82586689 | R8: 0.14381077 | S8: 0.49100318 | T8: 0.074196925 | U8: 41
A9: 8 | B9: 108 | C9: AYT Trial | D9: 30 | E9: 7-04 ayt plot files â€” ayttrialdata_rows_polygons__ayt_plots_dissolved | F9: D:/Drone Imagery/2025 summer/20250704/shapefiles/7-04 ayt plot files.gpkg|layername=ayttrialdata_rows_polygons__ayt_plots_dissolved | G9: 17553.464 | H9: 1.8288839e+08 | I9: 4706.4171 | J9: 80935379 | K9: 0.23225531 | L9: 0.028099424 | M9: -0.0090537772 | N9: 0.0018859383 | O9: 0.57974238 | P9: 0.24364115 | Q9: 0.5192724 | R9: 0.24962857 | S9: 0.52622038 | T9: 0.073420659 | U9: 23
A10: 9 | B10: 109 | C10: AYT Trial | D10: 30 | E10: 7-04 ayt plot files â€” ayttrialdata_rows_polygons__ayt_plots_dissolved | F10: D:/Drone Imagery/2025 summer/20250704/shapefiles/7-04 ayt plot files.gpkg|layername=ayttrialdata_rows_polygons__ayt_plots_dissolved | G10: 11069.675 | H10: 1.4931482e+08 | I10: 10227.594 | J10: 84015118 | K10: 0.13729395 | L10: 0.029669974 | M10: -0.030998123 | N10: 0.0020150959 | O10: 0.34966691 | P10: 0.22739996 | Q10: 0.69508695 | R10: 0.21194108 | S10: 0.37298298 | T10: 0.076103088 | U10: 40
A11: 10 | B11: 110 | C11: AYT Trial | D11: 30 | E11: 7-04 ayt plot files â€” ayttrialdata_rows_polygons__ayt_plots_dissolved | F11: D:/Drone Imagery/2025 summer/20250704/shapefiles/7-04 ayt plot files.gpkg|layername=ayttrialdata_rows_polygons__ayt_plots_dissolved | G11: 13931.951 | H11: 1.7932585e+08 | I11: 6036.5226 | J11: 72783309 | K11: 0.20845066 | L11: 0.025970352 | M11: -0.0087464002 | N11: 0.0020354989 | O11: 0.47515339 | P11: 0.24938265 | Q11: 0.32442712 | R11: 0.21917416 | S11: 0.46937636 | T11: 0.07234843 | U11: 11
A12: 11 | B12: 201 | C12: AYT Trial | D12: 30 | E12: 7-04 ayt plot files â€” ayttrialdata_rows_polygons__ayt_plots_dissolved | F12: D:/Drone Imagery/2025 summer/20250704/shapefiles/7-04 ayt plot files.gpkg|layername=ayttrialdata_rows_polygons__ayt_plots_dissolved | G12: 13045.239 | H12: 1.5673003e+08 | I12: 8103.0248 | J12: 85041319 | K12: 0.11214859 | L12: 0.032876629 | M12: -0.045431572 | N12: 0.0015220109 | O12: 0.42544581 | P12: 0.24444167 | Q12: 0.84863626 | R12: 0.12845276 | S12: 0.36628876 | T12: 0.091638626 | U12: 53
A13: 12 | B13: 202 | C13: AYT Trial | D13: 30 | E13: 7-04 ayt plot files â€” ayttrialdata_rows_polygons__ayt_plots_dissolved | F13: D:/Drone Imagery/2025 summer/20250704/shapefiles/7-04 ayt plot files.gpkg|layername=ayttrialdata_rows_polygons__ayt_plots_dissolved | G13: 9089.4046 | H13: 96909414 | I13: 9611.2097 | J13: 86203122 | K13: 0.10391809 | L13: 0.044775902 | M13: -0.034928896 | N13: 0.0021538457 | O13: 0.37218953 | P13: 0.23366448 | Q13: 0.73887201 | R13: 0.19294016 | S13: 0.31875177 | T13: 0.10253084 | U13: 38
... A165: 164 | B165: 612 | C165: PYT Trial | D165: 30 | E165: PYT plots | F165: D:/Drone Imagery/2025 summer/20250704/shapefiles/7-04 reg plot polygons.gpkg|layername=pyt_trial_data_rows_polygons__pyt_trial_data_row_polygons | G165: 4602.5079 | H165: 73736096 | I165: 14690.441 | J165: 46283629 | K165: 0.025808796 | L165: 0.012728684 | M165: -0.051473824 | N165: 0.0010469088 | O165: 0.13270267 | P165: 0.11509267 | Q165: 0.62857897 | R165: 0.23346745 | S165: 0.19167654 | T165: 0.040880058 | U165: 33
A166: 165 | C166: PYT Trial | D166: 30 | E166: PYT plots | F166: D:/Drone Imagery/2025 summer/20250704/shapefiles/7-04 reg plot polygons.gpkg|layername=pyt_trial_data_rows_polygons__pyt_trial_data_row_polygons | G166: 3881.7003 | H166: 31314102 | I166: 16203.77 | J166: 23112671 | K166: -0.065753607 | L166: 0.0069135681 | M166: -0.08864252 | N166: 0.00078452857 | O166: 0.049224912 | P166: 0.04680182 | Q166: 0 | R166: 0 | S166: 0.093870436 | T166: 0.022612022 | U166: 0
A167: 166 | C167: PYT Trial | D167: 30 | E167: PYT plots | F167: D:/Drone Imagery/2025 summer/20250704/shapefiles/7-04 reg plot polygons.gpkg|layername=pyt_trial_data_rows_polygons__pyt_trial_data_row_polygons | G167: 794.45385 | H167: 4321586.5 | I167: 12410.023 | J167: 39164801 | K167: -0.053895288 | L167: 0.044763796 | M167: -0.043945139 | N167: 0.0086922288 | O167: 0.059088351 | P167: 0.055596918 | Q167: 0 | R167: 0 | S167: 0.19451876 | T167: 0.035055638 | U167: 0
A168: 167 | B168: 801 | C168: Registration | D168: 30 | E168: Registration Plots | F168: D:/Drone Imagery/2025 summer/20250704/shapefiles/7-04 reg plot files.gpkg|layername=registrationtrialdatarows | G168: 12533.333 | H168: 1.0899488e+08 | I168: 5773.4544 | J168: 81127696 | K168: 0.21980647 | L168: 0.034933533 | M168: -0.015522853 | N168: 0.0017571425 | O168: 0.49965914 | P168: 0.24999988 | Q168: 0.4453082 | R168: 0.24700881 | S168: 0.46911109 | T168: 0.083978925 | U168: 14
A169: 168 | B169: 802 | C169: Registration | D169: 30 | E169: Registration Plots | F169: D:/Drone Imagery/2025 summer/20250704/shapefiles/7-04 reg plot files.gpkg|layername=registrationtrialdatarows | G169: 11538.902 | H169: 1.3291553e+08 | I169: 9232.8006 | J169: 95187062 | K169: 0.1478833 | L169: 0.033632619 | M169: -0.033641363 | N169: 0.0016361972 | O169: 0.38872239 | P169: 0.23761729 | Q169: 0.61183126 | R169: 0.23749377 | S169: 0.38045289 | T169: 0.0880804 | U169: 17
A170: 169 | B170: 803 | C170: Registration | D170: 30 | E170: Registration Plots | F170: D:/Drone Imagery/2025 summer/20250704/shapefiles/7-04 reg plot files.gpkg|layername=registrationtrialdatarows | G170: 18950.725 | H170: 1.9594667e+08 | I170: 3799.7781 | J170: 78300630 | K170: 0.22024475 | L170: 0.025066107 | M170: -0.012842817 | N170: 0.0018279776 | O170: 0.5882167 | P170: 0.24221781 | Q170: 0.63736718 | R170: 0.23113026 | S170: 0.51743847 | T170: 0.071545221 | U170: 24
A171: 170 | B171: 804 | C171: Registration | D171: 30 | E171: Registration Plots | F171: D:/Drone Imagery/2025 summer/20250704/shapefiles/7-04 reg plot files.gpkg|layername=registrationtrialdatarows | G171: 21384.165 | H171: 1.4940787e+08 | I171: 2165.8649 | J171: 59124450 | K171: 0.24558086 | L171: 0.021930643 | M171: -0.015419614 | N171: 0.001845769 | O171: 0.73431368 | P171: 0.1950971 | Q171: 0.91938496 | R171: 0.074116258 | S171: 0.57531858 | T171: 0.059146013 | U171: 63
A172: 171 | B172: 805 | C172: Registration | D172: 30 | E172: Registration Plots | F172: D:/Drone Imagery/2025 summer/20250704/shapefiles/7-04 reg plot files.gpkg|layername=registrationtrialdatarows | G172: 16433.658 | H172: 1.8250612e+08 | I172: 5155.0158 | J172: 84245012 | K172: 0.18031593 | L172: 0.030085057 | M172: -0.017948837 | N172: 0.0019170746 | O172: 0.53508062 | P172: 0.24876935 | Q172: 0.52249301 | R172: 0.24949406 | S172: 0.45469509 | T172: 0.085313519 | U172: 11
A173: 172 | B173: 806 | C173: Registration | D173: 30 | E173: Registration Plots | F173: D:/Drone Imagery/2025 summer/20250704/shapefiles/7-04 reg plot files.gpkg|layername=registrationtrialdatarows | G173: 13771.146 | H173: 1.9344834e+08 | I173: 7987.3574 | J173: 76587759 | K173: 0.10044991 | L173: 0.025620663 | M173: -0.04019354 | N173: 0.0016229581 | O173: 0.39852015 | P173: 0.23970184 | Q173: 0.67382625 | R173: 0.21978443 | S173: 0.35295408 | T173: 0.085120618 | U173: 21
A174: 173 | B174: 807 | C174: Registration | D174: 30 | E174: Registration Plots | F174: D:/Drone Imagery/2025 summer/20250704/shapefiles/7-04 reg plot files.gpkg|layername=registrationtrialdatarows | G174: 18847.241 | H174: 1.8996978e+08 | I174: 3518.0895 | J174: 77715205 | K174: 0.20476579 | L174: 0.030653553 | M174: -0.02259398 | N174: 0.0022192588 | O174: 0.6111867 | P174: 0.23763752 | Q174: 0.72682429 | R174: 0.19855074 | S174: 0.50820305 | T174: 0.080569706 | U174: 32
A175: 174 | B175: 808 | C175: Registration | D175: 30 | E175: Registration Plots | F175: D:/Drone Imagery/2025 summer/20250704/shapefiles/7-04 reg plot files.gpkg|layername=registrationtrialdatarows | G175: 16486.998 | H175: 1.7598477e+08 | I175: 5815.654 | J175: 72311029 | K175: 0.16898214 | L175: 0.027953768 | M175: -0.032351608 | N175: 0.0021047508 | O175: 0.54610569 | P175: 0.24787426 | Q175: 0.83111411 | R175: 0.14036345 | S175: 0.45900863 | T175: 0.078625351 | U175: 44
A176: 175 | B176: 809 | C176: Registration | D176: 30 | E176: Registration Plots | F176: D:/Drone Imagery/2025 summer/20250704/shapefiles/7-04 reg plot files.gpkg|layername=registrationtrialdatarows | G176: 11971.443 | H176: 1.8553474e+08 | I176: 7916.9461 | J176: 66507565 | K176: 0.11190979 | L176: 0.02379366 | M176: -0.038072897 | N176: 0.0015527415 | O176: 0.36682612 | P176: 0.23226472 | Q176: 0.82447706 | R176: 0.14471464 | S176: 0.34611197 | T176: 0.079950023 | U176: 32
A177: 176 | B177: 701 | C177: Registration | D177: 30 | E177: Registration Plots | F177: D:/Drone Imagery/2025 summer/20250704/shapefiles/7-04 reg plot files.gpkg|layername=registrationtrialdatarows | G177: 14081.571 | H177: 1.7422527e+08 | I177: 7557.4761 | J177: 77556147 | K177: 0.12618609 | L177: 0.027416521 | M177: -0.046610695 | N177: 0.0015144859 | O177: 0.44372116 | P177: 0.24683269 | Q177: 0.56292057 | R177: 0.246041 | S177: 0.38155945 | T177: 0.084138745 | U177: 19
A178: 177 | B178: 702 | C178: Registration | D178: 30 | E178: Registration Plots | F178: D:/Drone Imagery/2025 summer/20250704/shapefiles/7-04 reg plot files.gpkg|layername=registrationtrialdatarows | G178: 14786.665 | H178: 1.9117217e+08 | I178: 8348.5654 | J178: 85985786 | K178: 0.11132538 | L178: 0.025951588 | M178: -0.04374367 | N178: 0.0015571139 | O178: 0.42715443 | P178: 0.24469352 | Q178: 0.87939458 | R178: 0.10605975 | S178: 0.36414058 | T178: 0.091081824 | U178: 42
A179: 178 | B179: 703 | C179: Registration | D179: 30 | E179: Registration Plots | F179: D:/Drone Imagery/2025 summer/20250704/shapefiles/7-04 reg plot files.gpkg|layername=registrationtrialdatarows | G179: 21528.204 | H179: 1.6738593e+08 | I179: 2688.0144 | J179: 72112135 | K179: 0.20645281 | L179: 0.027485599 | M179: -0.031325363 | N179: 0.002051842 | O179: 0.69505641 | P179: 0.211953 | Q179: 0.87308207 | R179: 0.11080977 | S179: 0.53140282 | T179: 0.077840884 | U179: 58
... A241: 240 | B241: 66666 | C241: Registration | D241: 30 | E241: Registration Plots | F241: D:/Drone Imagery/2025 summer/20250704/shapefiles/7-04 reg plot files.gpkg|layername=registrationtrialdatarows | G241: 594.37427 | H241: 1674934.4 | I241: 17032.593 | J241: 35327502 | K241: -0.042580644 | L241: 0.016407104 | M241: -0.061714698 | N241: 0.0041226003 | O241: 0 | P241: 0 | Q241: 0 | R241: 0 | S241: 0.1515279 | T241: 0.0083907118 | U241: 0

Sheet 731
A1: fid | B1: id | C1: Trial Name | D1: DAS | E1: layer | F1: path | G1: 724ExG_mean | H1: 724ExG_variance | I1: 724ExR_mean | J1: 724ExR_variance | K1: 724gNDVI_mean | L1: 724gNDVI_variance | M1: 731NDREmean | N1: 731NDREvariance | O1: 731NDVI_mean | P1: 731NDVI_variance | Q1: 731THRESH_mean | R1: 731THRESH_variance | S1: 731HA_mean | T1: 731HA_variance | U1: 731PLT_
A2: 1 | B2: 101 | C2: AYT Trial | D2: 37 | E2: 7-04 ayt plot files â€” ayttrialdata_rows_polygons__ayt_plots_dissolved | F2: D:/Drone Imagery/2025 summer/20250704/shapefiles/7-04 ayt plot files.gpkg|layername=ayttrialdata_rows_polygons__ayt_plots_dissolved | G2: 14885.921 | H2: 1.2841182e+08 | I2: 6270.0539 | J2: 1.1946292e+08 | K2: 0.2136527 | L2: 0.054471822 | M2: -0.020035711 | N2: 0.0029523454 | O2: 0.4708068 | P2: 0.11138805 | Q2: 0.54147631 | R2: 0.24827972 | S2: 0.70672375 | T2: 0.20726529 | U2: 28
A3: 2 | B3: 102 | C3: AYT Trial | D3: 37 | E3: 7-04 ayt plot files â€” ayttrialdata_rows_polygons__ayt_plots_dissolved | F3: D:/Drone Imagery/2025 summer/20250704/shapefiles/7-04 ayt plot files.gpkg|layername=ayttrialdata_rows_polygons__ayt_plots_dissolved | G3: 17006.246 | H3: 1.9833015e+08 | I3: 7749.3463 | J3: 1.3629413e+08 | K3: 0.15057384 | L3: 0.048530858 | M3: -0.039852084 | N3: 0.003120974 | O3: 0.41903021 | P3: 0.11683967 | Q3: 0.5060643 | R3: 0.24996322 | S3: 0.62086742 | T3: 0.23539107 | U3: 18
A4: 3 | B4: 103 | C4: AYT Trial | D4: 37 | E4: 7-04 ayt plot files â€” ayttrialdata_rows_polygons__ayt_plots_dissolved | F4: D:/Drone Imagery/2025 summer/20250704/shapefiles/7-04 ayt plot files.gpkg|layername=ayttrialdata_rows_polygons__ayt_plots_dissolved | G4: 22873.364 | H4: 2.4384897e+08 | I4: 4102.1584 | J4: 1.083657e+08 | K4: 0.18656297 | L4: 0.031758141 | M4: -0.041519542 | N4: 0.0025342149 | O4: 0.50747506 | P4: 0.087298679 | Q4: 0.6392216 | R4: 0.23061735 | S4: 0.52791071 | T4: 0.24922099 | U4: 16
A5: 4 | B5: 104 | C5: AYT Trial | D5: 37 | E5: 7-04 ayt plot files â€” ayttrialdata_rows_polygons__ayt_plots_dissolved | F5: D:/Drone Imagery/2025 summer/20250704/shapefiles/7-04 ayt plot files.gpkg|layername=ayttrialdata_rows_polygons__ayt_plots_dissolved | G5: 26032.367 | H5: 2.0347449e+08 | I5: 506.81072 | J5: 82900304 | K5: 0.2208099 | L5: 0.030532243 | M5: -0.041568218 | N5: 0.0031551325 | O5: 0.57137775 | P5: 0.08099985 | Q5: 0.76285214 | R5: 0.18090875 | S5: 0.73597153 | T5: 0.19431744 | U5: 29
A6: 5 | B6: 105 | C6: AYT Trial | D6: 37 | E6: 7-04 ayt plot files â€” ayttrialdata_rows_polygons__ayt_plots_dissolved | F6: D:/Drone Imagery/2025 summer/20250704/shapefiles/7-04 ayt plot files.gpkg|layername=ayttrialdata_rows_polygons__ayt_plots_dissolved | G6: 27760.22 | H6: 1.8655036e+08 | I6: -467.07884 | J6: 57311501 | K6: 0.23215359 | L6: 0.020171278 | M6: -0.037239319 | N6: 0.0031034688 | O6: 0.59617849 | P6: 0.053700456 | Q6: 0.79423265 | R6: 0.16342715 | S6: 0.70934718 | T6: 0.20617376 | U6: 33
